Workbook

Sheet Read Me
A1: 🏆 MONIT MULTIBAGGER RESEARCH ENGINE & SCANNER
A2: Daily Analytics Report | Generated: Thursday, 04 June 2026
A5: 📖 QUICK REFERENCE RUNBOOK & SYSTEM FLOW
A6: Step 1: Reference this Read Me | B6: Understand terms, formulas, and underlying investment theses directly in this glossary dashboard.
A7: Step 2: Check Leaderboard Tab | B7: Locate long-term compounders with high Persistence Scores and streaks (institutional accumulation footprint).
A8: Step 3: Analyze Confluence Overlap | B8: Review the ultimate high-conviction candidates intersecting our scanner signals and StockScans overlaps.
A9: Step 4: Scoring Monit Tabs | B9: Open 'Monit Non Financial' or 'Monit Banks NBFC' to fill out your qualitative checks (Tailwinds, Promoters, Triggers).
A10: Step 5: Track Scan Matches | B10: Confirm consensus using 'Scan Match' tabs which score companies by total appearances across allStockScans.
A13: 📊 RESEARCH ENGINE GLOSSARY, METRICS & THESES
A15: Metric Term / Tab Name | B15: Practical Meaning & Underlying Investment Thesis | C15: Automated DB Query / Logic & Excel Formula
A16: EMA Crossover (Birth of a Trend) | B16: An entry signal triggered when price crosses above its 200-day EMA. [THESIS]: Represents the birth of a new long-term uptrend. Buying here provides maximum asymmetrical risk-to-reward because the entry is close to the logical stop-loss (the EMA itself). | C16: pine_signal == 'EMA Crossover' Sized at 7% capital allocation (~₹70,000 per position).
A17: 52W Breakout (Momentum Confirmation) | B17: A momentum signal triggered when a stock above its 200-day EMA breaks out to fresh 52-week highs. [THESIS]: Represents a confirmed breakout where institutional buying pressure clears all historical supply. High momentum outperformance. | C17: pine_signal == '52W Breakout' Sized at 5% capital allocation (~₹50,000 per position).
A18: ATH Momentum (Runaway Leader) | B18: An established trend signal triggered when the price is actively running near its All-Time Highs. [THESIS]: Identifies the strongest runaway leaders in the market. Ideal for high-velocity momentum trading where price experiences immediate continuation. | C18: pine_signal == 'ATH Momentum' Sized at 4% capital allocation (~₹40,000 per position).
A19: Persistence Score (30D) (Accumulation Footprint) | B19: The count of times a stock has appeared in the daily screener during the last 30 active trading days. [THESIS]: Represents persistent institutional buying. Random spikes appear 1-2 times, but compounders appear 10+ times as institutions accumulate. | C19: Queries the local SQLite database (`logs/backtest.db`) to sum the total number of distinct dates the ticker appeared on the screener during the last 30 active trading days. Formula: COUNT(DISTINCT date)
A20: Consecutive Streak Days (Uninterrupted Trend) | B20: The number of consecutive trading days that the stock has appeared in the screener up to today. [THESIS]: High streaks indicate an exceptionally strong, uninterrupted runaway trend with heavy daily buying pressure. | C20: Checks the chronological sequence of scanner dates in SQLite starting from the most recent run date and counting backward. The streak increments for every contiguous date the ticker appears.
A21: Sector Velocity WoW (Early Sector Rotation) | B21: Compares the volume of screener signals in a sector over the last 5 trading days (W1) against the previous 5 trading days (W2). [THESIS]: Detects early sector rotation. A sudden positive surge warns you of capital flowing aggressively into a specific theme. | C21: Counts appearances of all tickers categorized by their sector. Formula: W1_Count = COUNT(records WHERE date IN last 5 trading days) W2_Count = COUNT(records WHERE date IN days -10 to -5) Velocity % = ((W1_Count - W2_Count) / W2_Count) * 100
A22: Emerging Leaders (Momentum Expansion) | B22: Identifies breakout stocks experiencing a sudden momentum expansion. [THESIS]: Finds stocks with a high concentration of appearances recently but almost zero history in the preceding months. Represents new institutional entries. | C22: Finds stocks with at least 5 appearances in the last 10 trading days, but less than or equal to 3 appearances in the prior 50 trading days (i.e. trading days -60 to -10). Formula: COUNT(recent) >= 5 AND COUNT(historical) <= 3
A23: Tab: Confluence Overlap (The Ultimate Overlap) | B23: This sheet displays the absolute highest conviction watchlist candidates intersecting multiple strategies. [THESIS]: Filters out market noise by only displaying stocks appearing in at least two out of three major momentum dimensions: (1) Chartink screener universe, (2) Active scanner signals, and (3) StockScans overlap list. | C23: Calculates the mathematical intersection of the three sets: In_Universe + In_Scanner + In_StockScans >= 2 Single-dimension matches are automatically filtered out to eliminate market noise.
A24: Tab: Monit Non Financial (CHECKLIST SHEET) | B24: Your main watchlist scoring sheet for non-financial companies. [THESIS]: Keeps watchlist scoring fully formula-driven using Excel formulas. It combines automated metrics (RSI, ADX, V-stop, Persistence) with your qualitative scores (Promoter Buying, Near-Term Trigger, Headwind/Tailwind). | C24: Uses relative index-matching formulas to populate automated close prices, RSI, ADX, V-stop, and Persistence from the SQLite and Chartink universe sheets. Formula: INDEX-MATCH left-lookup.
A25: Tab: Monit Banks NBFC (BANKING CHECKLIST) | B25: Your main watchlist scoring sheet for banking and NBFC companies. [THESIS]: Tailored specifically for banking structures, incorporating specialized metrics like Net Interest Margins (NIM) and Credit Costs alongside technical indicators. | C25: Features banking-specific checklist criteria to ensure qualitative analyst inputs align with bank metrics.
A26: Tab: Scan Match tabs (StockScans Confluence) | B26: Displays the top 100 stocks appearing across all StockScans screeners. [THESIS]: Scores stocks qualitatively by scan volume. Stocks appearing in >20 scans receive a premium 10-point bonus, proving market-wide momentum consensus. | C26: Applies a nested Excel IF formula: `=IF(D8>20,10,IF(D8>=10,5,2))` Scores: >20 scans = 10 pts; 10-20 scans = 5 pts; <10 scans = 2 pts.
... A36: Weekly Tracking Highlighting (Additions / Removals) | B36: Visual highlights indicating weekly changes in the StockScans 100 (Scan Match) list. [THESIS]: Helps track the weekly turnover. Newly added candidates indicate fresh institutional attention, while removed candidates represent names losing relative strength. | C36: Compares daily lists against Monday's baseline database: - Added stocks: Highlighted in Soft Blue. - Removed stocks: Listed in the bottom section of Scan Match sheets.

Sheet Leaderboard
A1: 🌟 MULTIBAGGER MOMENTUM & SECTOR ROTATION LEADERBOARD 🌟
A4: TOP PERSISTENT MOMENTUM LEADERS (30D) | J4: SECTOR MOMENTUM VELOCITY HEATMAP (WoW)
A5: Rank | B5: Score | C5: Symbol | D5: Company Name | E5: Sector | F5: Streak (Days) | G5: Market Cap Cr | H5: Classification | J5: Sector Name | K5: Current Wk Count | L5: Previous Wk Count | M5: Velocity WoW %
A6: 1 | B6: 390 | C6: GRANULES | D6: Granules India Limited | E6: healthcare | F6: 50 | G6: 19670.12 | H6: Potential Leader | J6: services | K6: 41 | L6: 20 | M6: 105.0%
A7: 2 | B7: 378 | C7: HONASA | D7: Honasa Consumer Ltd | E7: services | F7: 48 | G7: 13083.12 | H7: Potential Leader | J7: building materials | K7: 34 | L7: 18 | M7: 88.9%
A8: 3 | B8: 366 | C8: ADANIPOWER | D8: Adani Power Limited | E8: power & utilities | F8: 46 | G8: 448407.72 | H8: Potential Leader | J8: textiles | K8: 90 | L8: 51 | M8: 76.5%
A9: 4 | B9: 366 | C9: BLISSGVS | D9: Bliss Gvs Pharma Limited | E9: healthcare | F9: 46 | G9: 4651.01 | H9: Potential Leader | J9: consumer discretionary | K9: 107 | L9: 62 | M9: 72.6%
A10: 5 | B10: 366 | C10: DEEDEV | D10: DEE Development Engineers Ltd | E10: metals & mining | F10: 46 | G10: 4555.45 | H10: Potential Leader | J10: fmcg | K10: 69 | L10: 40 | M10: 72.5%
A11: 6 | B11: 360 | C11: ARVIND | D11: Arvind Limited | E11: textiles | F11: 45 | G11: 12713.87 | H11: Potential Leader | J11: metals & mining | K11: 118 | L11: 69 | M11: 71.0%
A12: 7 | B12: 360 | C12: NITINSPIN | D12: Nitin Spinners Limited | E12: textiles | F12: 45 | G12: 2854.85 | H12: Potential Leader | J12: energy | K12: 41 | L12: 24 | M12: 70.8%
A13: 8 | B13: 360 | C13: RPTECH | D13: Rashi Peripherals Ltd | E13: services | F13: 45 | G13: 3573.41 | H13: Potential Leader | J13: telecom-service | K13: 10 | L13: 6 | M13: 66.7%
A14: 9 | B14: 360 | C14: WELCORP | D14: Welspun Corp Limited | E14: industrials | F14: 45 | G14: 37289.45 | H14: Potential Leader | J14: media | K14: 10 | L14: 6 | M14: 66.7%
A15: 10 | B15: 354 | C15: BAJAJCON | D15: Bajaj Consumer Care Ltd | E15: fmcg | F15: 44 | G15: 7254.54 | H15: Potential Leader | J15: transportation | K15: 16 | L15: 10 | M15: 60.0%
A16: 11 | B16: 354 | C16: STLTECH | D16: Sterlite Technologies Limited | E16: industrials | F16: 44 | G16: 30293.51 | H16: Potential Leader | J16: i.t | K16: 69 | L16: 45 | M16: 53.3%
A17: 12 | B17: 354 | C17: STYLAMIND | D17: Stylam Industries Ltd | E17: building materials | F17: 44 | G17: 5067.13 | H17: Potential Leader | J17: auto | K17: 129 | L17: 85 | M17: 51.8%
... A20: 15 | B20: 342 | C20: ADANIPORTS | D20: Adani Ports And Special Economic Zone Limited | E20: transportation | F20: 42 | G20: 415588.14 | H20: Potential Leader | J20: aerospace & defence | K20: 58 | L20: 39 | M20: 48.7%
A21: 16 | B21: 342 | C21: APCOTEXIND | D21: Apcotex Industries Limited | E21: chemicals | F21: 42 | G21: 2584.21 | H21: Potential Leader
A22: 17 | B22: 342 | C22: CRAFTSMAN | D22: Craftsman Automation Ltd | E22: auto | F22: 42 | G22: 21227.89 | H22: Potential Leader
A23: 18 | B23: 342 | C23: HFCL | D23: HFCL Ltd | E23: telecom | F23: 42 | G23: 30521.74 | H23: Potential Leader
A24: 19 | B24: 342 | C24: SATIN | D24: Satin Creditcare Network Limited | E24: financials | F24: 42 | G24: 2598.83 | H24: Potential Leader
A25: 20 | B25: 342 | C25: SHILPAMED | D25: Shilpa Medicare Limited | E25: healthcare | F25: 42 | G25: 10080.29 | H25: Potential Leader
A28: 🌟 EMERGING LEADERS (MOMENTUM EXPANSION) | J28: 💎 SATELLITE HOLDINGS SHORTLIST (MCAP < 25K CR)
A29: Symbol | B29: Company Name | C29: Sector | D29: Recent Matches (10D) | E29: Historical Matches | F29: Market Cap Cr | J29: Symbol | K29: Sector | L29: Monit Score | M29: Market Cap Cr | N29: Appearances (30D)
A30: TMPV | B30: Tata Motors Passenger Vehicles Ltd | C30: auto | D30: 10 | E30: 1 | F30: 146613.86 | J30: BAJAJCON | K30: fmcg | L30: 297 | M30: 7254.54 | N30: 30
A31: HESTERBIO | B31: Hester Biosciences Limited | C31: healthcare | D31: 10 | E31: 2 | F31: 1664.71 | J31: OMAXAUTO | K31: auto | L31: 293 | M31: 507.54 | N31: 26
A32: ASAHIINDIA | B32: Asahi India Glass Limited | C32: building materials | D32: 10 | E32: 0 | F32: 23032.67 | J32: IBULLSLTD | K32: miscellaneous | L32: 290 | M32: 5655.22 | N32: 25
A33: AVANTEL | B33: Avantel Ltd | C33: aerospace & defence | D33: 10 | E33: 0 | F33: 4668.54 | J33: CONFIPET | K33: miscellaneous | L33: 288 | M33: 2551.28 | N33: 28
A34: MONARCH | B34: Monarch Networth Capital Ltd | C34: financials | D34: 10 | E34: 2 | F34: 2685.61 | J34: FEDFINA | K34: financials | L34: 285 | M34: 5875.41 | N34: 24
A35: KOPRAN | B35: Kopran Limited | C35: healthcare | D35: 10 | E35: 2 | F35: 900.19 | J35: RBLBANK | K35: bank | L35: 285 | M35: 21522.64 | N35: 22
A36: DIAMONDYD | B36: Prataap Snacks Ltd | C36: fmcg | D36: 10 | E36: 0 | F36: 2836.39 | J36: TMB | K36: bank | L36: 285 | M36: 11725.13 | N36: 13
A37: SPECTRUM | B37: Spectrum Electrical Industries Ltd | C37: industrials | D37: 9 | E37: 1 | F37: 2547.37 | J37: GAYAPROJ | K37: realty | L37: 283 | M37: 595.36 | N37: 23
A38: VINCOFE | B38: Vintage Coffee & Beverages Ltd | C38: consumer discretionary | D38: 9 | E38: 0 | F38: 2167.99 | J38: DHANBANK | K38: bank | L38: 282 | M38: 1341.58 | N38: 30
A39: TEGA | B39: Tega Industries Ltd | C39: industrials | D39: 7 | E39: 1 | F39: 13681.51 | J39: VENUSREM | K39: healthcare | L39: 282 | M39: 1980.72 | N39: 17
A40: GUFICBIO | B40: Gufic Biosciences Limited | C40: healthcare | D40: 7 | E40: 0 | F40: 3629.73 | J40: WELINV | K40: financials | L40: 280 | M40: 678.97 | N40: 30
A41: BFINVEST | B41: Bf Investment Limited | C41: financials | D41: 7 | E41: 0 | F41: 1660.39 | J41: INDOBORAX | K41: chemicals | L41: 280 | M41: 1110.63 | N41: 28
A45: 🚀 HIGH MOMENTUM LEADERS (RS RATING >= 90)
A46: Rank | B46: RS Rating | C46: O'Neil Score | D46: Monit Score | E46: Symbol | F46: Company Name | G46: Sector | H46: Market Cap Cr
A47: 1 | B47: 99 | C47: 127.42 | D47: 260 | E47: STLTECH | F47: Sterlite Technologies Limited | G47: industrials | H47: 30293.51
A48: 2 | B48: 99 | C48: 89.41 | D48: 255 | E48: SIGMAADV | F48: Sigma Advanced System Ltd | G48: aerospace & defence | H48: 7699.91
A49: 3 | B49: 98 | C49: 68.45 | D49: 255 | E49: HFCL | F49: HFCL Ltd | G49: telecom | H49: 30521.74
...

Sheet Chartink Universe
A1: symbol | B1: company | C1: sector | D1: industry | E1: marketcap_bucket | F1: marketcap_cr | G1: close | H1: today_return_pct | I1: volume | J1: bse_code
A2: PANACEABIO | B2: Panacea Biotec Limited | C2: healthcare | D2: pharmaceuticals - indian - bulk drugs & formln | E2: smallcap | F2: 2655.83 | G2: 520.3 | H2: 20 | I2: 3632208 | J2: 531349
A3: MSTCLTD | B3: MSTC Ltd | C3: i.t | D3: trading | E3: smallcap | F3: 3143.01 | G3: 531.85 | H3: 19.13 | I3: 13124225 | J3: 542597
A4: RUBYMILLS | B4: The Ruby Mills Limited | C4: textiles | D4: textiles - composite | E4: smallcap | F4: 949.7 | G4: 336.2 | H4: 18.38 | I4: 1383749 | J4: 503169
A5: THANGAMAYL | B5: Thangamayil Jewellery Limited | C5: consumer discretionary | D5: diamond cutting / jewellery | E5: midcap | F5: 14903.83 | G5: 5520.6 | H5: 15.13 | I5: 1263774 | J5: 533158
A6: RICOAUTO | B6: Rico Auto Industries Limited | C6: auto | D6: auto ancillaries | E6: smallcap | F6: 1573.5 | G6: 131.37 | H6: 12.95 | I6: 44524758 | J6: 520008
A7: YASHO | B7: Yasho Industries Ltd | C7: chemicals | D7: chemicals | E7: smallcap | F7: 2702.12 | G7: 2475.2 | H7: 10.45 | I7: 87457 | J7: 541167
A8: ITDC | B8: India Tourism Development Corporation Ltd | C8: services | D8: hotels | E8: smallcap | F8: 4593.81 | G8: 589.15 | H8: 10 | I8: 357669 | J8: 532189
A9: JNKINDIA | B9: JNK India Ltd | C9: realty | D9: engineering - turnkey services | E9: smallcap | F9: 2144.71 | G9: 421.6 | H9: 9.99 | I9: 912000 | J9: 544167
A10: CEMPRO | B10: Cemindia Projects Ltd | C10: realty | D10: construction | E10: midcap | F10: 17606.51 | G10: 1127.3 | H10: 9.99 | I10: 1435282 | J10: 509496
A11: SOTL | B11: Savita Oil Technologies Limited | C11: energy | D11: petrochemicals | E11: smallcap | F11: 3528.12 | G11: 564.3 | H11: 9.66 | I11: 10971069 | J11: 524667
A12: PSPPROJECT | B12: PSP Projects Ltd | C12: realty | D12: construction | E12: smallcap | F12: 3250.83 | G12: 898.65 | H12: 9.58 | I12: 793302 | J12: 540544
A13: AVALON | B13: Avalon Technologies Ltd | C13: consumer discretionary | D13: electronics - components | E13: midcap | F13: 10120.42 | G13: 1637.7 | H13: 8.04 | I13: 781827 | J13: 543896
... A189: TIINDIA | B189: Tube Investments of India Ltd | C189: industrials | D189: steel - large | E189: largecap | F189: 59424.6 | G189: 3098.4 | H189: 0.92 | I189: 207106 | J189: 540762
A190: ANGELONE | B190: Angel One Ltd | C190: financials | D190: finance & investments | E190: largecap | F190: 30491.01 | G190: 337.7 | H190: 0.88 | I190: 6699518
A191: BIOCON | B191: Biocon Limited | C191: healthcare | D191: pharmaceuticals - indian - bulk drugs & formln | E191: largecap | F191: 66854.34 | G191: 416.05 | H191: 0.87 | I191: 2493074 | J191: 532523
A192: LLOYDSENGG | B192: Lloyds Engineering Works Ltd | C192: industrials | D192: engineering | E192: midcap | F192: 10495.26 | G192: 71.51 | H192: 0.85 | I192: 7197429 | J192: 539992
A193: RML | B193: Rane (madras) Limited | C193: auto | D193: auto ancillaries | E193: smallcap | F193: 2503.23 | G193: 913.35 | H193: 0.84 | I193: 13588 | J193: 532661
A194: NAVINFLUOR | B194: Navin Fluorine International Limited | C194: chemicals | D194: chemicals | E194: largecap | F194: 36055.93 | G194: 7090.5 | H194: 0.78 | I194: 77756 | J194: 532504
A195: RATEGAIN | B195: Rategain Travel Technologies Ltd | C195: i.t | D195: computers - software - medium / small | E195: midcap | F195: 9042.61 | G195: 771 | H195: 0.75 | I195: 451261 | J195: 543417
A196: ZYDUSLIFE | B196: Zydus Lifesciences Ltd | C196: healthcare | D196: pharmaceuticals - indian - bulk drugs & formln | E196: largecap | F196: 108331.15 | G196: 1084.6 | H196: 0.74 | I196: 1016000 | J196: 532321
A197: SKIPPER | B197: Skipper Limited | C197: industrials | D197: engineering | E197: midcap | F197: 6441.18 | G197: 574.65 | H197: 0.73 | I197: 2598018 | J197: 538562
A198: AJAXENGG | B198: Ajax Engineering Ltd | C198: industrials | D198: engineering | E198: midcap | F198: 6824.37 | G198: 600.85 | H198: 0.73 | I198: 50936 | J198: 544356
A199: SOUTHWEST | B199: South West Pinnacle Exploration Ltd | C199: metals & mining | D199: mining / minerals / metals | E199: smallcap | F199: 783.04 | G199: 264.25 | H199: 0.67 | I199: 458761 | J199: 535049
A200: GPTHEALTH | B200: GPT Healthcare Ltd | C200: healthcare | D200: healthcare | E200: smallcap | F200: 1242.64 | G200: 152.43 | H200: 0.65 | I200: 184805 | J200: 544131
A201: KERNEX | B201: Kernex Microsystems (india) Limited | C201: consumer discretionary | D201: electronics - components | E201: smallcap | F201: 3155.33 | G201: 1890.1 | H201: 0.65 | I201: 257159 | J201: 532686
A202: BAJAJCON | B202: Bajaj Consumer Care Ltd | C202: fmcg | D202: personal care - indian | E202: midcap | F202: 7254.54 | G202: 558.8 | H202: 0.61 | I202: 312589 | J202: 533229
... A255: RAINBOW | B255: Rainbow Childrens Medicare Ltd | C255: healthcare | D255: healthcare | E255: midcap | F255: 13753.14 | G255: 1347 | H255: -0.53 | I255: 102088 | J255: 543524
A256: RPTECH | B256: Rashi Peripherals Ltd | C256: services | D256: trading | E256: smallcap | F256: 3573.41 | G256: 539.25 | H256: -0.55 | I256: 159059
A257: ABB | B257: Abb India Limited | C257: industrials | D257: electric equipment | E257: largecap | F257: 152489.27 | G257: 7156 | H257: -0.56 | I257: 298566 | J257: 500002
A258: FIEMIND | B258: Fiem Industries Limited | C258: auto | D258: auto ancillaries | E258: midcap | F258: 6177.22 | G258: 2333.8 | H258: -0.56 | I258: 58528 | J258: 532768
A259: GLAND | B259: Gland Pharma Ltd | C259: healthcare | D259: pharmaceuticals - indian - formulations | E259: largecap | F259: 36778.58 | G259: 2219.5 | H259: -0.57 | I259: 204659 | J259: 543245
A260: CEIGALL | B260: Ceigall India Ltd | C260: realty | D260: construction | E260: midcap | F260: 6281.83 | G260: 358.5 | H260: -0.58 | I260: 805250 | J260: 544223
A261: AEGISLOG | B261: Aegis Logistics Ltd | C261: services | D261: trading | E261: largecap | F261: 26693.55 | G261: 755.8 | H261: -0.62 | I261: 199411 | J261: 500003
A262: LMW | B262: LMW Ltd | C262: industrials | D262: textile machinery | E262: midcap | F262: 16984.9 | G262: 15799 | H262: -0.63 | I262: 2683 | J262: 500252
A263: J&KBANK | B263: The Jammu & Kashmir Bank Limited | C263: bank | D263: banks - private sector | E263: midcap | F263: 16369.08 | G263: 147.68 | H263: -0.65 | I263: 4046091 | J263: 532209
A264: YESBANK | B264: Yes Bank Limited | C264: bank | D264: banks - private sector | E264: largecap | F264: 71950.77 | G264: 22.77 | H264: -0.7 | I264: 77191326 | J264: 532648
A265: STARHEALTH | B265: Star Health & Allied Insurance Company Ltd | C265: financials | D265: finance & investments | E265: largecap | F265: 31188.33 | G265: 526.25 | H265: -0.72 | I265: 222957 | J265: 543412
A266: ADANIPORTS | B266: Adani Ports And Special Economic Zone Limited | C266: transportation | D266: miscellaneous | E266: largecap | F266: 415588.14 | G266: 1790.9 | H266: -0.72 | I266: 1369988 | J266: 532921
A267: HONAUT | B267: Honeywell Automation India Limited | C267: consumer discretionary | D267: electronics - components | E267: largecap | F267: 30724.29 | G267: 34485 | H267: -0.76 | I267: 3125 | J267: 517174
...

Sheet Monit Non Financial
A1: Rank (Non Financial) | B1: Total Score | C1: Symbol | D1: Company | E1: Sector | F1: Industry | G1: Market Cap Bucket | H1: Market Cap Cr | I1: Close | J1: Today Return % | K1: Volume | L1: Relative Strength Rating | M1: Relative Strength Status | N1: Relative Strength Score | O1: Calculated RSI (14) | P1: Calculated ADX (14) | Q1: Calculated V-stop Line | R1: Calculated Near-term Trigger | S1: Sector Benchmark | T1: Benchmark 1Y Return % | U1: Stock 1Y Return % | V1: Relative Strength 1Y (%) | W1: O'Neil Weighted Score | X1: Industry Growth | Y1: Industry Growth Score | Z1: Competitiveness | AA1: Competitiveness Score | AB1: Regulation | AC1: Regulation Score | AD1: Sector Headwinds/Tailwind | AE1: Sector Headwinds/Tailwind Score | AF1: Industry Type | AG1: Industry Type Score | AH1: Margins | AI1: Margins Score | AJ1: Margins Stability | AK1: Margins Stability Score | AL1: Growth | AM1: Growth Score | AN1: Business Type | AO1: Business Type Score | AP1: Near term triggers | AQ1: Near term triggers Score | AR1: Type of Revenue | AS1: Type of Revenue Score | AT1: Capital Allocation | AU1: Capital Allocation Score | AV1: Medium term Growth | AW1: Medium term Growth Score | AX1: ADX | AY1: ADX Score | AZ1: RSI | BA1: RSI Score | BB1: Stage Analysis | BC1: Stage Analysis Score | BD1: Price Volume Action | BE1: Price Volume Action Score | BF1: Secondary Trend | BG1: Secondary Trend Score | BH1: Primary Trend | BI1: Primary Trend Score | BJ1: Resistance | BK1: Resistance Score | BL1: V-stop | BM1: V-stop Score | BN1: PAT Growth | BO1: PAT Growth Score | BP1: Stock History | BQ1: Stock History Score | BR1: PE Ratio | BS1: PE Ratio Score | BT1: PEG Ratio | BU1: PEG Ratio Score | BV1: CFO to EBITDA | BW1: CFO to EBITDA Score | BX1: Debt to Equity | BY1: Debt to Equity Score | BZ1: Auditor Resignation | CA1: Auditor Resignation Score | CB1: Contingent Liability | CC1: Contingent Liability Score | CD1: Pledging | CE1: Pledging Score
A2: =IF(B2=0,"",RANK(B2,$B$2:$B$314,0)) | B2: =SUM(N2,Y2,AA2,AC2,AE2,AG2,AI2,AK2,AM2,AO2,AQ2,AS2,AU2,AW2,AY2,BA2,BC2,BE2,BG2,BI2,BK2,BM2,BO2,BQ2,BS2,BU2,BW2,BY2,CA2,CC2,CE2) | C2: BAJAJCON | D2: Bajaj Consumer Care Ltd | E2: fmcg | F2: personal care - indian | G2: midcap | H2: 7254.54 | I2: 558.8 | J2: 0.61 | K2: 312589 | L2: 91 | M2: Outperforming | N2: =IF(M2="Underperforming",-5,IF(L2>=95,15,IF(L2>=90,10,IF(L2>=80,5,0)))) | O2: 74.91 | P2: 51.77 | Q2: 441.56 | R2: Near 52W High Breakout | S2: Nifty FMCG | T2: -13.6 | U2: 221.06 | V2: 271.57 | W2: 37.53 | X2: Growing Industry | Y2: =IF(X2="Growing Industry",10,IF(X2="Cyclical in an Upturn",5,0)) | Z2: Too Many Players with High ROCE | AA2: =IF(Z2="Monopoly",10,IF(Z2="Oligopoly",5,IF(Z2="Duopoly that cooperate",10,IF(Z2="Duopoly that compete",5,IF(Z2="Too many players with High ROCE",5,0))))) | AB2: No | AC2: =IF(AB2="No",5,0) | AD2: Tailwind | AE2: =IF(AD2="Tailwind",10,0) | AF2: Structural (10 Years Consistency) | AG2: =IF(AF2="Structural (10 Years Consistency)",10,IF(AF2="Shallow Cyclical (2 to 3 years growth)",5,0)) | AH2: No | AI2: =IF(AH2="Yes due to Product Mix change or Operating Leverage",10,IF(AH2="Yes, these are peak margins",-5,IF(AH2="No",5,0))) | AJ2: Stable | AK2: =IF(AJ2="Stable",10,0) | AL2: Yes | AM2: =IF(AL2="Yes",10,0) | AN2: B2C | AO2: =IF(AN2="B2C",10,IF(AN2="B2B",5,0)) | AP2: Yes | AQ2: =IF(AP2="Yes",10,0) | AR2: Higher Annuity, Lower One Time | AS2: =IF(AR2="Fully Annuity",10,IF(AR2="Higher Annuity, Lower One Time",5,IF(AR2="Higher One Time, Lower Annuity",3,0))) | AT2: Good | AU2: =IF(AT2="Good",10,0) | AV2: Yes for more than 2 years | AW2: =IF(AV2="Yes for more than 2 years",10,IF(AV2="Yes only for next 1 to 2 years",5,0)) | AX2: Above 40 | AY2: =IF(AX2="Above 40",20,IF(AX2="20 to 40",10,IF(AX2="0 to 20",-5,0))) | AZ2: Between 50 to 75 | BA2: =IF(AZ2="Between 50 to 75",10,IF(AZ2="Above 75",0,0)) | BB2: Stage 2 | BC2: =IF(BB2="Stage 2",20,IF(BB2="Stage 1",0,IF(BB2="Stage 3",5,IF(BB2="Stage 4",-5,0)))) | BD2: Positive Trend | BE2: =IF(BD2="Positive Trend",20,IF(BD2="Negative Trend",-10,0)) | BF2: Uptrend | BG2: =IF(BF2="Uptrend",10,IF(BF2="Sideways",5,0)) | BH2: Uptrend | BI2: =IF(BH2="Uptrend",10,IF(BH2="Sideways",5,0)) | BJ2: Blue sky scenario | BK2: =IF(BJ2="Overhead supply in last 2 years in last 2 years",-5,IF(BJ2="Close to 52 week high or retracement",5,IF(BJ2="Blue sky scenario",10,IF(BJ2="Long term Downtrend",-10,0)))) | BL2: Yes | BM2: =IF(BL2="Yes",10,0) | BN2: More than 20% | BO2: =IF(BN2="More than 20%",10,IF(BN2="Between 12 to 20%",5,IF(BN2="Less than 12%",0,0))) | BP2: No | BQ2: =IF(BP2="No",10,0) | BR2: No | BS2: =IF(BR2="NO",5,0) | BT2: Above 2 | BU2: =IF(BT2="Above 2",0,IF(BT2="Between 1.5 to 2",5,IF(BT2="Less than 1.5",10,0))) | BV2: Above 70% | BW2: =IF(BV2="Above 70%",10,IF(BV2="Between 50% to 70%",5,IF(BV2="Less than 50%",0,IF(BV2="Negative",-10,IF(BV2="Less than 50% and Borrowings are increasing",-5,0))))) | BX2: Less than 0.7 | BY2: =IF(BX2="More than 1.2",-10,IF(BX2="Between 0.7 to 1.2",0,IF(BX2="Less than 0.7",10,0))) | BZ2: No | CA2: =IF(BZ2="Yes",-10,0) | CB2: Less than 15% | CC2: =IF(CB2="More than 15%",-10,IF(CB2="Less than 15%",10,0)) | CD2: No | CE2: =IF(CD2="Yes, more than 10%",-10,IF(CD2="No",10,0))
A3: =IF(B3=0,"",RANK(B3,$B$2:$B$314,0)) | B3: =SUM(N3,Y3,AA3,AC3,AE3,AG3,AI3,AK3,AM3,AO3,AQ3,AS3,AU3,AW3,AY3,BA3,BC3,BE3,BG3,BI3,BK3,BM3,BO3,BQ3,BS3,BU3,BW3,BY3,CA3,CC3,CE3) | C3: OMAXAUTO | D3: Omax Autos Limited | E3: auto | F3: auto ancillaries | G3: smallcap | H3: 507.54 | I3: 236.98 | J3: -0.13 | K3: 63118 | L3: 97 | M3: Outperforming | N3: =IF(M3="Underperforming",-5,IF(L3>=95,15,IF(L3>=90,10,IF(L3>=80,5,0)))) | O3: 74.13 | P3: 35.13 | Q3: 176.72 | R3: Near 52W High Breakout | S3: Nifty Auto | T3: 10.49 | U3: 165.63 | V3: 140.4 | W3: 60.16 | X3: Growing Industry | Y3: =IF(X3="Growing Industry",10,IF(X3="Cyclical in an Upturn",5,0)) | Z3: Too Many Players with High ROCE | AA3: =IF(Z3="Monopoly",10,IF(Z3="Oligopoly",5,IF(Z3="Duopoly that cooperate",10,IF(Z3="Duopoly that compete",5,IF(Z3="Too many players with High ROCE",5,0))))) | AB3: No | AC3: =IF(AB3="No",5,0) | AD3: Tailwind | AE3: =IF(AD3="Tailwind",10,0) | AF3: Structural (10 Years Consistency) | AG3: =IF(AF3="Structural (10 Years Consistency)",10,IF(AF3="Shallow Cyclical (2 to 3 years growth)",5,0)) | AH3: No | AI3: =IF(AH3="Yes due to Product Mix change or Operating Leverage",10,IF(AH3="Yes, these are peak margins",-5,IF(AH3="No",5,0))) | AJ3: Stable | AK3: =IF(AJ3="Stable",10,0) | AL3: Yes | AM3: =IF(AL3="Yes",10,0) | AN3: B2B | AO3: =IF(AN3="B2C",10,IF(AN3="B2B",5,0)) | AP3: Yes | AQ3: =IF(AP3="Yes",10,0) | AR3: Higher One Time, Lower Annuity | AS3: =IF(AR3="Fully Annuity",10,IF(AR3="Higher Annuity, Lower One Time",5,IF(AR3="Higher One Time, Lower Annuity",3,0))) | AT3: Good | AU3: =IF(AT3="Good",10,0) | AV3: Yes for more than 2 years | AW3: =IF(AV3="Yes for more than 2 years",10,IF(AV3="Yes only for next 1 to 2 years",5,0)) | AX3: 20 to 40 | AY3: =IF(AX3="Above 40",20,IF(AX3="20 to 40",10,IF(AX3="0 to 20",-5,0))) | AZ3: Between 50 to 75 | BA3: =IF(AZ3="Between 50 to 75",10,IF(AZ3="Above 75",0,0)) | BB3: Stage 2 | BC3: =IF(BB3="Stage 2",20,IF(BB3="Stage 1",0,IF(BB3="Stage 3",5,IF(BB3="Stage 4",-5,0)))) | BD3: Positive Trend | BE3: =IF(BD3="Positive Trend",20,IF(BD3="Negative Trend",-10,0)) | BF3: Uptrend | BG3: =IF(BF3="Uptrend",10,IF(BF3="Sideways",5,0)) | BH3: Uptrend | BI3: =IF(BH3="Uptrend",10,IF(BH3="Sideways",5,0)) | BJ3: Blue sky scenario | BK3: =IF(BJ3="Overhead supply in last 2 years in last 2 years",-5,IF(BJ3="Close to 52 week high or retracement",5,IF(BJ3="Blue sky scenario",10,IF(BJ3="Long term Downtrend",-10,0)))) | BL3: Yes | BM3: =IF(BL3="Yes",10,0) | BN3: More than 20% | BO3: =IF(BN3="More than 20%",10,IF(BN3="Between 12 to 20%",5,IF(BN3="Less than 12%",0,0))) | BP3: No | BQ3: =IF(BP3="No",10,0) | BR3: No | BS3: =IF(BR3="NO",5,0) | BT3: Less than 1.5 | BU3: =IF(BT3="Above 2",0,IF(BT3="Between 1.5 to 2",5,IF(BT3="Less than 1.5",10,0))) | BV3: Above 70% | BW3: =IF(BV3="Above 70%",10,IF(BV3="Between 50% to 70%",5,IF(BV3="Less than 50%",0,IF(BV3="Negative",-10,IF(BV3="Less than 50% and Borrowings are increasing",-5,0))))) | BX3: Less than 0.7 | BY3: =IF(BX3="More than 1.2",-10,IF(BX3="Between 0.7 to 1.2",0,IF(BX3="Less than 0.7",10,0))) | BZ3: No | CA3: =IF(BZ3="Yes",-10,0) | CB3: Less than 15% | CC3: =IF(CB3="More than 15%",-10,IF(CB3="Less than 15%",10,0)) | CD3: No | CE3: =IF(CD3="Yes, more than 10%",-10,IF(CD3="No",10,0))
A4: =IF(B4=0,"",RANK(B4,$B$2:$B$314,0)) | B4: =SUM(N4,Y4,AA4,AC4,AE4,AG4,AI4,AK4,AM4,AO4,AQ4,AS4,AU4,AW4,AY4,BA4,BC4,BE4,BG4,BI4,BK4,BM4,BO4,BQ4,BS4,BU4,BW4,BY4,CA4,CC4,CE4) | C4: CONFIPET | D4: Confidence Petroleum India Ltd | E4: miscellaneous | F4: miscellaneous | G4: smallcap | H4: 2551.28 | I4: 76.89 | J4: 0.13 | K4: 7910840 | L4: 95 | M4: Outperforming | N4: =IF(M4="Underperforming",-5,IF(L4>=95,15,IF(L4>=90,10,IF(L4>=80,5,0)))) | O4: 78.6 | P4: 46.05 | Q4: 52.09 | R4: Near 52W High Breakout | S4: Nifty 50 | T4: -6.35 | U4: 29.26 | V4: 38.02 | W4: 51.11 | X4: Growing Industry | Y4: =IF(X4="Growing Industry",10,IF(X4="Cyclical in an Upturn",5,0)) | Z4: Too Many Players with High ROCE | AA4: =IF(Z4="Monopoly",10,IF(Z4="Oligopoly",5,IF(Z4="Duopoly that cooperate",10,IF(Z4="Duopoly that compete",5,IF(Z4="Too many players with High ROCE",5,0))))) | AB4: No | AC4: =IF(AB4="No",5,0) | AD4: Tailwind | AE4: =IF(AD4="Tailwind",10,0) | AF4: Structural (10 Years Consistency) | AG4: =IF(AF4="Structural (10 Years Consistency)",10,IF(AF4="Shallow Cyclical (2 to 3 years growth)",5,0)) | AH4: No | AI4: =IF(AH4="Yes due to Product Mix change or Operating Leverage",10,IF(AH4="Yes, these are peak margins",-5,IF(AH4="No",5,0))) | AJ4: Stable | AK4: =IF(AJ4="Stable",10,0) | AL4: Yes | AM4: =IF(AL4="Yes",10,0) | AN4: B2B | AO4: =IF(AN4="B2C",10,IF(AN4="B2B",5,0)) | AP4: Yes | AQ4: =IF(AP4="Yes",10,0) | AR4: Higher One Time, Lower Annuity | AS4: =IF(AR4="Fully Annuity",10,IF(AR4="Higher Annuity, Lower One Time",5,IF(AR4="Higher One Time, Lower Annuity",3,0))) | AT4: Good | AU4: =IF(AT4="Good",10,0) | AV4: Yes for more than 2 years | AW4: =IF(AV4="Yes for more than 2 years",10,IF(AV4="Yes only for next 1 to 2 years",5,0)) | AX4: Above 40 | AY4: =IF(AX4="Above 40",20,IF(AX4="20 to 40",10,IF(AX4="0 to 20",-5,0))) | AZ4: Above 75 | BA4: =IF(AZ4="Between 50 to 75",10,IF(AZ4="Above 75",0,0)) | BB4: Stage 2 | BC4: =IF(BB4="Stage 2",20,IF(BB4="Stage 1",0,IF(BB4="Stage 3",5,IF(BB4="Stage 4",-5,0)))) | BD4: Positive Trend | BE4: =IF(BD4="Positive Trend",20,IF(BD4="Negative Trend",-10,0)) | BF4: Uptrend | BG4: =IF(BF4="Uptrend",10,IF(BF4="Sideways",5,0)) | BH4: Uptrend | BI4: =IF(BH4="Uptrend",10,IF(BH4="Sideways",5,0)) | BJ4: Close to 52 week high or retracement | BK4: =IF(BJ4="Overhead supply in last 2 years in last 2 years",-5,IF(BJ4="Close to 52 week high or retracement",5,IF(BJ4="Blue sky scenario",10,IF(BJ4="Long term Downtrend",-10,0)))) | BL4: Yes | BM4: =IF(BL4="Yes",10,0) | BN4: More than 20% | BO4: =IF(BN4="More than 20%",10,IF(BN4="Between 12 to 20%",5,IF(BN4="Less than 12%",0,0))) | BP4: No | BQ4: =IF(BP4="No",10,0) | BR4: No | BS4: =IF(BR4="NO",5,0) | BT4: Less than 1.5 | BU4: =IF(BT4="Above 2",0,IF(BT4="Between 1.5 to 2",5,IF(BT4="Less than 1.5",10,0))) | BV4: Above 70% | BW4: =IF(BV4="Above 70%",10,IF(BV4="Between 50% to 70%",5,IF(BV4="Less than 50%",0,IF(BV4="Negative",-10,IF(BV4="Less than 50% and Borrowings are increasing",-5,0))))) | BX4: Less than 0.7 | BY4: =IF(BX4="More than 1.2",-10,IF(BX4="Between 0.7 to 1.2",0,IF(BX4="Less than 0.7",10,0))) | BZ4: No | CA4: =IF(BZ4="Yes",-10,0) | CB4: Less than 15% | CC4: =IF(CB4="More than 15%",-10,IF(CB4="Less than 15%",10,0)) | CD4: No | CE4: =IF(CD4="Yes, more than 10%",-10,IF(CD4="No",10,0))
A5: =IF(B5=0,"",RANK(B5,$B$2:$B$314,0)) | B5: =SUM(N5,Y5,AA5,AC5,AE5,AG5,AI5,AK5,AM5,AO5,AQ5,AS5,AU5,AW5,AY5,BA5,BC5,BE5,BG5,BI5,BK5,BM5,BO5,BQ5,BS5,BU5,BW5,BY5,CA5,CC5,CE5) | C5: IBULLSLTD | D5: Indiabulls Limited | E5: miscellaneous | F5: diversified - medium / small | G5: midcap | H5: 5655.22 | I5: 23.58 | J5: -3.08 | K5: 11394938 | L5: 96 | M5: Outperforming | N5: =IF(M5="Underperforming",-5,IF(L5>=95,15,IF(L5>=90,10,IF(L5>=80,5,0)))) | O5: 72.16 | P5: 35.91 | Q5: 16.54 | R5: Near 52W High Breakout | S5: Nifty 50 | T5: -6.35 | U5: 49.9 | V5: 60.06 | W5: 53.19 | X5: Growing Industry | Y5: =IF(X5="Growing Industry",10,IF(X5="Cyclical in an Upturn",5,0)) | Z5: Too Many Players with High ROCE | AA5: =IF(Z5="Monopoly",10,IF(Z5="Oligopoly",5,IF(Z5="Duopoly that cooperate",10,IF(Z5="Duopoly that compete",5,IF(Z5="Too many players with High ROCE",5,0))))) | AB5: No | AC5: =IF(AB5="No",5,0) | AD5: Tailwind | AE5: =IF(AD5="Tailwind",10,0) | AF5: Structural (10 Years Consistency) | AG5: =IF(AF5="Structural (10 Years Consistency)",10,IF(AF5="Shallow Cyclical (2 to 3 years growth)",5,0)) | AH5: No | AI5: =IF(AH5="Yes due to Product Mix change or Operating Leverage",10,IF(AH5="Yes, these are peak margins",-5,IF(AH5="No",5,0))) | AJ5: Stable | AK5: =IF(AJ5="Stable",10,0) | AL5: Yes | AM5: =IF(AL5="Yes",10,0) | AN5: B2B | AO5: =IF(AN5="B2C",10,IF(AN5="B2B",5,0)) | AP5: Yes | AQ5: =IF(AP5="Yes",10,0) | AR5: Higher One Time, Lower Annuity | AS5: =IF(AR5="Fully Annuity",10,IF(AR5="Higher Annuity, Lower One Time",5,IF(AR5="Higher One Time, Lower Annuity",3,0))) | AT5: Good | AU5: =IF(AT5="Good",10,0) | AV5: Yes for more than 2 years | AW5: =IF(AV5="Yes for more than 2 years",10,IF(AV5="Yes only for next 1 to 2 years",5,0)) | AX5: 20 to 40 | AY5: =IF(AX5="Above 40",20,IF(AX5="20 to 40",10,IF(AX5="0 to 20",-5,0))) | AZ5: Between 50 to 75 | BA5: =IF(AZ5="Between 50 to 75",10,IF(AZ5="Above 75",0,0)) | BB5: Stage 2 | BC5: =IF(BB5="Stage 2",20,IF(BB5="Stage 1",0,IF(BB5="Stage 3",5,IF(BB5="Stage 4",-5,0)))) | BD5: Positive Trend | BE5: =IF(BD5="Positive Trend",20,IF(BD5="Negative Trend",-10,0)) | BF5: Uptrend | BG5: =IF(BF5="Uptrend",10,IF(BF5="Sideways",5,0)) | BH5: Uptrend | BI5: =IF(BH5="Uptrend",10,IF(BH5="Sideways",5,0)) | BJ5: Blue sky scenario | BK5: =IF(BJ5="Overhead supply in last 2 years in last 2 years",-5,IF(BJ5="Close to 52 week high or retracement",5,IF(BJ5="Blue sky scenario",10,IF(BJ5="Long term Downtrend",-10,0)))) | BL5: Yes | BM5: =IF(BL5="Yes",10,0) | BN5: More than 20% | BO5: =IF(BN5="More than 20%",10,IF(BN5="Between 12 to 20%",5,IF(BN5="Less than 12%",0,0))) | BP5: No | BQ5: =IF(BP5="No",10,0) | BR5: No | BS5: =IF(BR5="NO",5,0) | BT5: Less than 1.5 | BU5: =IF(BT5="Above 2",0,IF(BT5="Between 1.5 to 2",5,IF(BT5="Less than 1.5",10,0))) | BV5: Between 50% to 70% | BW5: =IF(BV5="Above 70%",10,IF(BV5="Between 50% to 70%",5,IF(BV5="Less than 50%",0,IF(BV5="Negative",-10,IF(BV5="Less than 50% and Borrowings are increasing",-5,0))))) | BX5: Less than 0.7 | BY5: =IF(BX5="More than 1.2",-10,IF(BX5="Between 0.7 to 1.2",0,IF(BX5="Less than 0.7",10,0))) | BZ5: No | CA5: =IF(BZ5="Yes",-10,0) | CB5: Less than 15% | CC5: =IF(CB5="More than 15%",-10,IF(CB5="Less than 15%",10,0)) | CD5: No | CE5: =IF(CD5="Yes, more than 10%",-10,IF(CD5="No",10,0))
A6: =IF(B6=0,"",RANK(B6,$B$2:$B$314,0)) | B6: =SUM(N6,Y6,AA6,AC6,AE6,AG6,AI6,AK6,AM6,AO6,AQ6,AS6,AU6,AW6,AY6,BA6,BC6,BE6,BG6,BI6,BK6,BM6,BO6,BQ6,BS6,BU6,BW6,BY6,CA6,CC6,CE6) | C6: GAYAPROJ | D6: Gayatri Projects Limited | E6: realty | F6: construction | G6: smallcap | H6: 595.36 | I6: 20.9 | J6: 3.98 | K6: 779784 | L6: 89 | M6: Outperforming | N6: =IF(M6="Underperforming",-5,IF(L6>=95,15,IF(L6>=90,10,IF(L6>=80,5,0)))) | O6: 73.63 | P6: 62.92 | Q6: 16.78 | R6: Volume Spike & Near 52W High Breakout | S6: Nifty Realty | T6: -26.45 | U6: 144.73 | V6: 232.75 | W6: 34.94 | X6: Growing Industry | Y6: =IF(X6="Growing Industry",10,IF(X6="Cyclical in an Upturn",5,0)) | Z6: Too Many Players with High ROCE | AA6: =IF(Z6="Monopoly",10,IF(Z6="Oligopoly",5,IF(Z6="Duopoly that cooperate",10,IF(Z6="Duopoly that compete",5,IF(Z6="Too many players with High ROCE",5,0))))) | AB6: No | AC6: =IF(AB6="No",5,0) | AD6: Tailwind | AE6: =IF(AD6="Tailwind",10,0) | AF6: Structural (10 Years Consistency) | AG6: =IF(AF6="Structural (10 Years Consistency)",10,IF(AF6="Shallow Cyclical (2 to 3 years growth)",5,0)) | AH6: No | AI6: =IF(AH6="Yes due to Product Mix change or Operating Leverage",10,IF(AH6="Yes, these are peak margins",-5,IF(AH6="No",5,0))) | AJ6: Stable | AK6: =IF(AJ6="Stable",10,0) | AL6: Yes | AM6: =IF(AL6="Yes",10,0) | AN6: B2B | AO6: =IF(AN6="B2C",10,IF(AN6="B2B",5,0)) | AP6: Yes | AQ6: =IF(AP6="Yes",10,0) | AR6: Higher One Time, Lower Annuity | AS6: =IF(AR6="Fully Annuity",10,IF(AR6="Higher Annuity, Lower One Time",5,IF(AR6="Higher One Time, Lower Annuity",3,0))) | AT6: Good | AU6: =IF(AT6="Good",10,0) | AV6: Yes for more than 2 years | AW6: =IF(AV6="Yes for more than 2 years",10,IF(AV6="Yes only for next 1 to 2 years",5,0)) | AX6: Above 40 | AY6: =IF(AX6="Above 40",20,IF(AX6="20 to 40",10,IF(AX6="0 to 20",-5,0))) | AZ6: Between 50 to 75 | BA6: =IF(AZ6="Between 50 to 75",10,IF(AZ6="Above 75",0,0)) | BB6: Stage 2 | BC6: =IF(BB6="Stage 2",20,IF(BB6="Stage 1",0,IF(BB6="Stage 3",5,IF(BB6="Stage 4",-5,0)))) | BD6: Positive Trend | BE6: =IF(BD6="Positive Trend",20,IF(BD6="Negative Trend",-10,0)) | BF6: Uptrend | BG6: =IF(BF6="Uptrend",10,IF(BF6="Sideways",5,0)) | BH6: Uptrend | BI6: =IF(BH6="Uptrend",10,IF(BH6="Sideways",5,0)) | BJ6: Blue sky scenario | BK6: =IF(BJ6="Overhead supply in last 2 years in last 2 years",-5,IF(BJ6="Close to 52 week high or retracement",5,IF(BJ6="Blue sky scenario",10,IF(BJ6="Long term Downtrend",-10,0)))) | BL6: Yes | BM6: =IF(BL6="Yes",10,0) | BN6: More than 20% | BO6: =IF(BN6="More than 20%",10,IF(BN6="Between 12 to 20%",5,IF(BN6="Less than 12%",0,0))) | BP6: No | BQ6: =IF(BP6="No",10,0) | BR6: No | BS6: =IF(BR6="NO",5,0) | BT6: Above 2 | BU6: =IF(BT6="Above 2",0,IF(BT6="Between 1.5 to 2",5,IF(BT6="Less than 1.5",10,0))) | BV6: Above 70% | BW6: =IF(BV6="Above 70%",10,IF(BV6="Between 50% to 70%",5,IF(BV6="Less than 50%",0,IF(BV6="Negative",-10,IF(BV6="Less than 50% and Borrowings are increasing",-5,0))))) | BX6: Less than 0.7 | BY6: =IF(BX6="More than 1.2",-10,IF(BX6="Between 0.7 to 1.2",0,IF(BX6="Less than 0.7",10,0))) | BZ6: No | CA6: =IF(BZ6="Yes",-10,0) | CB6: Less than 15% | CC6: =IF(CB6="More than 15%",-10,IF(CB6="Less than 15%",10,0)) | CD6: No | CE6: =IF(CD6="Yes, more than 10%",-10,IF(CD6="No",10,0))
A7: =IF(B7=0,"",RANK(B7,$B$2:$B$314,0)) | B7: =SUM(N7,Y7,AA7,AC7,AE7,AG7,AI7,AK7,AM7,AO7,AQ7,AS7,AU7,AW7,AY7,BA7,BC7,BE7,BG7,BI7,BK7,BM7,BO7,BQ7,BS7,BU7,BW7,BY7,CA7,CC7,CE7) | C7: VENUSREM | D7: Venus Remedies Limited | E7: healthcare | F7: pharmaceuticals - indian - formulations | G7: smallcap | H7: 1980.72 | I7: 1555.8 | J7: 4.99 | K7: 282923 | L7: 97 | M7: Outperforming | N7: =IF(M7="Underperforming",-5,IF(L7>=95,15,IF(L7>=90,10,IF(L7>=80,5,0)))) | O7: 79.06 | P7: 45.62 | Q7: 1173.22 | R7: Volume Spike & Near 52W High Breakout | S7: Nifty Pharma | T7: 11.5 | U7: 261.81 | V7: 224.5 | W7: 61.02 | X7: Growing Industry | Y7: =IF(X7="Growing Industry",10,IF(X7="Cyclical in an Upturn",5,0)) | Z7: Too Many Players with High ROCE | AA7: =IF(Z7="Monopoly",10,IF(Z7="Oligopoly",5,IF(Z7="Duopoly that cooperate",10,IF(Z7="Duopoly that compete",5,IF(Z7="Too many players with High ROCE",5,0))))) | AB7: Yes | AC7: =IF(AB7="No",5,0) | AD7: Tailwind | AE7: =IF(AD7="Tailwind",10,0) | AF7: Structural (10 Years Consistency) | AG7: =IF(AF7="Structural (10 Years Consistency)",10,IF(AF7="Shallow Cyclical (2 to 3 years growth)",5,0)) | AH7: No | AI7: =IF(AH7="Yes due to Product Mix change or Operating Leverage",10,IF(AH7="Yes, these are peak margins",-5,IF(AH7="No",5,0))) | AJ7: Stable | AK7: =IF(AJ7="Stable",10,0) | AL7: Yes | AM7: =IF(AL7="Yes",10,0) | AN7: B2B | AO7: =IF(AN7="B2C",10,IF(AN7="B2B",5,0)) | AP7: Yes | AQ7: =IF(AP7="Yes",10,0) | AR7: Higher Annuity, Lower One Time | AS7: =IF(AR7="Fully Annuity",10,IF(AR7="Higher Annuity, Lower One Time",5,IF(AR7="Higher One Time, Lower Annuity",3,0))) | AT7: Good | AU7: =IF(AT7="Good",10,0) | AV7: Yes for more than 2 years | AW7: =IF(AV7="Yes for more than 2 years",10,IF(AV7="Yes only for next 1 to 2 years",5,0)) | AX7: Above 40 | AY7: =IF(AX7="Above 40",20,IF(AX7="20 to 40",10,IF(AX7="0 to 20",-5,0))) | AZ7: Above 75 | BA7: =IF(AZ7="Between 50 to 75",10,IF(AZ7="Above 75",0,0)) | BB7: Stage 2 | BC7: =IF(BB7="Stage 2",20,IF(BB7="Stage 1",0,IF(BB7="Stage 3",5,IF(BB7="Stage 4",-5,0)))) | BD7: Positive Trend | BE7: =IF(BD7="Positive Trend",20,IF(BD7="Negative Trend",-10,0)) | BF7: Uptrend | BG7: =IF(BF7="Uptrend",10,IF(BF7="Sideways",5,0)) | BH7: Uptrend | BI7: =IF(BH7="Uptrend",10,IF(BH7="Sideways",5,0)) | BJ7: Blue sky scenario | BK7: =IF(BJ7="Overhead supply in last 2 years in last 2 years",-5,IF(BJ7="Close to 52 week high or retracement",5,IF(BJ7="Blue sky scenario",10,IF(BJ7="Long term Downtrend",-10,0)))) | BL7: Yes | BM7: =IF(BL7="Yes",10,0) | BN7: More than 20% | BO7: =IF(BN7="More than 20%",10,IF(BN7="Between 12 to 20%",5,IF(BN7="Less than 12%",0,0))) | BP7: No | BQ7: =IF(BP7="No",10,0) | BR7: No | BS7: =IF(BR7="NO",5,0) | BT7: Above 2 | BU7: =IF(BT7="Above 2",0,IF(BT7="Between 1.5 to 2",5,IF(BT7="Less than 1.5",10,0))) | BV7: Above 70% | BW7: =IF(BV7="Above 70%",10,IF(BV7="Between 50% to 70%",5,IF(BV7="Less than 50%",0,IF(BV7="Negative",-10,IF(BV7="Less than 50% and Borrowings are increasing",-5,0))))) | BX7: Less than 0.7 | BY7: =IF(BX7="More than 1.2",-10,IF(BX7="Between 0.7 to 1.2",0,IF(BX7="Less than 0.7",10,0))) | BZ7: No | CA7: =IF(BZ7="Yes",-10,0) | CB7: Less than 15% | CC7: =IF(CB7="More than 15%",-10,IF(CB7="Less than 15%",10,0)) | CD7: No | CE7: =IF(CD7="Yes, more than 10%",-10,IF(CD7="No",10,0))
A8: =IF(B8=0,"",RANK(B8,$B$2:$B$314,0)) | B8: =SUM(N8,Y8,AA8,AC8,AE8,AG8,AI8,AK8,AM8,AO8,AQ8,AS8,AU8,AW8,AY8,BA8,BC8,BE8,BG8,BI8,BK8,BM8,BO8,BQ8,BS8,BU8,BW8,BY8,CA8,CC8,CE8) | C8: EMCURE | D8: Emcure Pharmaceuticals Ltd | E8: healthcare | F8: pharmaceuticals - indian - bulk drugs & formln | G8: largecap | H8: 32243.49 | I8: 1745.2 | J8: 2.62 | K8: 173206 | L8: 39 | M8: Outperforming | N8: =IF(M8="Underperforming",-5,IF(L8>=95,15,IF(L8>=90,10,IF(L8>=80,5,0)))) | O8: 65.05 | P8: 40.31 | Q8: 1367.39 | R8: Near 52W High Breakout | S8: Nifty Pharma | T8: 11.5 | U8: 31.75 | V8: 18.16 | W8: 10.65 | X8: Growing Industry | Y8: =IF(X8="Growing Industry",10,IF(X8="Cyclical in an Upturn",5,0)) | Z8: Too Many Players with High ROCE | AA8: =IF(Z8="Monopoly",10,IF(Z8="Oligopoly",5,IF(Z8="Duopoly that cooperate",10,IF(Z8="Duopoly that compete",5,IF(Z8="Too many players with High ROCE",5,0))))) | AB8: Yes | AC8: =IF(AB8="No",5,0) | AD8: Tailwind | AE8: =IF(AD8="Tailwind",10,0) | AF8: Structural (10 Years Consistency) | AG8: =IF(AF8="Structural (10 Years Consistency)",10,IF(AF8="Shallow Cyclical (2 to 3 years growth)",5,0)) | AH8: No | AI8: =IF(AH8="Yes due to Product Mix change or Operating Leverage",10,IF(AH8="Yes, these are peak margins",-5,IF(AH8="No",5,0))) | AJ8: Stable | AK8: =IF(AJ8="Stable",10,0) | AL8: Yes | AM8: =IF(AL8="Yes",10,0) | AN8: B2B | AO8: =IF(AN8="B2C",10,IF(AN8="B2B",5,0)) | AP8: Yes | AQ8: =IF(AP8="Yes",10,0) | AR8: Higher Annuity, Lower One Time | AS8: =IF(AR8="Fully Annuity",10,IF(AR8="Higher Annuity, Lower One Time",5,IF(AR8="Higher One Time, Lower Annuity",3,0))) | AT8: Good | AU8: =IF(AT8="Good",10,0) | AV8: Yes for more than 2 years | AW8: =IF(AV8="Yes for more than 2 years",10,IF(AV8="Yes only for next 1 to 2 years",5,0)) | AX8: Above 40 | AY8: =IF(AX8="Above 40",20,IF(AX8="20 to 40",10,IF(AX8="0 to 20",-5,0))) | AZ8: Between 50 to 75 | BA8: =IF(AZ8="Between 50 to 75",10,IF(AZ8="Above 75",0,0)) | BB8: Stage 2 | BC8: =IF(BB8="Stage 2",20,IF(BB8="Stage 1",0,IF(BB8="Stage 3",5,IF(BB8="Stage 4",-5,0)))) | BD8: Positive Trend | BE8: =IF(BD8="Positive Trend",20,IF(BD8="Negative Trend",-10,0)) | BF8: Uptrend | BG8: =IF(BF8="Uptrend",10,IF(BF8="Sideways",5,0)) | BH8: Uptrend | BI8: =IF(BH8="Uptrend",10,IF(BH8="Sideways",5,0)) | BJ8: Blue sky scenario | BK8: =IF(BJ8="Overhead supply in last 2 years in last 2 years",-5,IF(BJ8="Close to 52 week high or retracement",5,IF(BJ8="Blue sky scenario",10,IF(BJ8="Long term Downtrend",-10,0)))) | BL8: Yes | BM8: =IF(BL8="Yes",10,0) | BN8: More than 20% | BO8: =IF(BN8="More than 20%",10,IF(BN8="Between 12 to 20%",5,IF(BN8="Less than 12%",0,0))) | BP8: No | BQ8: =IF(BP8="No",10,0) | BR8: No | BS8: =IF(BR8="NO",5,0) | BT8: Less than 1.5 | BU8: =IF(BT8="Above 2",0,IF(BT8="Between 1.5 to 2",5,IF(BT8="Less than 1.5",10,0))) | BV8: Between 50% to 70% | BW8: =IF(BV8="Above 70%",10,IF(BV8="Between 50% to 70%",5,IF(BV8="Less than 50%",0,IF(BV8="Negative",-10,IF(BV8="Less than 50% and Borrowings are increasing",-5,0))))) | BX8: Less than 0.7 | BY8: =IF(BX8="More than 1.2",-10,IF(BX8="Between 0.7 to 1.2",0,IF(BX8="Less than 0.7",10,0))) | BZ8: No | CA8: =IF(BZ8="Yes",-10,0) | CB8: Less than 15% | CC8: =IF(CB8="More than 15%",-10,IF(CB8="Less than 15%",10,0)) | CD8: No | CE8: =IF(CD8="Yes, more than 10%",-10,IF(CD8="No",10,0))
A9: =IF(B9=0,"",RANK(B9,$B$2:$B$314,0)) | B9: =SUM(N9,Y9,AA9,AC9,AE9,AG9,AI9,AK9,AM9,AO9,AQ9,AS9,AU9,AW9,AY9,BA9,BC9,BE9,BG9,BI9,BK9,BM9,BO9,BQ9,BS9,BU9,BW9,BY9,CA9,CC9,CE9) | C9: RADICO | D9: Radico Khaitan Limited | E9: fmcg | F9: breweries & distilleries | G9: largecap | H9: 46383.58 | I9: 3502.4 | J9: 1.11 | K9: 247899 | L9: 45 | M9: Outperforming | N9: =IF(M9="Underperforming",-5,IF(L9>=95,15,IF(L9>=90,10,IF(L9>=80,5,0)))) | O9: 67.71 | P9: 30.24 | Q9: 2879.89 | R9: Near 52W High Breakout | S9: Nifty FMCG | T9: -13.6 | U9: 33.34 | V9: 54.33 | W9: 12.11 | X9: Growing Industry | Y9: =IF(X9="Growing Industry",10,IF(X9="Cyclical in an Upturn",5,0)) | Z9: Too Many Players with High ROCE | AA9: =IF(Z9="Monopoly",10,IF(Z9="Oligopoly",5,IF(Z9="Duopoly that cooperate",10,IF(Z9="Duopoly that compete",5,IF(Z9="Too many players with High ROCE",5,0))))) | AB9: No | AC9: =IF(AB9="No",5,0) | AD9: Tailwind | AE9: =IF(AD9="Tailwind",10,0) | AF9: Structural (10 Years Consistency) | AG9: =IF(AF9="Structural (10 Years Consistency)",10,IF(AF9="Shallow Cyclical (2 to 3 years growth)",5,0)) | AH9: No | AI9: =IF(AH9="Yes due to Product Mix change or Operating Leverage",10,IF(AH9="Yes, these are peak margins",-5,IF(AH9="No",5,0))) | AJ9: Stable | AK9: =IF(AJ9="Stable",10,0) | AL9: Yes | AM9: =IF(AL9="Yes",10,0) | AN9: B2C | AO9: =IF(AN9="B2C",10,IF(AN9="B2B",5,0)) | AP9: Yes | AQ9: =IF(AP9="Yes",10,0) | AR9: Higher Annuity, Lower One Time | AS9: =IF(AR9="Fully Annuity",10,IF(AR9="Higher Annuity, Lower One Time",5,IF(AR9="Higher One Time, Lower Annuity",3,0))) | AT9: Good | AU9: =IF(AT9="Good",10,0) | AV9: Yes for more than 2 years | AW9: =IF(AV9="Yes for more than 2 years",10,IF(AV9="Yes only for next 1 to 2 years",5,0)) | AX9: 20 to 40 | AY9: =IF(AX9="Above 40",20,IF(AX9="20 to 40",10,IF(AX9="0 to 20",-5,0))) | AZ9: Between 50 to 75 | BA9: =IF(AZ9="Between 50 to 75",10,IF(AZ9="Above 75",0,0)) | BB9: Stage 2 | BC9: =IF(BB9="Stage 2",20,IF(BB9="Stage 1",0,IF(BB9="Stage 3",5,IF(BB9="Stage 4",-5,0)))) | BD9: Positive Trend | BE9: =IF(BD9="Positive Trend",20,IF(BD9="Negative Trend",-10,0)) | BF9: Uptrend | BG9: =IF(BF9="Uptrend",10,IF(BF9="Sideways",5,0)) | BH9: Uptrend | BI9: =IF(BH9="Uptrend",10,IF(BH9="Sideways",5,0)) | BJ9: Blue sky scenario | BK9: =IF(BJ9="Overhead supply in last 2 years in last 2 years",-5,IF(BJ9="Close to 52 week high or retracement",5,IF(BJ9="Blue sky scenario",10,IF(BJ9="Long term Downtrend",-10,0)))) | BL9: Yes | BM9: =IF(BL9="Yes",10,0) | BN9: More than 20% | BO9: =IF(BN9="More than 20%",10,IF(BN9="Between 12 to 20%",5,IF(BN9="Less than 12%",0,0))) | BP9: No | BQ9: =IF(BP9="No",10,0) | BR9: Yes | BS9: =IF(BR9="NO",5,0) | BT9: Less than 1.5 | BU9: =IF(BT9="Above 2",0,IF(BT9="Between 1.5 to 2",5,IF(BT9="Less than 1.5",10,0))) | BV9: Above 70% | BW9: =IF(BV9="Above 70%",10,IF(BV9="Between 50% to 70%",5,IF(BV9="Less than 50%",0,IF(BV9="Negative",-10,IF(BV9="Less than 50% and Borrowings are increasing",-5,0))))) | BX9: Less than 0.7 | BY9: =IF(BX9="More than 1.2",-10,IF(BX9="Between 0.7 to 1.2",0,IF(BX9="Less than 0.7",10,0))) | BZ9: No | CA9: =IF(BZ9="Yes",-10,0) | CB9: Less than 15% | CC9: =IF(CB9="More than 15%",-10,IF(CB9="Less than 15%",10,0)) | CD9: No | CE9: =IF(CD9="Yes, more than 10%",-10,IF(CD9="No",10,0))
A10: =IF(B10=0,"",RANK(B10,$B$2:$B$314,0)) | B10: =SUM(N10,Y10,AA10,AC10,AE10,AG10,AI10,AK10,AM10,AO10,AQ10,AS10,AU10,AW10,AY10,BA10,BC10,BE10,BG10,BI10,BK10,BM10,BO10,BQ10,BS10,BU10,BW10,BY10,CA10,CC10,CE10) | C10: MTARTECH | D10: MTAR Technologies Ltd | E10: aerospace & defence | F10: engineering | G10: largecap | H10: 22971.26 | I10: 7755.5 | J10: 3.85 | K10: 1275473 | L10: 98 | M10: Outperforming | N10: =IF(M10="Underperforming",-5,IF(L10>=95,15,IF(L10>=90,10,IF(L10>=80,5,0)))) | O10: 85.85 | P10: 64.1 | Q10: 5930.54 | R10: Near 52W High Breakout | S10: Nifty 50 | T10: -6.35 | U10: 337.99 | V10: 367.67 | W10: 63.52 | X10: Growing Industry | Y10: =IF(X10="Growing Industry",10,IF(X10="Cyclical in an Upturn",5,0)) | Z10: Too Many Players with High ROCE | AA10: =IF(Z10="Monopoly",10,IF(Z10="Oligopoly",5,IF(Z10="Duopoly that cooperate",10,IF(Z10="Duopoly that compete",5,IF(Z10="Too many players with High ROCE",5,0))))) | AB10: No | AC10: =IF(AB10="No",5,0) | AD10: Tailwind | AE10: =IF(AD10="Tailwind",10,0) | AF10: Structural (10 Years Consistency) | AG10: =IF(AF10="Structural (10 Years Consistency)",10,IF(AF10="Shallow Cyclical (2 to 3 years growth)",5,0)) | AH10: No | AI10: =IF(AH10="Yes due to Product Mix change or Operating Leverage",10,IF(AH10="Yes, these are peak margins",-5,IF(AH10="No",5,0))) | AJ10: Stable | AK10: =IF(AJ10="Stable",10,0) | AL10: Yes | AM10: =IF(AL10="Yes",10,0) | AN10: B2B | AO10: =IF(AN10="B2C",10,IF(AN10="B2B",5,0)) | AP10: Yes | AQ10: =IF(AP10="Yes",10,0) | AR10: Higher One Time, Lower Annuity | AS10: =IF(AR10="Fully Annuity",10,IF(AR10="Higher Annuity, Lower One Time",5,IF(AR10="Higher One Time, Lower Annuity",3,0))) | AT10: Good | AU10: =IF(AT10="Good",10,0) | AV10: Yes for more than 2 years | AW10: =IF(AV10="Yes for more than 2 years",10,IF(AV10="Yes only for next 1 to 2 years",5,0)) | AX10: Above 40 | AY10: =IF(AX10="Above 40",20,IF(AX10="20 to 40",10,IF(AX10="0 to 20",-5,0))) | AZ10: Above 75 | BA10: =IF(AZ10="Between 50 to 75",10,IF(AZ10="Above 75",0,0)) | BB10: Stage 2 | BC10: =IF(BB10="Stage 2",20,IF(BB10="Stage 1",0,IF(BB10="Stage 3",5,IF(BB10="Stage 4",-5,0)))) | BD10: Positive Trend | BE10: =IF(BD10="Positive Trend",20,IF(BD10="Negative Trend",-10,0)) | BF10: Uptrend | BG10: =IF(BF10="Uptrend",10,IF(BF10="Sideways",5,0)) | BH10: Uptrend | BI10: =IF(BH10="Uptrend",10,IF(BH10="Sideways",5,0)) | BJ10: Blue sky scenario | BK10: =IF(BJ10="Overhead supply in last 2 years in last 2 years",-5,IF(BJ10="Close to 52 week high or retracement",5,IF(BJ10="Blue sky scenario",10,IF(BJ10="Long term Downtrend",-10,0)))) | BL10: Yes | BM10: =IF(BL10="Yes",10,0) | BN10: More than 20% | BO10: =IF(BN10="More than 20%",10,IF(BN10="Between 12 to 20%",5,IF(BN10="Less than 12%",0,0))) | BP10: No | BQ10: =IF(BP10="No",10,0) | BR10: Yes | BS10: =IF(BR10="NO",5,0) | BT10: Above 2 | BU10: =IF(BT10="Above 2",0,IF(BT10="Between 1.5 to 2",5,IF(BT10="Less than 1.5",10,0))) | BV10: Above 70% | BW10: =IF(BV10="Above 70%",10,IF(BV10="Between 50% to 70%",5,IF(BV10="Less than 50%",0,IF(BV10="Negative",-10,IF(BV10="Less than 50% and Borrowings are increasing",-5,0))))) | BX10: Less than 0.7 | BY10: =IF(BX10="More than 1.2",-10,IF(BX10="Between 0.7 to 1.2",0,IF(BX10="Less than 0.7",10,0))) | BZ10: No | CA10: =IF(BZ10="Yes",-10,0) | CB10: Less than 15% | CC10: =IF(CB10="More than 15%",-10,IF(CB10="Less than 15%",10,0)) | CD10: No | CE10: =IF(CD10="Yes, more than 10%",-10,IF(CD10="No",10,0))
A11: =IF(B11=0,"",RANK(B11,$B$2:$B$314,0)) | B11: =SUM(N11,Y11,AA11,AC11,AE11,AG11,AI11,AK11,AM11,AO11,AQ11,AS11,AU11,AW11,AY11,BA11,BC11,BE11,BG11,BI11,BK11,BM11,BO11,BQ11,BS11,BU11,BW11,BY11,CA11,CC11,CE11) | C11: INDOBORAX | D11: Indo Borax & Chemicals Ltd | E11: chemicals | F11: chemicals | G11: smallcap | H11: 1110.63 | I11: 358.7 | J11: 3.64 | K11: 193416 | L11: 74 | M11: Outperforming | N11: =IF(M11="Underperforming",-5,IF(L11>=95,15,IF(L11>=90,10,IF(L11>=80,5,0)))) | O11: 80.7 | P11: 45.78 | Q11: 283.7 | R11: Near 52W High Breakout | S11: Nifty 50 | T11: -6.35 | U11: 83.56 | V11: 96 | W11: 23.41 | X11: Growing Industry | Y11: =IF(X11="Growing Industry",10,IF(X11="Cyclical in an Upturn",5,0)) | Z11: Too Many Players with High ROCE | AA11: =IF(Z11="Monopoly",10,IF(Z11="Oligopoly",5,IF(Z11="Duopoly that cooperate",10,IF(Z11="Duopoly that compete",5,IF(Z11="Too many players with High ROCE",5,0))))) | AB11: No | AC11: =IF(AB11="No",5,0) | AD11: Tailwind | AE11: =IF(AD11="Tailwind",10,0) | AF11: Structural (10 Years Consistency) | AG11: =IF(AF11="Structural (10 Years Consistency)",10,IF(AF11="Shallow Cyclical (2 to 3 years growth)",5,0)) | AH11: No | AI11: =IF(AH11="Yes due to Product Mix change or Operating Leverage",10,IF(AH11="Yes, these are peak margins",-5,IF(AH11="No",5,0))) | AJ11: Stable | AK11: =IF(AJ11="Stable",10,0) | AL11: Yes | AM11: =IF(AL11="Yes",10,0) | AN11: B2B | AO11: =IF(AN11="B2C",10,IF(AN11="B2B",5,0)) | AP11: Yes | AQ11: =IF(AP11="Yes",10,0) | AR11: Higher One Time, Lower Annuity | AS11: =IF(AR11="Fully Annuity",10,IF(AR11="Higher Annuity, Lower One Time",5,IF(AR11="Higher One Time, Lower Annuity",3,0))) | AT11: Good | AU11: =IF(AT11="Good",10,0) | AV11: Yes for more than 2 years | AW11: =IF(AV11="Yes for more than 2 years",10,IF(AV11="Yes only for next 1 to 2 years",5,0)) | AX11: Above 40 | AY11: =IF(AX11="Above 40",20,IF(AX11="20 to 40",10,IF(AX11="0 to 20",-5,0))) | AZ11: Above 75 | BA11: =IF(AZ11="Between 50 to 75",10,IF(AZ11="Above 75",0,0)) | BB11: Stage 2 | BC11: =IF(BB11="Stage 2",20,IF(BB11="Stage 1",0,IF(BB11="Stage 3",5,IF(BB11="Stage 4",-5,0)))) | BD11: Positive Trend | BE11: =IF(BD11="Positive Trend",20,IF(BD11="Negative Trend",-10,0)) | BF11: Uptrend | BG11: =IF(BF11="Uptrend",10,IF(BF11="Sideways",5,0)) | BH11: Uptrend | BI11: =IF(BH11="Uptrend",10,IF(BH11="Sideways",5,0)) | BJ11: Blue sky scenario | BK11: =IF(BJ11="Overhead supply in last 2 years in last 2 years",-5,IF(BJ11="Close to 52 week high or retracement",5,IF(BJ11="Blue sky scenario",10,IF(BJ11="Long term Downtrend",-10,0)))) | BL11: Yes | BM11: =IF(BL11="Yes",10,0) | BN11: More than 20% | BO11: =IF(BN11="More than 20%",10,IF(BN11="Between 12 to 20%",5,IF(BN11="Less than 12%",0,0))) | BP11: No | BQ11: =IF(BP11="No",10,0) | BR11: No | BS11: =IF(BR11="NO",5,0) | BT11: Less than 1.5 | BU11: =IF(BT11="Above 2",0,IF(BT11="Between 1.5 to 2",5,IF(BT11="Less than 1.5",10,0))) | BV11: Above 70% | BW11: =IF(BV11="Above 70%",10,IF(BV11="Between 50% to 70%",5,IF(BV11="Less than 50%",0,IF(BV11="Negative",-10,IF(BV11="Less than 50% and Borrowings are increasing",-5,0))))) | BX11: Less than 0.7 | BY11: =IF(BX11="More than 1.2",-10,IF(BX11="Between 0.7 to 1.2",0,IF(BX11="Less than 0.7",10,0))) | BZ11: No | CA11: =IF(BZ11="Yes",-10,0) | CB11: Less than 15% | CC11: =IF(CB11="More than 15%",-10,IF(CB11="Less than 15%",10,0)) | CD11: No | CE11: =IF(CD11="Yes, more than 10%",-10,IF(CD11="No",10,0))
A12: =IF(B12=0,"",RANK(B12,$B$2:$B$314,0)) | B12: =SUM(N12,Y12,AA12,AC12,AE12,AG12,AI12,AK12,AM12,AO12,AQ12,AS12,AU12,AW12,AY12,BA12,BC12,BE12,BG12,BI12,BK12,BM12,BO12,BQ12,BS12,BU12,BW12,BY12,CA12,CC12,CE12) | C12: GVT&D | D12: GE Vernova T&D India Ltd | E12: industrials | F12: electric equipment | G12: largecap | H12: 127114.3 | I12: 5086.5 | J12: 2.46 | K12: 999168 | L12: 77 | M12: Outperforming | N12: =IF(M12="Underperforming",-5,IF(L12>=95,15,IF(L12>=90,10,IF(L12>=80,5,0)))) | O12: 73.43 | P12: 49.15 | Q12: 3909.14 | R12: Near 52W High Breakout | S12: Nifty 50 | T12: -6.35 | U12: 120.06 | V12: 134.96 | W12: 24.46 | X12: Cyclical in an Upturn | Y12: =IF(X12="Growing Industry",10,IF(X12="Cyclical in an Upturn",5,0)) | Z12: Too Many Players with High ROCE | AA12: =IF(Z12="Monopoly",10,IF(Z12="Oligopoly",5,IF(Z12="Duopoly that cooperate",10,IF(Z12="Duopoly that compete",5,IF(Z12="Too many players with High ROCE",5,0))))) | AB12: No | AC12: =IF(AB12="No",5,0) | AD12: Tailwind | AE12: =IF(AD12="Tailwind",10,0) | AF12: Structural (10 Years Consistency) | AG12: =IF(AF12="Structural (10 Years Consistency)",10,IF(AF12="Shallow Cyclical (2 to 3 years growth)",5,0)) | AH12: No | AI12: =IF(AH12="Yes due to Product Mix change or Operating Leverage",10,IF(AH12="Yes, these are peak margins",-5,IF(AH12="No",5,0))) | AJ12: Stable | AK12: =IF(AJ12="Stable",10,0) | AL12: Yes | AM12: =IF(AL12="Yes",10,0) | AN12: B2B | AO12: =IF(AN12="B2C",10,IF(AN12="B2B",5,0)) | AP12: Yes | AQ12: =IF(AP12="Yes",10,0) | AR12: Higher One Time, Lower Annuity | AS12: =IF(AR12="Fully Annuity",10,IF(AR12="Higher Annuity, Lower One Time",5,IF(AR12="Higher One Time, Lower Annuity",3,0))) | AT12: Good | AU12: =IF(AT12="Good",10,0) | AV12: Yes for more than 2 years | AW12: =IF(AV12="Yes for more than 2 years",10,IF(AV12="Yes only for next 1 to 2 years",5,0)) | AX12: Above 40 | AY12: =IF(AX12="Above 40",20,IF(AX12="20 to 40",10,IF(AX12="0 to 20",-5,0))) | AZ12: Between 50 to 75 | BA12: =IF(AZ12="Between 50 to 75",10,IF(AZ12="Above 75",0,0)) | BB12: Stage 2 | BC12: =IF(BB12="Stage 2",20,IF(BB12="Stage 1",0,IF(BB12="Stage 3",5,IF(BB12="Stage 4",-5,0)))) | BD12: Positive Trend | BE12: =IF(BD12="Positive Trend",20,IF(BD12="Negative Trend",-10,0)) | BF12: Uptrend | BG12: =IF(BF12="Uptrend",10,IF(BF12="Sideways",5,0)) | BH12: Uptrend | BI12: =IF(BH12="Uptrend",10,IF(BH12="Sideways",5,0)) | BJ12: Blue sky scenario | BK12: =IF(BJ12="Overhead supply in last 2 years in last 2 years",-5,IF(BJ12="Close to 52 week high or retracement",5,IF(BJ12="Blue sky scenario",10,IF(BJ12="Long term Downtrend",-10,0)))) | BL12: Yes | BM12: =IF(BL12="Yes",10,0) | BN12: More than 20% | BO12: =IF(BN12="More than 20%",10,IF(BN12="Between 12 to 20%",5,IF(BN12="Less than 12%",0,0))) | BP12: No | BQ12: =IF(BP12="No",10,0) | BR12: Yes | BS12: =IF(BR12="NO",5,0) | BT12: Less than 1.5 | BU12: =IF(BT12="Above 2",0,IF(BT12="Between 1.5 to 2",5,IF(BT12="Less than 1.5",10,0))) | BV12: Above 70% | BW12: =IF(BV12="Above 70%",10,IF(BV12="Between 50% to 70%",5,IF(BV12="Less than 50%",0,IF(BV12="Negative",-10,IF(BV12="Less than 50% and Borrowings are increasing",-5,0))))) | BX12: Less than 0.7 | BY12: =IF(BX12="More than 1.2",-10,IF(BX12="Between 0.7 to 1.2",0,IF(BX12="Less than 0.7",10,0))) | BZ12: No | CA12: =IF(BZ12="Yes",-10,0) | CB12: Less than 15% | CC12: =IF(CB12="More than 15%",-10,IF(CB12="Less than 15%",10,0)) | CD12: No | CE12: =IF(CD12="Yes, more than 10%",-10,IF(CD12="No",10,0))
