Workbook

Sheet Read Me
A1: 🏆 MONIT MULTIBAGGER RESEARCH ENGINE & SCANNER
A2: Daily Analytics Report | Generated: Monday, 10 August 2026
A5: 📖 QUICK REFERENCE RUNBOOK & SYSTEM FLOW
A6: Step 1: Reference this Read Me | B6: Understand terms, formulas, and underlying investment theses directly in this glossary dashboard.
A7: Step 2: Check Leaderboard Tab | B7: Locate long-term compounders with high Persistence Scores and streaks (institutional accumulation footprint).
A8: Step 3: Analyze Confluence Overlap | B8: Review the ultimate high-conviction candidates intersecting our scanner signals and StockScans overlaps.
A9: Step 4: Scoring Monit Tabs | B9: Open 'Monit Non Financial' or 'Monit Banks NBFC' to fill out your qualitative checks (Tailwinds, Promoters, Triggers).
A10: Step 5: Track Scan Matches | B10: Confirm consensus using 'Scan Match' tabs which score companies by total appearances across allStockScans.
A13: 📊 RESEARCH ENGINE GLOSSARY, METRICS & THESES
A15: Metric Term / Tab Name | B15: Practical Meaning & Underlying Investment Thesis | C15: Automated DB Query / Logic & Excel Formula
A16: EMA Crossover (Birth of a Trend) | B16: An entry signal triggered when price crosses above its 200-day EMA. [THESIS]: Represents the birth of a new long-term uptrend. Buying here provides maximum asymmetrical risk-to-reward because the entry is close to the logical stop-loss (the EMA itself). | C16: pine_signal == 'EMA Crossover' Sized at 7% capital allocation (~₹70,000 per position).
A17: 52W Breakout (Momentum Confirmation) | B17: A momentum signal triggered when a stock above its 200-day EMA breaks out to fresh 52-week highs. [THESIS]: Represents a confirmed breakout where institutional buying pressure clears all historical supply. High momentum outperformance. | C17: pine_signal == '52W Breakout' Sized at 5% capital allocation (~₹50,000 per position).
A18: ATH Momentum (Runaway Leader) | B18: An established trend signal triggered when the price is actively running near its All-Time Highs. [THESIS]: Identifies the strongest runaway leaders in the market. Ideal for high-velocity momentum trading where price experiences immediate continuation. | C18: pine_signal == 'ATH Momentum' Sized at 4% capital allocation (~₹40,000 per position).
A19: Persistence Score (30D) (Accumulation Footprint) | B19: The count of times a stock has appeared in the daily screener during the last 30 active trading days. [THESIS]: Represents persistent institutional buying. Random spikes appear 1-2 times, but compounders appear 10+ times as institutions accumulate. | C19: Queries the local SQLite database (`logs/backtest.db`) to sum the total number of distinct dates the ticker appeared on the screener during the last 30 active trading days. Formula: COUNT(DISTINCT date)
A20: Consecutive Streak Days (Uninterrupted Trend) | B20: The number of consecutive trading days that the stock has appeared in the screener up to today. [THESIS]: High streaks indicate an exceptionally strong, uninterrupted runaway trend with heavy daily buying pressure. | C20: Checks the chronological sequence of scanner dates in SQLite starting from the most recent run date and counting backward. The streak increments for every contiguous date the ticker appears.
A21: Sector Velocity WoW (Early Sector Rotation) | B21: Compares the volume of screener signals in a sector over the last 5 trading days (W1) against the previous 5 trading days (W2). [THESIS]: Detects early sector rotation. A sudden positive surge warns you of capital flowing aggressively into a specific theme. | C21: Counts appearances of all tickers categorized by their sector. Formula: W1_Count = COUNT(records WHERE date IN last 5 trading days) W2_Count = COUNT(records WHERE date IN days -10 to -5) Velocity % = ((W1_Count - W2_Count) / W2_Count) * 100
A22: Emerging Leaders (Momentum Expansion) | B22: Identifies breakout stocks experiencing a sudden momentum expansion. [THESIS]: Finds stocks with a high concentration of appearances recently but almost zero history in the preceding months. Represents new institutional entries. | C22: Finds stocks with at least 5 appearances in the last 10 trading days, but less than or equal to 3 appearances in the prior 50 trading days (i.e. trading days -60 to -10). Formula: COUNT(recent) >= 5 AND COUNT(historical) <= 3
A23: Tab: Confluence Overlap (The Ultimate Overlap) | B23: This sheet displays the absolute highest conviction watchlist candidates intersecting multiple strategies. [THESIS]: Filters out market noise by only displaying stocks appearing in at least two out of three major momentum dimensions: (1) Chartink screener universe, (2) Active scanner signals, and (3) StockScans overlap list. | C23: Calculates the mathematical intersection of the three sets: In_Universe + In_Scanner + In_StockScans >= 2 Single-dimension matches are automatically filtered out to eliminate market noise.
A24: Tab: Monit Non Financial (CHECKLIST SHEET) | B24: Your main watchlist scoring sheet for non-financial companies. [THESIS]: Keeps watchlist scoring fully formula-driven using Excel formulas. It combines automated metrics (RSI, ADX, V-stop, Persistence) with your qualitative scores (Promoter Buying, Near-Term Trigger, Headwind/Tailwind). | C24: Uses relative index-matching formulas to populate automated close prices, RSI, ADX, V-stop, and Persistence from the SQLite and Chartink universe sheets. Formula: INDEX-MATCH left-lookup.
A25: Tab: Monit Banks NBFC (BANKING CHECKLIST) | B25: Your main watchlist scoring sheet for banking and NBFC companies. [THESIS]: Tailored specifically for banking structures, incorporating specialized metrics like Net Interest Margins (NIM) and Credit Costs alongside technical indicators. | C25: Features banking-specific checklist criteria to ensure qualitative analyst inputs align with bank metrics.
A26: Tab: Scan Match tabs (StockScans Confluence) | B26: Displays the top 100 stocks appearing across all StockScans screeners. [THESIS]: Scores stocks qualitatively by scan volume. Stocks appearing in >20 scans receive a premium 10-point bonus, proving market-wide momentum consensus. | C26: Applies a nested Excel IF formula: `=IF(D8>20,10,IF(D8>=10,5,2))` Scores: >20 scans = 10 pts; 10-20 scans = 5 pts; <10 scans = 2 pts.
... A36: Weekly Tracking Highlighting (Additions / Removals) | B36: Visual highlights indicating weekly changes in the StockScans 100 (Scan Match) list. [THESIS]: Helps track the weekly turnover. Newly added candidates indicate fresh institutional attention, while removed candidates represent names losing relative strength. | C36: Compares daily lists against Monday's baseline database: - Added stocks: Highlighted in Soft Blue. - Removed stocks: Listed in the bottom section of Scan Match sheets.

Sheet Leaderboard
A1: 🌟 MULTIBAGGER MOMENTUM & SECTOR ROTATION LEADERBOARD 🌟
A4: TOP PERSISTENT MOMENTUM LEADERS (30D) | J4: SECTOR MOMENTUM VELOCITY HEATMAP (WoW)
A5: Rank | B5: Score | C5: Symbol | D5: Company Name | E5: Sector | F5: Streak (Days) | G5: Market Cap Cr | H5: Classification | J5: Sector Name | K5: Current Wk Count | L5: Previous Wk Count | M5: Velocity WoW %
A6: 1 | B6: 576 | C6: WELCORP | D6: Welspun Corp Limited | E6: industrials | F6: 81 | G6: 48532.2 | H6: Potential Leader | J6: power & utilities | K6: 15 | L6: 5 | M6: 200.0%
A7: 2 | B7: 468 | C7: BLSE | D7: BLS E-Services Ltd | E7: i.t | F7: 63 | G7: 2821.55 | H7: Potential Leader | J7: aerospace & defence | K7: 54 | L7: 24 | M7: 125.0%
A8: 3 | B8: 462 | C8: LAURUSLABS | D8: Laurus Labs Limited | E8: healthcare | F8: 62 | G8: 99638.23 | H8: Potential Leader | J8: metals & mining | K8: 127 | L8: 68 | M8: 86.8%
A9: 4 | B9: 396 | C9: YASHO | D9: Yasho Industries Ltd | E9: chemicals | F9: 51 | G9: 5006.95 | H9: Potential Leader | J9: miscellaneous | K9: 64 | L9: 41 | M9: 56.1%
A10: 5 | B10: 390 | C10: CUPID | D10: Cupid Limited | E10: fmcg | F10: 50 | G10: 35247.59 | H10: Potential Leader | J10: industrials | K10: 271 | L10: 182 | M10: 48.9%
A11: 6 | B11: 360 | C11: SPECTRUM | D11: Spectrum Electrical Industries Ltd | E11: industrials | F11: 45 | G11: 3835.28 | H11: Potential Leader | J11: energy | K11: 58 | L11: 39 | M11: 48.7%
A12: 7 | B12: 330 | C12: VADILALIND | D12: Vadilal Industries Limited | E12: fmcg | F12: 40 | G12: 5180.63 | H12: Potential Leader | J12: fmcg | K12: 129 | L12: 92 | M12: 40.2%
A13: 8 | B13: 324 | C13: FEDERALBNK | D13: The Federal Bank Limited | E13: bank | F13: 39 | G13: 87923.89 | H13: Potential Leader | J13: realty | K13: 66 | L13: 48 | M13: 37.5%
A14: 9 | B14: 312 | C14: HITECHCORP | D14: Hitech Corporation | E14: industrials | F14: 37 | G14: 553.57 | H14: Potential Leader | J14: building materials | K14: 74 | L14: 54 | M14: 37.0%
A15: 10 | B15: 282 | C15: SSWL | D15: Steel Strips Wheels Limited | E15: auto | F15: 32 | G15: 4849.02 | H15: Potential Leader | J15: auto | K15: 233 | L15: 171 | M15: 36.3%
A16: 11 | B16: 261 | C16: ADOR | D16: Ador Welding Ltd | E16: industrials | F16: 29 | G16: 2581.53 | H16: Potential Leader | J16: chemicals | K16: 162 | L16: 121 | M16: 33.9%
A17: 12 | B17: 261 | C17: CENTENKA | D17: Century Enka Limited | E17: textiles | F17: 29 | G17: 1333.43 | H17: Potential Leader | J17: textiles | K17: 95 | L17: 72 | M17: 31.9%
... A20: 15 | B20: 261 | C20: KAMDHENU | D20: Kamdhenu Limited | E20: metals & mining | F20: 29 | G20: 991.66 | H20: Potential Leader | J20: healthcare | K20: 222 | L20: 179 | M20: 24.0%
A21: 16 | B21: 261 | C21: RADICO | D21: Radico Khaitan Limited | E21: fmcg | F21: 29 | G21: 60255.71 | H21: Potential Leader
A22: 17 | B22: 261 | C22: RPTECH | D22: Rashi Peripherals Ltd | E22: services | F22: 29 | G22: 5895.71 | H22: Potential Leader
A23: 18 | B23: 261 | C23: TBZ | D23: Tribhovandas Bhimji Zaveri Limited | E23: consumer discretionary | F23: 29 | G23: 1821.75 | H23: Potential Leader
A24: 19 | B24: 252 | C24: ESAFSFB | D24: ESAF Small Finance Bank Ltd | E24: bank | F24: 28 | G24: 2077.74 | H24: Potential Leader
A25: 20 | B25: 252 | C25: GABRIEL | D25: Gabriel India Limited | E25: auto | F25: 28 | G25: 26580.96 | H25: Potential Leader
A28: 🌟 EMERGING LEADERS (MOMENTUM EXPANSION) | J28: 💎 SATELLITE HOLDINGS SHORTLIST (MCAP < 25K CR)
A29: Symbol | B29: Company Name | C29: Sector | D29: Recent Matches (10D) | E29: Historical Matches | F29: Market Cap Cr | J29: Symbol | K29: Sector | L29: Monit Score | M29: Market Cap Cr | N29: Appearances (30D)
A30: M&M | B30: Mahindra & Mahindra Limited | C30: auto | D30: 10 | E30: 2 | F30: 435483.8 | J30: SBCL | K30: metals & mining | L30: 247 | M30: 5304.77 | N30: 21
A31: PNB | B31: Punjab National Bank Ltd | C31: bank | D31: 10 | E31: 2 | F31: 131950.48 | J31: PIXTRANS | K31: fmcg | L31: 237 | M31: 2339.72 | N31: 18
A32: ETERNAL | B32: Eternal Ltd | C32: i.t | D32: 10 | E32: 0 | F32: 303986.05 | J32: ARMANFIN | K32: financials | L32: 235 | M32: 2136.6 | N32: 17
A33: VRLLOG | B33: Vrl Logistics Limited | C33: transportation | D33: 10 | E33: 1 | F33: 4921.85 | J33: APCOTEXIND | K33: chemicals | L33: 232 | M33: 3187.43 | N33: 25
A34: LODHA | B34: Lodha Developers Ltd | C34: realty | D34: 10 | E34: 2 | F34: 121759.64 | J34: IBULLSLTD | K34: Real Estate | L34: 230 | M34: 6447 | N34: 23
A35: GLAXO | B35: Glaxosmithkline Pharmaceuticals Limited | C35: healthcare | D35: 9 | E35: 0 | F35: 44040.49 | J35: CONFIPET | K35: miscellaneous | L35: 228 | M35: 2700.46 | N35: 24
A36: COFORGE | B36: Coforge (Niit Tech) Ltd | C36: i.t | D36: 9 | E36: 0 | F36: 78621.89 | J36: RPEL | K36: building materials | L36: 228 | M36: 5770.09 | N36: 22
A37: PERSISTENT | B37: Persistent Systems Limited | C37: i.t | D37: 9 | E37: 1 | F37: 86368.13 | J37: PRICOLLTD | K37: auto | L37: 227 | M37: 8993.64 | N37: 20
A38: TARSONS | B38: Tarsons Products Ltd | C38: healthcare | D38: 9 | E38: 1 | F38: 1661.63 | J38: IOLCP | K38: healthcare | L38: 227 | M38: 4926.86 | N38: 17
A39: LANDMARK | B39: Landmark Cars Ltd | C39: consumer discretionary | D39: 9 | E39: 2 | F39: 2218.58 | J39: RPTECH | K39: services | L39: 225 | M39: 5895.71 | N39: 29
A40: ANTHEM | B40: Anthem Biosciences Ltd | C40: healthcare | D40: 8 | E40: 0 | F40: 47380.66 | J40: TINNARUBR | K40: fmcg | L40: 225 | M40: 1996.33 | N40: 28
A41: SMLMAH | B41: SML Mahindra Ltd | C41: auto | D41: 8 | E41: 0 | F41: 8037.55 | J41: KTKBANK | K41: bank | L41: 225 | M41: 11724.3 | N41: 23
A45: 🚀 HIGH MOMENTUM LEADERS (RS RATING >= 90)
A46: Rank | B46: RS Rating | C46: O'Neil Score | D46: Monit Score | E46: Symbol | F46: Company Name | G46: Sector | H46: Market Cap Cr
A47: 1 | B47: 99 | C47: 110.03 | D47: 215 | E47: AXISOL | F47: Axis Solutions Limited | G47: Industrials | H47: 2194.45
A48: 2 | B48: 99 | C48: 76.51 | D48: 217 | E48: CUPID | F48: Cupid Limited | G48: fmcg | H48: 35247.59
A49: 3 | B49: 99 | C49: 74.59 | D49: 190 | E49: SIGMAADV | F49: Sigma Advanced System Ltd | G49: aerospace & defence | H49: 13282.73
...

Sheet Chartink Universe
A1: symbol | B1: company | C1: sector | D1: industry | E1: marketcap_bucket | F1: marketcap_cr | G1: close | H1: today_return_pct | I1: volume | J1: bse_code
A2: UNIVCABLES | B2: Universal Cables Limited | C2: industrials | D2: cables - power | E2: smallcap | F2: 4896.21 | G2: 1693.4 | H2: 20 | I2: 1907323 | J2: 504212
A3: AARTIPHARM | B3: Aarti Pharmalabs Ltd | C3: healthcare | D3: pharmaceuticals - indian - bulk drugs & formln | E3: midcap | F3: 6219.28 | G3: 823 | H3: 20 | I3: 3125635 | J3: 543748
A4: SBCL | B4: Shivalik Bimetal Controls Ltd | C4: metals & mining | D4: mining / minerals / metals | E4: midcap | F4: 5304.77 | G4: 1105.05 | H4: 20 | I4: 10977326 | J4: 513097
A5: COMSYN | B5: Commercial Syn Bags Ltd | C5: industrials | D5: packaging | E5: smallcap | F5: 906.95 | G5: 269.03 | H5: 19.66 | I5: 7601735 | J5: 539986
A6: PIXTRANS | B6: Pix Transmission Ltd | C6: fmcg | D6: miscellaneous | E6: smallcap | F6: 2339.72 | G6: 1986.5 | H6: 15.68 | I6: 1309397 | J6: 500333
A7: KABRAEXTRU | B7: Kabra Extrusion Technik Limited | C7: industrials | D7: engineering | E7: smallcap | F7: 1568.88 | G7: 510.75 | H7: 13.85 | I7: 2087592 | J7: 524109
A8: ANDHRSUGAR | B8: The Andhra Sugars Limited | C8: chemicals | D8: chlor alkali / soda ash | E8: smallcap | F8: 1192.44 | G8: 99.98 | H8: 13.64 | I8: 17423821 | J8: 590062
A9: DMCC | B9: DMCC Speciality Chemicals Ltd | C9: chemicals | D9: chemicals | E9: smallcap | F9: 692.46 | G9: 313.1 | H9: 12.77 | I9: 1241573 | J9: 506405
A10: JGCHEM | B10: J.G.Chemicals Ltd | C10: chemicals | D10: chemicals | E10: smallcap | F10: 2166.21 | G10: 622.2 | H10: 12.55 | I10: 10811484
A11: RAMCOIND | B11: Ramco Industries Limited | C11: building materials | D11: cement products | E11: smallcap | F11: 2949.57 | G11: 377.2 | H11: 11.06 | I11: 21233222 | J11: 532369
A12: POWERINDIA | B12: Hitachi Energy India Ltd | C12: industrials | D12: electric equipment | E12: largecap | F12: 145305.9 | G12: 36050 | H12: 10.58 | I12: 1348196 | J12: 543187
A13: PAYTM | B13: One 97 Communications Ltd | C13: i.t | D13: miscellaneous | E13: largecap | F13: 92310.98 | G13: 1584.1 | H13: 9.88 | I13: 39982128 | J13: 543396
A14: EMIL | B14: Electronics Mart India Ltd | C14: consumer discretionary | D14: trading | E14: midcap | F14: 6380.29 | G14: 180.77 | H14: 9.01 | I14: 101219512 | J14: 543626
A15: VINDHYATEL | B15: Vindhya Telelinks Limited | C15: realty | D15: construction | E15: smallcap | F15: 2656.61 | G15: 2438.4 | H15: 8.77 | I15: 290828 | J15: 517015
A16: MACPOWER | B16: Macpower CNC Machines Ltd | C16: industrials | D16: engineering | E16: smallcap | F16: 1681.8 | G16: 1824.3 | H16: 8.52 | I16: 138274 | J16: 535057
A17: SKYGOLD | B17: Sky Gold Ltd | C17: consumer discretionary | D17: diamond cutting / jewellery | E17: midcap | F17: 11141.63 | G17: 779.6 | H17: 8.37 | I17: 8041846 | J17: 541967
A18: ORCHPHARMA | B18: Orchid Pharma Ltd | C18: healthcare | D18: pharmaceuticals - indian - bulk drugs & formln | E18: midcap | F18: 5081.29 | G18: 1079.15 | H18: 7.72 | I18: 222143 | J18: 524372
A19: KAPSTON | B19: Kapston Services Ltd | C19: miscellaneous | D19: miscellaneous | E19: smallcap | F19: 1600.43 | G19: 566.05 | H19: 7.63 | I19: 195599 | J19: 535064
A20: NEOGEN | B20: Neogen Chemicals Ltd | C20: chemicals | D20: chemicals | E20: midcap | F20: 5563.68 | G20: 2182.8 | H20: 7.43 | I20: 505295 | J20: 542665
A21: INDOBORAX | B21: Indo Borax & Chemicals Ltd | C21: chemicals | D21: chemicals | E21: smallcap | F21: 1284.88 | G21: 429.5 | H21: 7.27 | I21: 1906898 | J21: 524342
A22: SHAILY | B22: Shaily Engineering Plastics Ltd | C22: plastic products | D22: plastics products | E22: midcap | F22: 14545.08 | G22: 3367.4 | H22: 6.49 | I22: 408713 | J22: 501423
... A166: DPABHUSHAN | B166: D.P. Abhushan Ltd | C166: consumer discretionary | D166: diamond cutting / jewellery | E166: smallcap | F166: 3294.98 | G166: 1470.1 | H166: 1.85 | I166: 28158 | J166: 535026
A167: BELRISE | B167: Belrise Industries Ltd | C167: auto | D167: auto ancillaries | E167: largecap | F167: 24005.68 | G167: 252.77 | H167: 1.84 | I167: 6590771
A168: ETHOSLTD | B168: Ethos Ltd | C168: consumer discretionary | D168: trading | E168: midcap | F168: 7444.26 | G168: 2833.1 | H168: 1.83 | I168: 31526 | J168: 543532
A169: GRAPHITE | B169: Graphite India Limited | C169: industrials | D169: electrodes - graphites | E169: midcap | F169: 13870.69 | G169: 722.9 | H169: 1.82 | I169: 966513 | J169: 509488
A170: VARROC | B170: Varroc Engineering Ltd | C170: auto | D170: auto ancillaries | E170: midcap | F170: 12394.03 | G170: 825.95 | H170: 1.82 | I170: 1417670 | J170: 541578
A171: CONFIPET | B171: Confidence Petroleum India Ltd | C171: miscellaneous | D171: miscellaneous | E171: smallcap | F171: 2700.46 | G171: 82.74 | H171: 1.8 | I171: 5858829 | J171: 526829
A172: GEECEE | B172: Geecee Ventures Limited | C172: financials | D172: finance & investments | E172: smallcap | F172: 760.04 | G172: 370 | H172: 1.8 | I172: 7109 | J172: 532764
A173: NAHARINDUS | B173: Nahar Industrial Enterprises Limited | C173: textiles | D173: textiles - cotton/blended | E173: smallcap | F173: 551.82 | G173: 130 | H173: 1.79 | I173: 147014 | J173: 519136
A174: ACE | B174: Action Construction Equipment Limited | C174: industrials | D174: engineering | E174: midcap | F174: 13031.27 | G174: 1113.6 | H174: 1.76 | I174: 305830 | J174: 532762
A175: SHANTIGOLD | B175: Shanti Gold International Ltd | C175: consumer discretionary | D175: diamond cutting / jewellery | E175: smallcap | F175: 1615.02 | G175: 227.91 | H175: 1.74 | I175: 704322 | J175: 544459
A176: FILATEX | B176: Filatex India Limited | C176: textiles | D176: textiles - manmade | E176: smallcap | F176: 3700.34 | G176: 84.78 | H176: 1.74 | I176: 4575349 | J176: 526227
A177: GRASIM | B177: Grasim Industries Limited | C177: textiles | D177: textiles - manmade | E177: largecap | F177: 226156.93 | G177: 3380.5 | H177: 1.73 | I177: 5122421 | J177: 500300
A178: HNDFDS | B178: Hindustan Foods Ltd | C178: fmcg | D178: diversified - large | E178: midcap | F178: 6981.39 | G178: 586 | H178: 1.7 | I178: 74737 | J178: 519126
A179: TMB | B179: Tamilnad Mercantile Bank Ltd | C179: bank | D179: banks - private sector | E179: midcap | F179: 13870.8 | G179: 890.2 | H179: 1.63 | I179: 181662 | J179: 543596
... A181: GNFC | B181: Gujarat Narmada Valley Fertilizers And Chemicals Limited | C181: chemicals | D181: chemicals | E181: midcap | F181: 7868.67 | G181: 544.1 | H181: 1.61 | I181: 272440 | J181: 500670
A182: BORANA | B182: Borana Weaves Ltd | C182: textiles | D182: textiles - processing | E182: smallcap | F182: 904.87 | G182: 345 | H182: 1.59 | I182: 39480
A183: NGLFINE | B183: NGL Fine Chem Ltd | C183: healthcare | D183: pharmaceuticals - indian - bulk drugs | E183: smallcap | F183: 2102.75 | G183: 3457.8 | H183: 1.59 | I183: 7370 | J183: 524774
A184: VRLLOG | B184: Vrl Logistics Limited | C184: transportation | D184: miscellaneous | E184: smallcap | F184: 4921.85 | G184: 285.8 | H184: 1.58 | I184: 324876 | J184: 539118
...

Sheet Confluence Overlap
A1: Confluence Rank | B1: Total Score | C1: Relative Strength Rating | D1: Symbol | E1: Company Name | F1: Industry | G1: Common Count | H1: Scanner Signal | I1: Chartink Universe | J1: Scan Matches Count | K1: Backtest Recurrence (30D)
A2: =IF(B2=0,"",ROW()-1) | B2: =IFERROR(INDEX('Monit Non Financial'!$B$2:$B$400, MATCH(D2, 'Monit Non Financial'!$C$2:$C$400, 0)), IFERROR(INDEX('Monit Banks NBFC'!$B$2:$B$100, MATCH(D2, 'Monit Banks NBFC'!$C$2:$C$100, 0)), 0)) | C2: =IFERROR(INDEX('Monit Non Financial'!$L$2:$L$400, MATCH(D2, 'Monit Non Financial'!$C$2:$C$400, 0)), IFERROR(INDEX('Monit Banks NBFC'!$L$2:$L$100, MATCH(D2, 'Monit Banks NBFC'!$C$2:$C$100, 0)), "")) | D2: SBCL | E2: Shivalik Bimetal Controls Ltd | F2: Shunt Resistors | G2: 3 | H2: 52W Breakout | I2: Yes | J2: 21 | K2: 21
A3: =IF(B3=0,"",ROW()-1) | B3: =IFERROR(INDEX('Monit Non Financial'!$B$2:$B$400, MATCH(D3, 'Monit Non Financial'!$C$2:$C$400, 0)), IFERROR(INDEX('Monit Banks NBFC'!$B$2:$B$100, MATCH(D3, 'Monit Banks NBFC'!$C$2:$C$100, 0)), 0)) | C3: =IFERROR(INDEX('Monit Non Financial'!$L$2:$L$400, MATCH(D3, 'Monit Non Financial'!$C$2:$C$400, 0)), IFERROR(INDEX('Monit Banks NBFC'!$L$2:$L$100, MATCH(D3, 'Monit Banks NBFC'!$C$2:$C$100, 0)), "")) | D3: SYRMA | E3: Syrma SGS Technology Ltd | F3: Consumer Electronics - EMS | G3: 3 | H3: 52W Breakout | I3: Yes | J3: 23 | K3: 20
A4: =IF(B4=0,"",ROW()-1) | B4: =IFERROR(INDEX('Monit Non Financial'!$B$2:$B$400, MATCH(D4, 'Monit Non Financial'!$C$2:$C$400, 0)), IFERROR(INDEX('Monit Banks NBFC'!$B$2:$B$100, MATCH(D4, 'Monit Banks NBFC'!$C$2:$C$100, 0)), 0)) | C4: =IFERROR(INDEX('Monit Non Financial'!$L$2:$L$400, MATCH(D4, 'Monit Non Financial'!$C$2:$C$400, 0)), IFERROR(INDEX('Monit Banks NBFC'!$L$2:$L$100, MATCH(D4, 'Monit Banks NBFC'!$C$2:$C$100, 0)), "")) | D4: MACPOWER | E4: Macpower CNC Machines Ltd | F4: CNC - Machines | G4: 3 | H4: 52W Breakout | I4: Yes | J4: 28 | K4: 22
A5: =IF(B5=0,"",ROW()-1) | B5: =IFERROR(INDEX('Monit Non Financial'!$B$2:$B$400, MATCH(D5, 'Monit Non Financial'!$C$2:$C$400, 0)), IFERROR(INDEX('Monit Banks NBFC'!$B$2:$B$100, MATCH(D5, 'Monit Banks NBFC'!$C$2:$C$100, 0)), 0)) | C5: =IFERROR(INDEX('Monit Non Financial'!$L$2:$L$400, MATCH(D5, 'Monit Non Financial'!$C$2:$C$400, 0)), IFERROR(INDEX('Monit Banks NBFC'!$L$2:$L$100, MATCH(D5, 'Monit Banks NBFC'!$C$2:$C$100, 0)), "")) | D5: COMSYN | E5: Commercial Syn Bags Ltd | F5: Packaging - Polysacks | G5: 3 | H5: 52W Breakout | I5: Yes | J5: 22 | K5: 16
A6: =IF(B6=0,"",ROW()-1) | B6: =IFERROR(INDEX('Monit Non Financial'!$B$2:$B$400, MATCH(D6, 'Monit Non Financial'!$C$2:$C$400, 0)), IFERROR(INDEX('Monit Banks NBFC'!$B$2:$B$100, MATCH(D6, 'Monit Banks NBFC'!$C$2:$C$100, 0)), 0)) | C6: =IFERROR(INDEX('Monit Non Financial'!$L$2:$L$400, MATCH(D6, 'Monit Non Financial'!$C$2:$C$400, 0)), IFERROR(INDEX('Monit Banks NBFC'!$L$2:$L$100, MATCH(D6, 'Monit Banks NBFC'!$C$2:$C$100, 0)), "")) | D6: UEL | E6: Ujaas Energy Ltd | F6: Capital Goods - Transformers | G6: 3 | H6: 52W Breakout | I6: Yes | J6: 19 | K6: 6
A7: =IF(B7=0,"",ROW()-1) | B7: =IFERROR(INDEX('Monit Non Financial'!$B$2:$B$400, MATCH(D7, 'Monit Non Financial'!$C$2:$C$400, 0)), IFERROR(INDEX('Monit Banks NBFC'!$B$2:$B$100, MATCH(D7, 'Monit Banks NBFC'!$C$2:$C$100, 0)), 0)) | C7: =IFERROR(INDEX('Monit Non Financial'!$L$2:$L$400, MATCH(D7, 'Monit Non Financial'!$C$2:$C$400, 0)), IFERROR(INDEX('Monit Banks NBFC'!$L$2:$L$100, MATCH(D7, 'Monit Banks NBFC'!$C$2:$C$100, 0)), "")) | D7: PAYTM | E7: One 97 Communications Ltd | F7: E-Commerce - Platform - Utility | G7: 3 | H7: 52W Breakout | I7: Yes | J7: 23 | K7: 18
A8: =IF(B8=0,"",ROW()-1) | B8: =IFERROR(INDEX('Monit Non Financial'!$B$2:$B$400, MATCH(D8, 'Monit Non Financial'!$C$2:$C$400, 0)), IFERROR(INDEX('Monit Banks NBFC'!$B$2:$B$100, MATCH(D8, 'Monit Banks NBFC'!$C$2:$C$100, 0)), 0)) | C8: =IFERROR(INDEX('Monit Non Financial'!$L$2:$L$400, MATCH(D8, 'Monit Non Financial'!$C$2:$C$400, 0)), IFERROR(INDEX('Monit Banks NBFC'!$L$2:$L$100, MATCH(D8, 'Monit Banks NBFC'!$C$2:$C$100, 0)), "")) | D8: MMFL | E8: Mm Forgings Limited | F8: Castings, Forgings & Fastners | G8: 3 | H8: 52W Breakout | I8: Yes | J8: 21 | K8: 20
A9: =IF(B9=0,"",ROW()-1) | B9: =IFERROR(INDEX('Monit Non Financial'!$B$2:$B$400, MATCH(D9, 'Monit Non Financial'!$C$2:$C$400, 0)), IFERROR(INDEX('Monit Banks NBFC'!$B$2:$B$100, MATCH(D9, 'Monit Banks NBFC'!$C$2:$C$100, 0)), 0)) | C9: =IFERROR(INDEX('Monit Non Financial'!$L$2:$L$400, MATCH(D9, 'Monit Non Financial'!$C$2:$C$400, 0)), IFERROR(INDEX('Monit Banks NBFC'!$L$2:$L$100, MATCH(D9, 'Monit Banks NBFC'!$C$2:$C$100, 0)), "")) | D9: PIXTRANS | E9: Pix Transmission Ltd | F9: Rubber Processing/Rubber Products | G9: 2 | H9: No | I9: Yes | J9: 24 | K9: 18
A10: =IF(B10=0,"",ROW()-1) | B10: =IFERROR(INDEX('Monit Non Financial'!$B$2:$B$400, MATCH(D10, 'Monit Non Financial'!$C$2:$C$400, 0)), IFERROR(INDEX('Monit Banks NBFC'!$B$2:$B$100, MATCH(D10, 'Monit Banks NBFC'!$C$2:$C$100, 0)), 0)) | C10: =IFERROR(INDEX('Monit Non Financial'!$L$2:$L$400, MATCH(D10, 'Monit Non Financial'!$C$2:$C$400, 0)), IFERROR(INDEX('Monit Banks NBFC'!$L$2:$L$100, MATCH(D10, 'Monit Banks NBFC'!$C$2:$C$100, 0)), "")) | D10: NAVINFLUOR | E10: Navin Fluorine International Limited | F10: Chemicals - Flourine | G10: 2 | H10: No | I10: Yes | J10: 21 | K10: 21
A11: =IF(B11=0,"",ROW()-1) | B11: =IFERROR(INDEX('Monit Non Financial'!$B$2:$B$400, MATCH(D11, 'Monit Non Financial'!$C$2:$C$400, 0)), IFERROR(INDEX('Monit Banks NBFC'!$B$2:$B$100, MATCH(D11, 'Monit Banks NBFC'!$C$2:$C$100, 0)), 0)) | C11: =IFERROR(INDEX('Monit Non Financial'!$L$2:$L$400, MATCH(D11, 'Monit Non Financial'!$C$2:$C$400, 0)), IFERROR(INDEX('Monit Banks NBFC'!$L$2:$L$100, MATCH(D11, 'Monit Banks NBFC'!$C$2:$C$100, 0)), "")) | D11: APCOTEXIND | E11: Apcotex Industries Limited | F11: Rubber Processing/Rubber Products | G11: 2 | H11: No | I11: Yes | J11: 20 | K11: 25
A12: =IF(B12=0,"",ROW()-1) | B12: =IFERROR(INDEX('Monit Non Financial'!$B$2:$B$400, MATCH(D12, 'Monit Non Financial'!$C$2:$C$400, 0)), IFERROR(INDEX('Monit Banks NBFC'!$B$2:$B$100, MATCH(D12, 'Monit Banks NBFC'!$C$2:$C$100, 0)), 0)) | C12: =IFERROR(INDEX('Monit Non Financial'!$L$2:$L$400, MATCH(D12, 'Monit Non Financial'!$C$2:$C$400, 0)), IFERROR(INDEX('Monit Banks NBFC'!$L$2:$L$100, MATCH(D12, 'Monit Banks NBFC'!$C$2:$C$100, 0)), "")) | D12: IOLCP | E12: Iol Chemicals And Pharmaceuticals Limited | F12: Pharma - API & CRAMS | G12: 2 | H12: No | I12: Yes | J12: 19 | K12: 17
A13: =IF(B13=0,"",ROW()-1) | B13: =IFERROR(INDEX('Monit Non Financial'!$B$2:$B$400, MATCH(D13, 'Monit Non Financial'!$C$2:$C$400, 0)), IFERROR(INDEX('Monit Banks NBFC'!$B$2:$B$100, MATCH(D13, 'Monit Banks NBFC'!$C$2:$C$100, 0)), 0)) | C13: =IFERROR(INDEX('Monit Non Financial'!$L$2:$L$400, MATCH(D13, 'Monit Non Financial'!$C$2:$C$400, 0)), IFERROR(INDEX('Monit Banks NBFC'!$L$2:$L$100, MATCH(D13, 'Monit Banks NBFC'!$C$2:$C$100, 0)), "")) | D13: PRICOLLTD | E13: Pricol Ltd. | F13: Auto Ancillaries - 2 Wheelers | G13: 2 | H13: No | I13: Yes | J13: 20 | K13: 20
... A97: =IF(B97=0,"",ROW()-1) | B97: =IFERROR(INDEX('Monit Non Financial'!$B$2:$B$400, MATCH(D97, 'Monit Non Financial'!$C$2:$C$400, 0)), IFERROR(INDEX('Monit Banks NBFC'!$B$2:$B$100, MATCH(D97, 'Monit Banks NBFC'!$C$2:$C$100, 0)), 0)) | C97: =IFERROR(INDEX('Monit Non Financial'!$L$2:$L$400, MATCH(D97, 'Monit Non Financial'!$C$2:$C$400, 0)), IFERROR(INDEX('Monit Banks NBFC'!$L$2:$L$100, MATCH(D97, 'Monit Banks NBFC'!$C$2:$C$100, 0)), "")) | D97: JINDALSTEL | E97: Jindal Steel Ltd | F97: Steel Products | G97: 2 | H97: EMA Crossover | I97: Yes | J97: 3 | K97: 4

Sheet Monit Non Financial
A1: Rank (Non Financial) | B1: Total Score | C1: Symbol | D1: Company | E1: Sector | F1: Industry | G1: Market Cap Bucket | H1: Market Cap Cr | I1: Close | J1: Today Return % | K1: Volume | L1: Relative Strength Rating | M1: Relative Strength Status | N1: Relative Strength Score | O1: Calculated RSI (14) | P1: Calculated ADX (14) | Q1: Calculated V-stop Line | R1: Calculated Near-term Trigger | S1: Sector Benchmark | T1: Benchmark 1Y Return % | U1: Stock 1Y Return % | V1: Relative Strength 1Y (%) | W1: O'Neil Weighted Score | X1: Industry Growth | Y1: Industry Growth Score | Z1: Competitiveness | AA1: Competitiveness Score | AB1: Regulation | AC1: Regulation Score | AD1: Sector Headwinds/Tailwind | AE1: Sector Headwinds/Tailwind Score | AF1: Industry Type | AG1: Industry Type Score | AH1: Margins | AI1: Margins Score | AJ1: Margins Stability | AK1: Margins Stability Score | AL1: Growth | AM1: Growth Score | AN1: Business Type | AO1: Business Type Score | AP1: Near term triggers | AQ1: Near term triggers Score | AR1: Type of Revenue | AS1: Type of Revenue Score | AT1: Capital Allocation | AU1: Capital Allocation Score | AV1: Medium term Growth | AW1: Medium term Growth Score | AX1: ADX | AY1: ADX Score | AZ1: RSI | BA1: RSI Score | BB1: Stage Analysis | BC1: Stage Analysis Score | BD1: Price Volume Action | BE1: Price Volume Action Score | BF1: Secondary Trend | BG1: Secondary Trend Score | BH1: Primary Trend | BI1: Primary Trend Score | BJ1: Resistance | BK1: Resistance Score | BL1: V-stop | BM1: V-stop Score | BN1: PAT Growth | BO1: PAT Growth Score | BP1: Stock History | BQ1: Stock History Score | BR1: PE Ratio | BS1: PE Ratio Score | BT1: PEG Ratio | BU1: PEG Ratio Score | BV1: CFO to EBITDA | BW1: CFO to EBITDA Score | BX1: Debt to Equity | BY1: Debt to Equity Score | BZ1: Auditor Resignation | CA1: Auditor Resignation Score | CB1: Contingent Liability | CC1: Contingent Liability Score | CD1: Pledging | CE1: Pledging Score
A2: =IF(B2=0,"",RANK(B2,$B$2:$B$400,0)) | B2: =SUM(N2,Y2,AA2,AC2,AE2,AG2,AI2,AK2,AM2,AO2,AQ2,AS2,AU2,AW2,AY2,BA2,BC2,BE2,BG2,BI2,BK2,BM2,BO2,BQ2,BS2,BU2,BW2,BY2,CA2,CC2,CE2) | C2: KEI | D2: Kei Industries Limited | E2: industrials | F2: cables - power | G2: largecap | H2: 53536.33 | I2: 5659.8 | J2: 1.07 | K2: 736899 | L2: 36 | M2: Outperforming | N2: =IF(M2="Underperforming",-5,IF(L2>=95,15,IF(L2>=90,10,IF(L2>=80,5,0)))) | O2: 64.15 | P2: 25.26 | R2: Earnings / Momentum Support | S2: Nifty Energy | T2: 8.41 | U2: 25.03 | V2: 15.34 | W2: 4.92 | X2: Growing Industry | Y2: =IF(X2="Growing Industry",10,IF(X2="Cyclical in an Upturn",5,0)) | Z2: Too Many Players with High ROCE | AA2: =IF(Z2="Monopoly",10,IF(Z2="Oligopoly",5,IF(Z2="Duopoly that cooperate",10,IF(Z2="Duopoly that compete",5,IF(Z2="Too many players with High ROCE",5,0))))) | AB2: No | AC2: =IF(AB2="No",5,0) | AD2: Tailwind | AE2: =IF(AD2="Tailwind",10,0) | AF2: Structural (10 Years Consistency) | AG2: =IF(AF2="Structural (10 Years Consistency)",10,IF(AF2="Shallow Cyclical (2 to 3 years growth)",5,0)) | AH2: No | AI2: =IF(AH2="Yes due to Product Mix change or Operating Leverage",10,IF(AH2="Yes, these are peak margins",-5,IF(AH2="No",5,0))) | AJ2: Stable | AK2: =IF(AJ2="Stable",10,0) | AL2: Yes | AM2: =IF(AL2="Yes",10,0) | AN2: B2B | AO2: =IF(AN2="B2C",10,IF(AN2="B2B",5,0)) | AP2: Yes | AQ2: =IF(AP2="Yes",10,0) | AR2: Fully Annuity | AS2: =IF(AR2="Fully Annuity",10,IF(AR2="Higher Annuity, Lower One Time",5,IF(AR2="Higher One Time, Lower Annuity",3,0))) | AT2: Good | AU2: =IF(AT2="Good",10,0) | AV2: Yes for more than 2 years | AW2: =IF(AV2="Yes for more than 2 years",10,IF(AV2="Yes only for next 1 to 2 years",5,0)) | AX2: Above 40 | AY2: =IF(AX2="Above 40",20,IF(AX2="20 to 40",10,IF(AX2="0 to 20",-5,0))) | AZ2: Between 50 to 75 | BA2: =IF(AZ2="Between 50 to 75",10,IF(AZ2="Above 75",0,0)) | BB2: Stage 2 | BC2: =IF(BB2="Stage 2",20,IF(BB2="Stage 1",0,IF(BB2="Stage 3",5,IF(BB2="Stage 4",-5,0)))) | BD2: Positive Trend | BE2: =IF(BD2="Positive Trend",20,IF(BD2="Negative Trend",-10,0)) | BF2: Uptrend | BG2: =IF(BF2="Uptrend",10,IF(BF2="Sideways",5,0)) | BH2: Uptrend | BI2: =IF(BH2="Uptrend",10,IF(BH2="Sideways",5,0)) | BJ2: Close to 52 week high or retracement | BK2: =IF(BJ2="Overhead supply in last 2 years in last 2 years",-5,IF(BJ2="Close to 52 week high or retracement",5,IF(BJ2="Blue sky scenario",10,IF(BJ2="Long term Downtrend",-10,0)))) | BL2: Yes | BM2: =IF(BL2="Yes",10,0) | BN2: More than 20% | BO2: =IF(BN2="More than 20%",10,IF(BN2="Between 12 to 20%",5,IF(BN2="Less than 12%",0,0))) | BP2: Yes | BQ2: =IF(BP2="No",10,0) | BR2: No | BS2: =IF(BR2="NO",5,0) | BT2: Less than 1.5 | BU2: =IF(BT2="Above 2",0,IF(BT2="Between 1.5 to 2",5,IF(BT2="Less than 1.5",10,0))) | BV2: Above 70% | BW2: =IF(BV2="Above 70%",10,IF(BV2="Between 50% to 70%",5,IF(BV2="Less than 50%",0,IF(BV2="Negative",-10,IF(BV2="Less than 50% and Borrowings are increasing",-5,0))))) | BX2: Less than 0.7 | BY2: =IF(BX2="More than 1.2",-10,IF(BX2="Between 0.7 to 1.2",0,IF(BX2="Less than 0.7",10,0))) | BZ2: No | CA2: =IF(BZ2="Yes",-10,0) | CB2: Less than 15% | CC2: =IF(CB2="More than 15%",-10,IF(CB2="Less than 15%",10,0)) | CD2: Yes, More Than 10% | CE2: =IF(CD2="Yes, more than 10%",-10,IF(CD2="No",10,0))
A3: =IF(B3=0,"",RANK(B3,$B$2:$B$400,0)) | B3: =SUM(N3,Y3,AA3,AC3,AE3,AG3,AI3,AK3,AM3,AO3,AQ3,AS3,AU3,AW3,AY3,BA3,BC3,BE3,BG3,BI3,BK3,BM3,BO3,BQ3,BS3,BU3,BW3,BY3,CA3,CC3,CE3) | C3: SBCL | D3: Shivalik Bimetal Controls Ltd | E3: metals & mining | F3: mining / minerals / metals | G3: midcap | H3: 5304.77 | I3: 1105.05 | J3: 20 | K3: 10977326 | L3: 72 | M3: Underperforming | N3: =IF(M3="Underperforming",-5,IF(L3>=95,15,IF(L3>=90,10,IF(L3>=80,5,0)))) | O3: 76.2 | P3: 45.6 | R3: Volume Spike / Accumulation | S3: Nifty Metal | T3: 31.49 | U3: 23.64 | V3: -5.97 | W3: 14.67 | X3: Growing Industry | Y3: =IF(X3="Growing Industry",10,IF(X3="Cyclical in an Upturn",5,0)) | Z3: Monopoly | AA3: =IF(Z3="Monopoly",10,IF(Z3="Oligopoly",5,IF(Z3="Duopoly that cooperate",10,IF(Z3="Duopoly that compete",5,IF(Z3="Too many players with High ROCE",5,0))))) | AB3: No | AC3: =IF(AB3="No",5,0) | AD3: Tailwind | AE3: =IF(AD3="Tailwind",10,0) | AF3: Shallow Cyclical (2 to 3 Years Growth) | AG3: =IF(AF3="Structural (10 Years Consistency)",10,IF(AF3="Shallow Cyclical (2 to 3 years growth)",5,0)) | AH3: Yes due to Product Mix change or Operating Leverage | AI3: =IF(AH3="Yes due to Product Mix change or Operating Leverage",10,IF(AH3="Yes, these are peak margins",-5,IF(AH3="No",5,0))) | AJ3: Stable | AK3: =IF(AJ3="Stable",10,0) | AL3: Yes | AM3: =IF(AL3="Yes",10,0) | AN3: B2B | AO3: =IF(AN3="B2C",10,IF(AN3="B2B",5,0)) | AP3: Yes | AQ3: =IF(AP3="Yes",10,0) | AR3: Fully One Time | AS3: =IF(AR3="Fully Annuity",10,IF(AR3="Higher Annuity, Lower One Time",5,IF(AR3="Higher One Time, Lower Annuity",3,0))) | AT3: Good | AU3: =IF(AT3="Good",10,0) | AV3: Yes for more than 2 years | AW3: =IF(AV3="Yes for more than 2 years",10,IF(AV3="Yes only for next 1 to 2 years",5,0)) | AX3: 20 to 40 | AY3: =IF(AX3="Above 40",20,IF(AX3="20 to 40",10,IF(AX3="0 to 20",-5,0))) | AZ3: Between 50 to 75 | BA3: =IF(AZ3="Between 50 to 75",10,IF(AZ3="Above 75",0,0)) | BB3: Stage 2 | BC3: =IF(BB3="Stage 2",20,IF(BB3="Stage 1",0,IF(BB3="Stage 3",5,IF(BB3="Stage 4",-5,0)))) | BD3: Positive Trend | BE3: =IF(BD3="Positive Trend",20,IF(BD3="Negative Trend",-10,0)) | BF3: Uptrend | BG3: =IF(BF3="Uptrend",10,IF(BF3="Sideways",5,0)) | BH3: Uptrend | BI3: =IF(BH3="Uptrend",10,IF(BH3="Sideways",5,0)) | BJ3: Close to 52 week high or retracement | BK3: =IF(BJ3="Overhead supply in last 2 years in last 2 years",-5,IF(BJ3="Close to 52 week high or retracement",5,IF(BJ3="Blue sky scenario",10,IF(BJ3="Long term Downtrend",-10,0)))) | BL3: Yes | BM3: =IF(BL3="Yes",10,0) | BN3: More than 20% | BO3: =IF(BN3="More than 20%",10,IF(BN3="Between 12 to 20%",5,IF(BN3="Less than 12%",0,0))) | BP3: Yes | BQ3: =IF(BP3="No",10,0) | BR3: No | BS3: =IF(BR3="NO",5,0) | BT3: Between 1.5 to 2 | BU3: =IF(BT3="Above 2",0,IF(BT3="Between 1.5 to 2",5,IF(BT3="Less than 1.5",10,0))) | BV3: Less than 50% | BW3: =IF(BV3="Above 70%",10,IF(BV3="Between 50% to 70%",5,IF(BV3="Less than 50%",0,IF(BV3="Negative",-10,IF(BV3="Less than 50% and Borrowings are increasing",-5,0))))) | BX3: Less than 0.7 | BY3: =IF(BX3="More than 1.2",-10,IF(BX3="Between 0.7 to 1.2",0,IF(BX3="Less than 0.7",10,0))) | BZ3: No | CA3: =IF(BZ3="Yes",-10,0) | CB3: Less than 15% | CC3: =IF(CB3="More than 15%",-10,IF(CB3="Less than 15%",10,0)) | CD3: No | CE3: =IF(CD3="Yes, more than 10%",-10,IF(CD3="No",10,0))
A4: =IF(B4=0,"",RANK(B4,$B$2:$B$400,0)) | B4: =SUM(N4,Y4,AA4,AC4,AE4,AG4,AI4,AK4,AM4,AO4,AQ4,AS4,AU4,AW4,AY4,BA4,BC4,BE4,BG4,BI4,BK4,BM4,BO4,BQ4,BS4,BU4,BW4,BY4,CA4,CC4,CE4) | C4: PIXTRANS | D4: Pix Transmission Ltd | E4: fmcg | F4: miscellaneous | G4: smallcap | H4: 2339.72 | I4: 1986.5 | J4: 15.68 | K4: 1309397 | L4: 48 | M4: Outperforming | N4: =IF(M4="Underperforming",-5,IF(L4>=95,15,IF(L4>=90,10,IF(L4>=80,5,0)))) | O4: 59.95 | P4: 43.39 | R4: Volume Spike / Accumulation | S4: Nifty FMCG | T4: -13.73 | U4: 17.79 | V4: 36.54 | W4: 7.69 | X4: Growing Industry | Y4: =IF(X4="Growing Industry",10,IF(X4="Cyclical in an Upturn",5,0)) | Z4: Too Many Players with High ROCE | AA4: =IF(Z4="Monopoly",10,IF(Z4="Oligopoly",5,IF(Z4="Duopoly that cooperate",10,IF(Z4="Duopoly that compete",5,IF(Z4="Too many players with High ROCE",5,0))))) | AB4: No | AC4: =IF(AB4="No",5,0) | AD4: Headwind | AE4: =IF(AD4="Tailwind",10,0) | AF4: Structural (10 Years Consistency) | AG4: =IF(AF4="Structural (10 Years Consistency)",10,IF(AF4="Shallow Cyclical (2 to 3 years growth)",5,0)) | AH4: No | AI4: =IF(AH4="Yes due to Product Mix change or Operating Leverage",10,IF(AH4="Yes, these are peak margins",-5,IF(AH4="No",5,0))) | AJ4: Stable | AK4: =IF(AJ4="Stable",10,0) | AL4: Yes | AM4: =IF(AL4="Yes",10,0) | AN4: B2C | AO4: =IF(AN4="B2C",10,IF(AN4="B2B",5,0)) | AP4: Yes | AQ4: =IF(AP4="Yes",10,0) | AR4: Higher Annuity, Lower One Time | AS4: =IF(AR4="Fully Annuity",10,IF(AR4="Higher Annuity, Lower One Time",5,IF(AR4="Higher One Time, Lower Annuity",3,0))) | AT4: Good | AU4: =IF(AT4="Good",10,0) | AV4: Yes for more than 2 years | AW4: =IF(AV4="Yes for more than 2 years",10,IF(AV4="Yes only for next 1 to 2 years",5,0)) | AX4: Above 40 | AY4: =IF(AX4="Above 40",20,IF(AX4="20 to 40",10,IF(AX4="0 to 20",-5,0))) | AZ4: Between 50 to 75 | BA4: =IF(AZ4="Between 50 to 75",10,IF(AZ4="Above 75",0,0)) | BB4: Stage 3 | BC4: =IF(BB4="Stage 2",20,IF(BB4="Stage 1",0,IF(BB4="Stage 3",5,IF(BB4="Stage 4",-5,0)))) | BD4: Negative Trend | BE4: =IF(BD4="Positive Trend",20,IF(BD4="Negative Trend",-10,0)) | BF4: Uptrend | BG4: =IF(BF4="Uptrend",10,IF(BF4="Sideways",5,0)) | BH4: Uptrend | BI4: =IF(BH4="Uptrend",10,IF(BH4="Sideways",5,0)) | BJ4: Close to 52 week high or retracement | BK4: =IF(BJ4="Overhead supply in last 2 years in last 2 years",-5,IF(BJ4="Close to 52 week high or retracement",5,IF(BJ4="Blue sky scenario",10,IF(BJ4="Long term Downtrend",-10,0)))) | BL4: Yes | BM4: =IF(BL4="Yes",10,0) | BN4: More than 20% | BO4: =IF(BN4="More than 20%",10,IF(BN4="Between 12 to 20%",5,IF(BN4="Less than 12%",0,0))) | BP4: No | BQ4: =IF(BP4="No",10,0) | BR4: No | BS4: =IF(BR4="NO",5,0) | BT4: Less than 1.5 | BU4: =IF(BT4="Above 2",0,IF(BT4="Between 1.5 to 2",5,IF(BT4="Less than 1.5",10,0))) | BV4: Above 70% | BW4: =IF(BV4="Above 70%",10,IF(BV4="Between 50% to 70%",5,IF(BV4="Less than 50%",0,IF(BV4="Negative",-10,IF(BV4="Less than 50% and Borrowings are increasing",-5,0))))) | BX4: Less than 0.7 | BY4: =IF(BX4="More than 1.2",-10,IF(BX4="Between 0.7 to 1.2",0,IF(BX4="Less than 0.7",10,0))) | BZ4: No | CA4: =IF(BZ4="Yes",-10,0) | CB4: Less than 15% | CC4: =IF(CB4="More than 15%",-10,IF(CB4="Less than 15%",10,0)) | CD4: No | CE4: =IF(CD4="Yes, more than 10%",-10,IF(CD4="No",10,0))
A5: =IF(B5=0,"",RANK(B5,$B$2:$B$400,0)) | B5: =SUM(N5,Y5,AA5,AC5,AE5,AG5,AI5,AK5,AM5,AO5,AQ5,AS5,AU5,AW5,AY5,BA5,BC5,BE5,BG5,BI5,BK5,BM5,BO5,BQ5,BS5,BU5,BW5,BY5,CA5,CC5,CE5) | C5: APLAPOLLO | D5: Apl Apollo Tubes Limited | E5: industrials | F5: steel - large | G5: largecap | H5: 54698.71 | I5: 2020 | J5: 2.54 | K5: 1128980 | L5: 10 | M5: Underperforming | N5: =IF(M5="Underperforming",-5,IF(L5>=95,15,IF(L5>=90,10,IF(L5>=80,5,0)))) | O5: 56.06 | P5: 10.78 | R5: Earnings / Momentum Support | S5: Nifty Metal | T5: 31.49 | U5: 8.12 | V5: -17.78 | W5: -0.94 | X5: Cyclical in an Upturn | Y5: =IF(X5="Growing Industry",10,IF(X5="Cyclical in an Upturn",5,0)) | Z5: Oligopoly | AA5: =IF(Z5="Monopoly",10,IF(Z5="Oligopoly",5,IF(Z5="Duopoly that cooperate",10,IF(Z5="Duopoly that compete",5,IF(Z5="Too many players with High ROCE",5,0))))) | AB5: No | AC5: =IF(AB5="No",5,0) | AD5: Tailwind | AE5: =IF(AD5="Tailwind",10,0) | AF5: Cyclical | AG5: =IF(AF5="Structural (10 Years Consistency)",10,IF(AF5="Shallow Cyclical (2 to 3 years growth)",5,0)) | AH5: No | AI5: =IF(AH5="Yes due to Product Mix change or Operating Leverage",10,IF(AH5="Yes, these are peak margins",-5,IF(AH5="No",5,0))) | AJ5: Stable | AK5: =IF(AJ5="Stable",10,0) | AL5: Yes | AM5: =IF(AL5="Yes",10,0) | AN5: B2C | AO5: =IF(AN5="B2C",10,IF(AN5="B2B",5,0)) | AP5: Yes | AQ5: =IF(AP5="Yes",10,0) | AR5: Fully One Time | AS5: =IF(AR5="Fully Annuity",10,IF(AR5="Higher Annuity, Lower One Time",5,IF(AR5="Higher One Time, Lower Annuity",3,0))) | AT5: Good | AU5: =IF(AT5="Good",10,0) | AV5: Yes for more than 2 years | AW5: =IF(AV5="Yes for more than 2 years",10,IF(AV5="Yes only for next 1 to 2 years",5,0)) | AX5: Above 40 | AY5: =IF(AX5="Above 40",20,IF(AX5="20 to 40",10,IF(AX5="0 to 20",-5,0))) | AZ5: Above 75 | BA5: =IF(AZ5="Between 50 to 75",10,IF(AZ5="Above 75",0,0)) | BB5: Stage 2 | BC5: =IF(BB5="Stage 2",20,IF(BB5="Stage 1",0,IF(BB5="Stage 3",5,IF(BB5="Stage 4",-5,0)))) | BD5: Positive Trend | BE5: =IF(BD5="Positive Trend",20,IF(BD5="Negative Trend",-10,0)) | BF5: Uptrend | BG5: =IF(BF5="Uptrend",10,IF(BF5="Sideways",5,0)) | BH5: Uptrend | BI5: =IF(BH5="Uptrend",10,IF(BH5="Sideways",5,0)) | BJ5: Close to 52 week high or retracement | BK5: =IF(BJ5="Overhead supply in last 2 years in last 2 years",-5,IF(BJ5="Close to 52 week high or retracement",5,IF(BJ5="Blue sky scenario",10,IF(BJ5="Long term Downtrend",-10,0)))) | BL5: Yes | BM5: =IF(BL5="Yes",10,0) | BN5: More than 20% | BO5: =IF(BN5="More than 20%",10,IF(BN5="Between 12 to 20%",5,IF(BN5="Less than 12%",0,0))) | BP5: Yes | BQ5: =IF(BP5="No",10,0) | BR5: Yes | BS5: =IF(BR5="NO",5,0) | BT5: Between 1.5 to 2 | BU5: =IF(BT5="Above 2",0,IF(BT5="Between 1.5 to 2",5,IF(BT5="Less than 1.5",10,0))) | BV5: Above 70% | BW5: =IF(BV5="Above 70%",10,IF(BV5="Between 50% to 70%",5,IF(BV5="Less than 50%",0,IF(BV5="Negative",-10,IF(BV5="Less than 50% and Borrowings are increasing",-5,0))))) | BX5: Less than 0.7 | BY5: =IF(BX5="More than 1.2",-10,IF(BX5="Between 0.7 to 1.2",0,IF(BX5="Less than 0.7",10,0))) | BZ5: No | CA5: =IF(BZ5="Yes",-10,0) | CB5: Less than 15% | CC5: =IF(CB5="More than 15%",-10,IF(CB5="Less than 15%",10,0)) | CD5: No | CE5: =IF(CD5="Yes, more than 10%",-10,IF(CD5="No",10,0))
A6: =IF(B6=0,"",RANK(B6,$B$2:$B$400,0)) | B6: =SUM(N6,Y6,AA6,AC6,AE6,AG6,AI6,AK6,AM6,AO6,AQ6,AS6,AU6,AW6,AY6,BA6,BC6,BE6,BG6,BI6,BK6,BM6,BO6,BQ6,BS6,BU6,BW6,BY6,CA6,CC6,CE6) | C6: APOLLOTYRE | D6: Apollo Tyres Limited | E6: auto | F6: tyres | G6: largecap | H6: 28261.99 | I6: 445.95 | J6: 0.21 | K6: 709497 | L6: 10 | M6: Underperforming | N6: =IF(M6="Underperforming",-5,IF(L6>=95,15,IF(L6>=90,10,IF(L6>=80,5,0)))) | O6: 54.37 | P6: 16.91 | R6: Earnings / Momentum Support | S6: Nifty Auto | T6: 13.41 | U6: -4.18 | V6: -15.51 | W6: -1.18 | X6: Cyclical in an Upturn | Y6: =IF(X6="Growing Industry",10,IF(X6="Cyclical in an Upturn",5,0)) | Z6: Oligopoly | AA6: =IF(Z6="Monopoly",10,IF(Z6="Oligopoly",5,IF(Z6="Duopoly that cooperate",10,IF(Z6="Duopoly that compete",5,IF(Z6="Too many players with High ROCE",5,0))))) | AB6: No | AC6: =IF(AB6="No",5,0) | AD6: Tailwind | AE6: =IF(AD6="Tailwind",10,0) | AF6: Cyclical | AG6: =IF(AF6="Structural (10 Years Consistency)",10,IF(AF6="Shallow Cyclical (2 to 3 years growth)",5,0)) | AH6: No | AI6: =IF(AH6="Yes due to Product Mix change or Operating Leverage",10,IF(AH6="Yes, these are peak margins",-5,IF(AH6="No",5,0))) | AJ6: Stable | AK6: =IF(AJ6="Stable",10,0) | AL6: Yes | AM6: =IF(AL6="Yes",10,0) | AN6: B2C | AO6: =IF(AN6="B2C",10,IF(AN6="B2B",5,0)) | AP6: Yes | AQ6: =IF(AP6="Yes",10,0) | AR6: Fully One Time | AS6: =IF(AR6="Fully Annuity",10,IF(AR6="Higher Annuity, Lower One Time",5,IF(AR6="Higher One Time, Lower Annuity",3,0))) | AT6: Good | AU6: =IF(AT6="Good",10,0) | AV6: Yes for more than 2 years | AW6: =IF(AV6="Yes for more than 2 years",10,IF(AV6="Yes only for next 1 to 2 years",5,0)) | AX6: Above 40 | AY6: =IF(AX6="Above 40",20,IF(AX6="20 to 40",10,IF(AX6="0 to 20",-5,0))) | AZ6: Above 75 | BA6: =IF(AZ6="Between 50 to 75",10,IF(AZ6="Above 75",0,0)) | BB6: Stage 2 | BC6: =IF(BB6="Stage 2",20,IF(BB6="Stage 1",0,IF(BB6="Stage 3",5,IF(BB6="Stage 4",-5,0)))) | BD6: Positive Trend | BE6: =IF(BD6="Positive Trend",20,IF(BD6="Negative Trend",-10,0)) | BF6: Uptrend | BG6: =IF(BF6="Uptrend",10,IF(BF6="Sideways",5,0)) | BH6: Uptrend | BI6: =IF(BH6="Uptrend",10,IF(BH6="Sideways",5,0)) | BJ6: Close to 52 week high or retracement | BK6: =IF(BJ6="Overhead supply in last 2 years in last 2 years",-5,IF(BJ6="Close to 52 week high or retracement",5,IF(BJ6="Blue sky scenario",10,IF(BJ6="Long term Downtrend",-10,0)))) | BL6: Yes | BM6: =IF(BL6="Yes",10,0) | BN6: More than 20% | BO6: =IF(BN6="More than 20%",10,IF(BN6="Between 12 to 20%",5,IF(BN6="Less than 12%",0,0))) | BP6: Yes | BQ6: =IF(BP6="No",10,0) | BR6: Yes | BS6: =IF(BR6="NO",5,0) | BT6: Between 1.5 to 2 | BU6: =IF(BT6="Above 2",0,IF(BT6="Between 1.5 to 2",5,IF(BT6="Less than 1.5",10,0))) | BV6: Above 70% | BW6: =IF(BV6="Above 70%",10,IF(BV6="Between 50% to 70%",5,IF(BV6="Less than 50%",0,IF(BV6="Negative",-10,IF(BV6="Less than 50% and Borrowings are increasing",-5,0))))) | BX6: Less than 0.7 | BY6: =IF(BX6="More than 1.2",-10,IF(BX6="Between 0.7 to 1.2",0,IF(BX6="Less than 0.7",10,0))) | BZ6: No | CA6: =IF(BZ6="Yes",-10,0) | CB6: Less than 15% | CC6: =IF(CB6="More than 15%",-10,IF(CB6="Less than 15%",10,0)) | CD6: No | CE6: =IF(CD6="Yes, more than 10%",-10,IF(CD6="No",10,0))
A7: =IF(B7=0,"",RANK(B7,$B$2:$B$400,0)) | B7: =SUM(N7,Y7,AA7,AC7,AE7,AG7,AI7,AK7,AM7,AO7,AQ7,AS7,AU7,AW7,AY7,BA7,BC7,BE7,BG7,BI7,BK7,BM7,BO7,BQ7,BS7,BU7,BW7,BY7,CA7,CC7,CE7) | C7: NAVINFLUOR | D7: Navin Fluorine International Limited | E7: chemicals | F7: chemicals | G7: largecap | H7: 42422.92 | I7: 8196.5 | J7: -0.9 | K7: 190608 | L7: 73 | M7: Outperforming | N7: =IF(M7="Underperforming",-5,IF(L7>=95,15,IF(L7>=90,10,IF(L7>=80,5,0)))) | O7: 76.5 | P7: 55.5 | R7: Earnings / Momentum Support | S7: Nifty 50 | T7: 0.85 | U7: 72.22 | V7: 70.77 | W7: 15.32 | X7: Growing Industry | Y7: =IF(X7="Growing Industry",10,IF(X7="Cyclical in an Upturn",5,0)) | Z7: Oligopoly | AA7: =IF(Z7="Monopoly",10,IF(Z7="Oligopoly",5,IF(Z7="Duopoly that cooperate",10,IF(Z7="Duopoly that compete",5,IF(Z7="Too many players with High ROCE",5,0))))) | AB7: No | AC7: =IF(AB7="No",5,0) | AD7: Tailwind | AE7: =IF(AD7="Tailwind",10,0) | AF7: Shallow Cyclical (2 to 3 Years Growth) | AG7: =IF(AF7="Structural (10 Years Consistency)",10,IF(AF7="Shallow Cyclical (2 to 3 years growth)",5,0)) | AH7: No | AI7: =IF(AH7="Yes due to Product Mix change or Operating Leverage",10,IF(AH7="Yes, these are peak margins",-5,IF(AH7="No",5,0))) | AJ7: Stable | AK7: =IF(AJ7="Stable",10,0) | AL7: Yes | AM7: =IF(AL7="Yes",10,0) | AN7: B2B | AO7: =IF(AN7="B2C",10,IF(AN7="B2B",5,0)) | AP7: Yes | AQ7: =IF(AP7="Yes",10,0) | AR7: Higher One Time, Lower Annuity | AS7: =IF(AR7="Fully Annuity",10,IF(AR7="Higher Annuity, Lower One Time",5,IF(AR7="Higher One Time, Lower Annuity",3,0))) | AT7: Good | AU7: =IF(AT7="Good",10,0) | AV7: Yes for more than 2 years | AW7: =IF(AV7="Yes for more than 2 years",10,IF(AV7="Yes only for next 1 to 2 years",5,0)) | AX7: 20 to 40 | AY7: =IF(AX7="Above 40",20,IF(AX7="20 to 40",10,IF(AX7="0 to 20",-5,0))) | AZ7: Between 50 to 75 | BA7: =IF(AZ7="Between 50 to 75",10,IF(AZ7="Above 75",0,0)) | BB7: Stage 3 | BC7: =IF(BB7="Stage 2",20,IF(BB7="Stage 1",0,IF(BB7="Stage 3",5,IF(BB7="Stage 4",-5,0)))) | BD7: Positive Trend | BE7: =IF(BD7="Positive Trend",20,IF(BD7="Negative Trend",-10,0)) | BF7: Uptrend | BG7: =IF(BF7="Uptrend",10,IF(BF7="Sideways",5,0)) | BH7: Uptrend | BI7: =IF(BH7="Uptrend",10,IF(BH7="Sideways",5,0)) | BJ7: Close to 52 week high or retracement | BK7: =IF(BJ7="Overhead supply in last 2 years in last 2 years",-5,IF(BJ7="Close to 52 week high or retracement",5,IF(BJ7="Blue sky scenario",10,IF(BJ7="Long term Downtrend",-10,0)))) | BL7: Yes | BM7: =IF(BL7="Yes",10,0) | BN7: More than 20% | BO7: =IF(BN7="More than 20%",10,IF(BN7="Between 12 to 20%",5,IF(BN7="Less than 12%",0,0))) | BP7: No | BQ7: =IF(BP7="No",10,0) | BR7: Yes | BS7: =IF(BR7="NO",5,0) | BT7: Above 2 | BU7: =IF(BT7="Above 2",0,IF(BT7="Between 1.5 to 2",5,IF(BT7="Less than 1.5",10,0))) | BV7: Between 50% to 70% | BW7: =IF(BV7="Above 70%",10,IF(BV7="Between 50% to 70%",5,IF(BV7="Less than 50%",0,IF(BV7="Negative",-10,IF(BV7="Less than 50% and Borrowings are increasing",-5,0))))) | BX7: Less than 0.7 | BY7: =IF(BX7="More than 1.2",-10,IF(BX7="Between 0.7 to 1.2",0,IF(BX7="Less than 0.7",10,0))) | BZ7: No | CA7: =IF(BZ7="Yes",-10,0) | CB7: Less than 15% | CC7: =IF(CB7="More than 15%",-10,IF(CB7="Less than 15%",10,0)) | CD7: No | CE7: =IF(CD7="Yes, more than 10%",-10,IF(CD7="No",10,0))
A8: =IF(B8=0,"",RANK(B8,$B$2:$B$400,0)) | B8: =SUM(N8,Y8,AA8,AC8,AE8,AG8,AI8,AK8,AM8,AO8,AQ8,AS8,AU8,AW8,AY8,BA8,BC8,BE8,BG8,BI8,BK8,BM8,BO8,BQ8,BS8,BU8,BW8,BY8,CA8,CC8,CE8) | C8: APCOTEXIND | D8: Apcotex Industries Limited | E8: chemicals | F8: miscellaneous | G8: smallcap | H8: 3187.43 | I8: 624.05 | J8: 1.5 | K8: 271630 | L8: 71 | M8: Outperforming | N8: =IF(M8="Underperforming",-5,IF(L8>=95,15,IF(L8>=90,10,IF(L8>=80,5,0)))) | O8: 73.88 | P8: 64.59 | R8: Earnings / Momentum Support | S8: Nifty 50 | T8: 0.85 | U8: 53.86 | V8: 52.57 | W8: 14.24 | X8: Growing Industry | Y8: =IF(X8="Growing Industry",10,IF(X8="Cyclical in an Upturn",5,0)) | Z8: Oligopoly | AA8: =IF(Z8="Monopoly",10,IF(Z8="Oligopoly",5,IF(Z8="Duopoly that cooperate",10,IF(Z8="Duopoly that compete",5,IF(Z8="Too many players with High ROCE",5,0))))) | AB8: No | AC8: =IF(AB8="No",5,0) | AD8: Tailwind | AE8: =IF(AD8="Tailwind",10,0) | AF8: Cyclical | AG8: =IF(AF8="Structural (10 Years Consistency)",10,IF(AF8="Shallow Cyclical (2 to 3 years growth)",5,0)) | AH8: No | AI8: =IF(AH8="Yes due to Product Mix change or Operating Leverage",10,IF(AH8="Yes, these are peak margins",-5,IF(AH8="No",5,0))) | AJ8: Stable | AK8: =IF(AJ8="Stable",10,0) | AL8: Yes | AM8: =IF(AL8="Yes",10,0) | AN8: B2B | AO8: =IF(AN8="B2C",10,IF(AN8="B2B",5,0)) | AP8: Yes | AQ8: =IF(AP8="Yes",10,0) | AR8: Fully One Time | AS8: =IF(AR8="Fully Annuity",10,IF(AR8="Higher Annuity, Lower One Time",5,IF(AR8="Higher One Time, Lower Annuity",3,0))) | AT8: Good | AU8: =IF(AT8="Good",10,0) | AV8: Yes for more than 2 years | AW8: =IF(AV8="Yes for more than 2 years",10,IF(AV8="Yes only for next 1 to 2 years",5,0)) | AX8: Above 40 | AY8: =IF(AX8="Above 40",20,IF(AX8="20 to 40",10,IF(AX8="0 to 20",-5,0))) | AZ8: Between 50 to 75 | BA8: =IF(AZ8="Between 50 to 75",10,IF(AZ8="Above 75",0,0)) | BB8: Stage 1 | BC8: =IF(BB8="Stage 2",20,IF(BB8="Stage 1",0,IF(BB8="Stage 3",5,IF(BB8="Stage 4",-5,0)))) | BD8: Positive Trend | BE8: =IF(BD8="Positive Trend",20,IF(BD8="Negative Trend",-10,0)) | BF8: Sideways | BG8: =IF(BF8="Uptrend",10,IF(BF8="Sideways",5,0)) | BH8: Uptrend | BI8: =IF(BH8="Uptrend",10,IF(BH8="Sideways",5,0)) | BJ8: Overhead supply in last 2 years in last 2 years | BK8: =IF(BJ8="Overhead supply in last 2 years in last 2 years",-5,IF(BJ8="Close to 52 week high or retracement",5,IF(BJ8="Blue sky scenario",10,IF(BJ8="Long term Downtrend",-10,0)))) | BL8: Yes | BM8: =IF(BL8="Yes",10,0) | BN8: More than 20% | BO8: =IF(BN8="More than 20%",10,IF(BN8="Between 12 to 20%",5,IF(BN8="Less than 12%",0,0))) | BP8: No | BQ8: =IF(BP8="No",10,0) | BR8: No | BS8: =IF(BR8="NO",5,0) | BT8: Less than 1.5 | BU8: =IF(BT8="Above 2",0,IF(BT8="Between 1.5 to 2",5,IF(BT8="Less than 1.5",10,0))) | BV8: Between 50% to 70% | BW8: =IF(BV8="Above 70%",10,IF(BV8="Between 50% to 70%",5,IF(BV8="Less than 50%",0,IF(BV8="Negative",-10,IF(BV8="Less than 50% and Borrowings are increasing",-5,0))))) | BX8: Less than 0.7 | BY8: =IF(BX8="More than 1.2",-10,IF(BX8="Between 0.7 to 1.2",0,IF(BX8="Less than 0.7",10,0))) | BZ8: No | CA8: =IF(BZ8="Yes",-10,0) | CB8: Less than 15% | CC8: =IF(CB8="More than 15%",-10,IF(CB8="Less than 15%",10,0)) | CD8: No | CE8: =IF(CD8="Yes, more than 10%",-10,IF(CD8="No",10,0))
A9: =IF(B9=0,"",RANK(B9,$B$2:$B$400,0)) | B9: =SUM(N9,Y9,AA9,AC9,AE9,AG9,AI9,AK9,AM9,AO9,AQ9,AS9,AU9,AW9,AY9,BA9,BC9,BE9,BG9,BI9,BK9,BM9,BO9,BQ9,BS9,BU9,BW9,BY9,CA9,CC9,CE9) | C9: RPEL | D9: Raghav Productivity Enhancers Ltd | E9: building materials | F9: refractories / intermediates | G9: midcap | H9: 5770.09 | I9: 1313.8 | J9: 4.56 | K9: 101708 | L9: 96 | M9: Outperforming | N9: =IF(M9="Underperforming",-5,IF(L9>=95,15,IF(L9>=90,10,IF(L9>=80,5,0)))) | O9: 69.73 | P9: 51.74 | R9: Earnings / Momentum Support | S9: Nifty Infra | T9: 1.74 | U9: 89.85 | V9: 86.6 | W9: 35.04 | X9: Growing Industry | Y9: =IF(X9="Growing Industry",10,IF(X9="Cyclical in an Upturn",5,0)) | Z9: Too Many Players with High ROCE | AA9: =IF(Z9="Monopoly",10,IF(Z9="Oligopoly",5,IF(Z9="Duopoly that cooperate",10,IF(Z9="Duopoly that compete",5,IF(Z9="Too many players with High ROCE",5,0))))) | AB9: No | AC9: =IF(AB9="No",5,0) | AD9: Headwind | AE9: =IF(AD9="Tailwind",10,0) | AF9: Structural (10 Years Consistency) | AG9: =IF(AF9="Structural (10 Years Consistency)",10,IF(AF9="Shallow Cyclical (2 to 3 years growth)",5,0)) | AH9: No | AI9: =IF(AH9="Yes due to Product Mix change or Operating Leverage",10,IF(AH9="Yes, these are peak margins",-5,IF(AH9="No",5,0))) | AJ9: Stable | AK9: =IF(AJ9="Stable",10,0) | AL9: Yes | AM9: =IF(AL9="Yes",10,0) | AN9: B2B | AO9: =IF(AN9="B2C",10,IF(AN9="B2B",5,0)) | AP9: No | AQ9: =IF(AP9="Yes",10,0) | AR9: Higher One Time, Lower Annuity | AS9: =IF(AR9="Fully Annuity",10,IF(AR9="Higher Annuity, Lower One Time",5,IF(AR9="Higher One Time, Lower Annuity",3,0))) | AT9: Good | AU9: =IF(AT9="Good",10,0) | AV9: Yes for more than 2 years | AW9: =IF(AV9="Yes for more than 2 years",10,IF(AV9="Yes only for next 1 to 2 years",5,0)) | AX9: Above 40 | AY9: =IF(AX9="Above 40",20,IF(AX9="20 to 40",10,IF(AX9="0 to 20",-5,0))) | AZ9: Between 50 to 75 | BA9: =IF(AZ9="Between 50 to 75",10,IF(AZ9="Above 75",0,0)) | BB9: Stage 3 | BC9: =IF(BB9="Stage 2",20,IF(BB9="Stage 1",0,IF(BB9="Stage 3",5,IF(BB9="Stage 4",-5,0)))) | BD9: Negative Trend | BE9: =IF(BD9="Positive Trend",20,IF(BD9="Negative Trend",-10,0)) | BF9: Uptrend | BG9: =IF(BF9="Uptrend",10,IF(BF9="Sideways",5,0)) | BH9: Uptrend | BI9: =IF(BH9="Uptrend",10,IF(BH9="Sideways",5,0)) | BJ9: Close to 52 week high or retracement | BK9: =IF(BJ9="Overhead supply in last 2 years in last 2 years",-5,IF(BJ9="Close to 52 week high or retracement",5,IF(BJ9="Blue sky scenario",10,IF(BJ9="Long term Downtrend",-10,0)))) | BL9: Yes | BM9: =IF(BL9="Yes",10,0) | BN9: More than 20% | BO9: =IF(BN9="More than 20%",10,IF(BN9="Between 12 to 20%",5,IF(BN9="Less than 12%",0,0))) | BP9: No | BQ9: =IF(BP9="No",10,0) | BR9: Yes | BS9: =IF(BR9="NO",5,0) | BT9: Less than 1.5 | BU9: =IF(BT9="Above 2",0,IF(BT9="Between 1.5 to 2",5,IF(BT9="Less than 1.5",10,0))) | BV9: Above 70% | BW9: =IF(BV9="Above 70%",10,IF(BV9="Between 50% to 70%",5,IF(BV9="Less than 50%",0,IF(BV9="Negative",-10,IF(BV9="Less than 50% and Borrowings are increasing",-5,0))))) | BX9: Less than 0.7 | BY9: =IF(BX9="More than 1.2",-10,IF(BX9="Between 0.7 to 1.2",0,IF(BX9="Less than 0.7",10,0))) | BZ9: No | CA9: =IF(BZ9="Yes",-10,0) | CB9: Less than 15% | CC9: =IF(CB9="More than 15%",-10,IF(CB9="Less than 15%",10,0)) | CD9: No | CE9: =IF(CD9="Yes, more than 10%",-10,IF(CD9="No",10,0))
A10: =IF(B10=0,"",RANK(B10,$B$2:$B$400,0)) | B10: =SUM(N10,Y10,AA10,AC10,AE10,AG10,AI10,AK10,AM10,AO10,AQ10,AS10,AU10,AW10,AY10,BA10,BC10,BE10,BG10,BI10,BK10,BM10,BO10,BQ10,BS10,BU10,BW10,BY10,CA10,CC10,CE10) | C10: CONFIPET | D10: Confidence Petroleum India Ltd | E10: miscellaneous | F10: miscellaneous | G10: smallcap | H10: 2700.46 | I10: 82.74 | J10: 1.8 | K10: 5858829 | L10: 90 | M10: Outperforming | N10: =IF(M10="Underperforming",-5,IF(L10>=95,15,IF(L10>=90,10,IF(L10>=80,5,0)))) | O10: 72.7 | P10: 69.01 | R10: Earnings / Momentum Support | S10: Nifty 50 | T10: 0.85 | U10: 66.91 | V10: 65.5 | W10: 26.52 | X10: Growing Industry | Y10: =IF(X10="Growing Industry",10,IF(X10="Cyclical in an Upturn",5,0)) | Z10: Too Many Players with High ROCE | AA10: =IF(Z10="Monopoly",10,IF(Z10="Oligopoly",5,IF(Z10="Duopoly that cooperate",10,IF(Z10="Duopoly that compete",5,IF(Z10="Too many players with High ROCE",5,0))))) | AB10: No | AC10: =IF(AB10="No",5,0) | AD10: Headwind | AE10: =IF(AD10="Tailwind",10,0) | AF10: Structural (10 Years Consistency) | AG10: =IF(AF10="Structural (10 Years Consistency)",10,IF(AF10="Shallow Cyclical (2 to 3 years growth)",5,0)) | AH10: No | AI10: =IF(AH10="Yes due to Product Mix change or Operating Leverage",10,IF(AH10="Yes, these are peak margins",-5,IF(AH10="No",5,0))) | AJ10: Stable | AK10: =IF(AJ10="Stable",10,0) | AL10: Yes | AM10: =IF(AL10="Yes",10,0) | AN10: B2B | AO10: =IF(AN10="B2C",10,IF(AN10="B2B",5,0)) | AP10: No | AQ10: =IF(AP10="Yes",10,0) | AR10: Higher One Time, Lower Annuity | AS10: =IF(AR10="Fully Annuity",10,IF(AR10="Higher Annuity, Lower One Time",5,IF(AR10="Higher One Time, Lower Annuity",3,0))) | AT10: Good | AU10: =IF(AT10="Good",10,0) | AV10: Yes for more than 2 years | AW10: =IF(AV10="Yes for more than 2 years",10,IF(AV10="Yes only for next 1 to 2 years",5,0)) | AX10: Above 40 | AY10: =IF(AX10="Above 40",20,IF(AX10="20 to 40",10,IF(AX10="0 to 20",-5,0))) | AZ10: Between 50 to 75 | BA10: =IF(AZ10="Between 50 to 75",10,IF(AZ10="Above 75",0,0)) | BB10: Stage 3 | BC10: =IF(BB10="Stage 2",20,IF(BB10="Stage 1",0,IF(BB10="Stage 3",5,IF(BB10="Stage 4",-5,0)))) | BD10: Negative Trend | BE10: =IF(BD10="Positive Trend",20,IF(BD10="Negative Trend",-10,0)) | BF10: Uptrend | BG10: =IF(BF10="Uptrend",10,IF(BF10="Sideways",5,0)) | BH10: Uptrend | BI10: =IF(BH10="Uptrend",10,IF(BH10="Sideways",5,0)) | BJ10: Close to 52 week high or retracement | BK10: =IF(BJ10="Overhead supply in last 2 years in last 2 years",-5,IF(BJ10="Close to 52 week high or retracement",5,IF(BJ10="Blue sky scenario",10,IF(BJ10="Long term Downtrend",-10,0)))) | BL10: Yes | BM10: =IF(BL10="Yes",10,0) | BN10: More than 20% | BO10: =IF(BN10="More than 20%",10,IF(BN10="Between 12 to 20%",5,IF(BN10="Less than 12%",0,0))) | BP10: No | BQ10: =IF(BP10="No",10,0) | BR10: No | BS10: =IF(BR10="NO",5,0) | BT10: Less than 1.5 | BU10: =IF(BT10="Above 2",0,IF(BT10="Between 1.5 to 2",5,IF(BT10="Less than 1.5",10,0))) | BV10: Above 70% | BW10: =IF(BV10="Above 70%",10,IF(BV10="Between 50% to 70%",5,IF(BV10="Less than 50%",0,IF(BV10="Negative",-10,IF(BV10="Less than 50% and Borrowings are increasing",-5,0))))) | BX10: Less than 0.7 | BY10: =IF(BX10="More than 1.2",-10,IF(BX10="Between 0.7 to 1.2",0,IF(BX10="Less than 0.7",10,0))) | BZ10: No | CA10: =IF(BZ10="Yes",-10,0) | CB10: Less than 15% | CC10: =IF(CB10="More than 15%",-10,IF(CB10="Less than 15%",10,0)) | CD10: No | CE10: =IF(CD10="Yes, more than 10%",-10,IF(CD10="No",10,0))
