Workbook

Sheet Read Me
A1: 🏆 MONIT MULTIBAGGER RESEARCH ENGINE & SCANNER
A2: Daily Analytics Report | Generated: Thursday, 17 September 2026
A5: 📖 QUICK REFERENCE RUNBOOK & SYSTEM FLOW
A6: Step 1: Reference this Read Me | B6: Understand terms, formulas, and underlying investment theses directly in this glossary dashboard.
A7: Step 2: Check Leaderboard Tab | B7: Locate long-term compounders with high Persistence Scores and streaks (institutional accumulation footprint).
A8: Step 3: Analyze Confluence Overlap | B8: Review the ultimate high-conviction candidates intersecting our scanner signals and StockScans overlaps.
A9: Step 4: Scoring Monit Tabs | B9: Open 'Monit Non Financial' or 'Monit Banks NBFC' to fill out your qualitative checks (Tailwinds, Promoters, Triggers).
A10: Step 5: Track Scan Matches | B10: Confirm consensus using 'Scan Match' tabs which score companies by total appearances across allStockScans.
A13: 📊 RESEARCH ENGINE GLOSSARY, METRICS & THESES
A15: Metric Term / Tab Name | B15: Practical Meaning & Underlying Investment Thesis | C15: Automated DB Query / Logic & Excel Formula
A16: EMA Crossover (Birth of a Trend) | B16: An entry signal triggered when price crosses above its 200-day EMA. [THESIS]: Represents the birth of a new long-term uptrend. Buying here provides maximum asymmetrical risk-to-reward because the entry is close to the logical stop-loss (the EMA itself). | C16: pine_signal == 'EMA Crossover' Sized at 7% capital allocation (~₹70,000 per position).
A17: 52W Breakout (Momentum Confirmation) | B17: A momentum signal triggered when a stock above its 200-day EMA breaks out to fresh 52-week highs. [THESIS]: Represents a confirmed breakout where institutional buying pressure clears all historical supply. High momentum outperformance. | C17: pine_signal == '52W Breakout' Sized at 5% capital allocation (~₹50,000 per position).
A18: ATH Momentum (Runaway Leader) | B18: An established trend signal triggered when the price is actively running near its All-Time Highs. [THESIS]: Identifies the strongest runaway leaders in the market. Ideal for high-velocity momentum trading where price experiences immediate continuation. | C18: pine_signal == 'ATH Momentum' Sized at 4% capital allocation (~₹40,000 per position).
A19: Persistence Score (30D) (Accumulation Footprint) | B19: The count of times a stock has appeared in the daily screener during the last 30 active trading days. [THESIS]: Represents persistent institutional buying. Random spikes appear 1-2 times, but compounders appear 10+ times as institutions accumulate. | C19: Queries the local SQLite database (`logs/backtest.db`) to sum the total number of distinct dates the ticker appeared on the screener during the last 30 active trading days. Formula: COUNT(DISTINCT date)
A20: Consecutive Streak Days (Uninterrupted Trend) | B20: The number of consecutive trading days that the stock has appeared in the screener up to today. [THESIS]: High streaks indicate an exceptionally strong, uninterrupted runaway trend with heavy daily buying pressure. | C20: Checks the chronological sequence of scanner dates in SQLite starting from the most recent run date and counting backward. The streak increments for every contiguous date the ticker appears.
A21: Sector Velocity WoW (Early Sector Rotation) | B21: Compares the volume of screener signals in a sector over the last 5 trading days (W1) against the previous 5 trading days (W2). [THESIS]: Detects early sector rotation. A sudden positive surge warns you of capital flowing aggressively into a specific theme. | C21: Counts appearances of all tickers categorized by their sector. Formula: W1_Count = COUNT(records WHERE date IN last 5 trading days) W2_Count = COUNT(records WHERE date IN days -10 to -5) Velocity % = ((W1_Count - W2_Count) / W2_Count) * 100
A22: Emerging Leaders (Momentum Expansion) | B22: Identifies breakout stocks experiencing a sudden momentum expansion. [THESIS]: Finds stocks with a high concentration of appearances recently but almost zero history in the preceding months. Represents new institutional entries. | C22: Finds stocks with at least 5 appearances in the last 10 trading days, but less than or equal to 3 appearances in the prior 50 trading days (i.e. trading days -60 to -10). Formula: COUNT(recent) >= 5 AND COUNT(historical) <= 3
A23: Tab: Confluence Overlap (The Ultimate Overlap) | B23: This sheet displays the absolute highest conviction watchlist candidates intersecting multiple strategies. [THESIS]: Filters out market noise by only displaying stocks appearing in at least two out of three major momentum dimensions: (1) Chartink screener universe, (2) Active scanner signals, and (3) StockScans overlap list. | C23: Calculates the mathematical intersection of the three sets: In_Universe + In_Scanner + In_StockScans >= 2 Single-dimension matches are automatically filtered out to eliminate market noise.
A24: Tab: Monit Non Financial (CHECKLIST SHEET) | B24: Your main watchlist scoring sheet for non-financial companies. [THESIS]: Keeps watchlist scoring fully formula-driven using Excel formulas. It combines automated metrics (RSI, ADX, V-stop, Persistence) with your qualitative scores (Promoter Buying, Near-Term Trigger, Headwind/Tailwind). | C24: Uses relative index-matching formulas to populate automated close prices, RSI, ADX, V-stop, and Persistence from the SQLite and Chartink universe sheets. Formula: INDEX-MATCH left-lookup.
A25: Tab: Monit Banks NBFC (BANKING CHECKLIST) | B25: Your main watchlist scoring sheet for banking and NBFC companies. [THESIS]: Tailored specifically for banking structures, incorporating specialized metrics like Net Interest Margins (NIM) and Credit Costs alongside technical indicators. | C25: Features banking-specific checklist criteria to ensure qualitative analyst inputs align with bank metrics.
A26: Tab: Scan Match tabs (StockScans Confluence) | B26: Displays the top 100 stocks appearing across all StockScans screeners. [THESIS]: Scores stocks qualitatively by scan volume. Stocks appearing in >20 scans receive a premium 10-point bonus, proving market-wide momentum consensus. | C26: Applies a nested Excel IF formula: `=IF(D8>20,10,IF(D8>=10,5,2))` Scores: >20 scans = 10 pts; 10-20 scans = 5 pts; <10 scans = 2 pts.
... A36: Weekly Tracking Highlighting (Additions / Removals) | B36: Visual highlights indicating weekly changes in the StockScans 100 (Scan Match) list. [THESIS]: Helps track the weekly turnover. Newly added candidates indicate fresh institutional attention, while removed candidates represent names losing relative strength. | C36: Compares daily lists against Monday's baseline database: - Added stocks: Highlighted in Soft Blue. - Removed stocks: Listed in the bottom section of Scan Match sheets.

Sheet Leaderboard
A1: 🌟 MULTIBAGGER MOMENTUM & SECTOR ROTATION LEADERBOARD 🌟
A4: TOP PERSISTENT MOMENTUM LEADERS (30D) | J4: SECTOR MOMENTUM VELOCITY HEATMAP (WoW)
A5: Rank | B5: Score | C5: Symbol | D5: Company Name | E5: Sector | F5: Streak (Days) | G5: Market Cap Cr | H5: Classification | J5: Sector Name | K5: Current Wk Count | L5: Previous Wk Count | M5: Velocity WoW %
A6: 1 | B6: 432 | C6: CYIENTDLM | D6: Cyient DLM Ltd | E6: aerospace & defence | F6: 57 | G6: 7092.9 | H6: Potential Leader | J6: telecom-service | K6: 9 | L6: 8 | M6: 12.5%
A7: 2 | B7: 426 | C7: SETL | D7: Standard Enginnering Technology Ltd | E7: industrials | F7: 56 | G7: 8008.59 | H7: Potential Leader | J7: services | K7: 39 | L7: 41 | M7: -4.9%
A8: 3 | B8: 384 | C8: SUNDRMFAST | D8: Sundram Fasteners Limited | E8: auto | F8: 49 | G8: 25776.45 | H8: Potential Leader | J8: realty | K8: 75 | L8: 94 | M8: -20.2%
A9: 4 | B9: 360 | C9: KABRAEXTRU | D9: Kabra Extrusion Technik Limited | E9: industrials | F9: 45 | G9: 2212.91 | H9: Potential Leader | J9: transportation | K9: 33 | L9: 45 | M9: -26.7%
A10: 5 | B10: 348 | C10: DIVISLAB | D10: Divi's Laboratories Limited | E10: healthcare | F10: 43 | G10: 247496.36 | H10: Potential Leader | J10: auto | K10: 73 | L10: 101 | M10: -27.7%
A11: 6 | B11: 348 | C11: MENONBE | D11: Menon Bearings Limited | E11: auto | F11: 43 | G11: 1709.5 | H11: Potential Leader | J11: healthcare | K11: 196 | L11: 275 | M11: -28.7%
A12: 7 | B12: 348 | C12: TFCILTD | D12: Tourism Finance Corporation Of India Limited | E12: financials | F12: 43 | G12: 6438.16 | H12: Potential Leader | J12: miscellaneous | K12: 30 | L12: 44 | M12: -31.8%
A13: 8 | B13: 348 | C13: VSSL | D13: Vardhman Special Steels Limited | E13: metals & mining | F13: 43 | G13: 3925.92 | H13: Potential Leader | J13: industrials | K13: 173 | L13: 258 | M13: -32.9%
A14: 9 | B14: 336 | C14: WSTCSTPAPR | D14: West Coast Paper Mills Limited | E14: building materials | F14: 41 | G14: 4732.07 | H14: Potential Leader | J14: chemicals | K14: 91 | L14: 137 | M14: -33.6%
A15: 10 | B15: 324 | C15: PAYTM | D15: One 97 Communications Ltd | E15: i.t | F15: 39 | G15: 112891.41 | H15: Potential Leader | J15: i.t | K15: 44 | L15: 67 | M15: -34.3%
A16: 11 | B16: 318 | C16: DEEPINDS | D16: Deep Industries Ltd | E16: energy | F16: 38 | G16: 4702.08 | H16: Potential Leader | J16: aerospace & defence | K16: 46 | L16: 72 | M16: -36.1%
A17: 12 | B17: 318 | C17: REDINGTON | D17: Redington (india) Limited | E17: services | F17: 38 | G17: 31278.8 | H17: Potential Leader | J17: power & utilities | K17: 7 | L17: 11 | M17: -36.4%
... A20: 15 | B20: 300 | C20: MMP | D20: MMP Industries Ltd | E20: metals & mining | F20: 35 | G20: 881.14 | H20: Potential Leader | J20: metals & mining | K20: 86 | L20: 137 | M20: -37.2%
A21: 16 | B21: 294 | C21: DOLPHIN | D21: Dolphin Offshore Enterprises (India) Ltd | E21: energy | F21: 34 | G21: 2695.11 | H21: Potential Leader
A22: 17 | B22: 294 | C22: PTCIL | D22: PTC Industries Ltd | E22: industrials | F22: 34 | G22: 33988.11 | H22: Potential Leader
A23: 18 | B23: 294 | C23: RATNAVEER | D23: Ratnaveer Precision Engineering Ltd | E23: metals & mining | F23: 34 | G23: 2170.3 | H23: Potential Leader
A24: 19 | B24: 294 | C24: SHILPAMED | D24: Shilpa Medicare Limited | E24: healthcare | F24: 34 | G24: 18743.58 | H24: Potential Leader
A25: 20 | B25: 294 | C25: STLTECH | D25: Sterlite Technologies Limited | E25: industrials | F25: 34 | G25: 42522.34 | H25: Potential Leader
A28: 🌟 EMERGING LEADERS (MOMENTUM EXPANSION) | J28: 💎 SATELLITE HOLDINGS SHORTLIST (MCAP < 25K CR)
A29: Symbol | B29: Company Name | C29: Sector | D29: Recent Matches (10D) | E29: Historical Matches | F29: Market Cap Cr | J29: Symbol | K29: Sector | L29: Monit Score | M29: Market Cap Cr | N29: Appearances (30D)
A30: SHREEJISPG | B30: Shreeji Shipping Global Ltd | C30: transportation | D30: 10 | E30: 1 | F30: 11257.65 | J30: CUB | K30: bank | L30: 295 | M30: 22968.43 | N30: 14
A31: IONEXCHANG | B31: Ion Exchange (India) Ltd | C31: realty | D31: 10 | E31: 1 | F31: 6223.8 | J31: IBULLSLTD | K31: miscellaneous | L31: 295 | M31: 6907.1 | N31: 3
A32: UNITEDPOLY | B32: United Polyfab Gujarat Ltd | C32: textiles | D32: 10 | E32: 0 | F32: 1018.13 | J32: VISHNU | K32: chemicals | L32: 288 | M32: 4773.33 | N32: 24
A33: MVGJL | B33: Manoj Vaibhav Gems N Jewellers Ltd | C33: consumer discretionary | D33: 10 | E33: 1 | F33: 1052.03 | J33: UNIVPHOTO | K33: consumer discretionary | L33: 288 | M33: 672.12 | N33: 14
A34: PCJEWELLER | B34: Pc Jeweller Limited | C34: consumer discretionary | D34: 9 | E34: 0 | F34: 11992.51 | J34: TALBROAUTO | K34: auto | L34: 288 | M34: 2686.41 | N34: 12
A35: INDIQUBE | B35: Indiqube Spaces Ltd | C35: co-working | D35: 9 | E35: 0 | F35: 4291.89 | J35: TFCILTD | K35: financials | L35: 287 | M35: 6438.16 | N35: 30
A36: SPLPETRO | B36: Supreme Petrochem Ltd | C36: energy | D36: 9 | E36: 0 | F36: 15174.94 | J36: VINCOFE | K36: consumer discretionary | L36: 287 | M36: 2563.53 | N36: 18
A37: SMSPHARMA | B37: Sms Pharmaceuticals Limited | C37: healthcare | D37: 9 | E37: 2 | F37: 3874.85 | J37: WELINV | K37: financials | L37: 285 | M37: 831.39 | N37: 22
A38: JUBLPHARMA | B38: Jubilant Pharmova Ltd | C38: healthcare | D38: 8 | E38: 2 | F38: 16120.84 | J38: TBZ | K38: consumer discretionary | L38: 285 | M38: 3836.01 | N38: 23
A39: SRHHYPOLTD | B39: Sree Rayalaseema Hi-strength Hypo Limited | C39: chemicals | D39: 8 | E39: 0 | F39: 888.45 | J39: DCBBANK | K39: bank | L39: 285 | M39: 7037.71 | N39: 20
A40: AHCL | B40: Anlon Healthcare Ltd | C40: healthcare | D40: 8 | E40: 0 | F40: 1160.83 | J40: BHAGYANGR | K40: power & utilities | L40: 285 | M40: 1495.62 | N40: 8
A41: WENDT | B41: Wendt (india) Limited | C41: industrials | D41: 8 | E41: 1 | F41: 1753 | J41: NORTHARC | K41: financials | L41: 285 | M41: 5018.87 | N41: 10
A45: 🚀 HIGH MOMENTUM LEADERS (RS RATING >= 90)
A46: Rank | B46: RS Rating | C46: O'Neil Score | D46: Monit Score | E46: Symbol | F46: Company Name | G46: Sector | H46: Market Cap Cr
A47: 1 | B47: 99 | C47: 85 | D47: 285 | E47: TBZ | F47: Tribhovandas Bhimji Zaveri Limited | G47: consumer discretionary | H47: 3836.01
A48: 2 | B48: 99 | C48: 68.27 | D48: 258 | E48: SIGMAADV | F48: Sigma Advanced System Ltd | G48: aerospace & defence | H48: 16247.4
A49: 3 | B49: 98 | C49: 65.62 | D49: 275 | E49: BODALCHEM | F49: Bodal Chemicals Limited | G49: chemicals | H49: 2293.82
...

Sheet Chartink Universe
A1: symbol | B1: company | C1: sector | D1: industry | E1: marketcap_bucket | F1: marketcap_cr | G1: close | H1: today_return_pct | I1: volume | J1: bse_code
A2: ASTEC | B2: Astec Lifesciences Limited | C2: chemicals | D2: pesticides / agrochemicals - indian | E2: smallcap | F2: 1682.69 | G2: 755.15 | H2: 14.08 | I2: 994540 | J2: 533138
A3: TEGA | B3: Tega Industries Ltd | C3: industrials | D3: engineering | E3: midcap | F3: 14424.52 | G3: 1920 | H3: 11.82 | I3: 3909542 | J3: 543413
A4: SHAREINDIA | B4: Share India Securities Ltd | C4: financials | D4: finance & investments | E4: smallcap | F4: 4780.02 | G4: 218.44 | H4: 11.42 | I4: 28924428 | J4: 540725
A5: TREL | B5: TransIndia Real Estate Ltd | C5: transportation | D5: miscellaneous | E5: smallcap | F5: 731.44 | G5: 29.77 | H5: 10.14 | I5: 726901 | J5: 543955
A6: VENUSPIPES | B6: Venus Pipes & Tubes Ltd | C6: metals & mining | D6: steel - medium / small | E6: smallcap | F6: 4416.05 | G6: 2131.7 | H6: 9.99 | I6: 1296328 | J6: 543528
A7: AXISCADES | B7: AXISCADES Technologies Ltd | C7: aerospace & defence | D7: computers - software - medium / small | E7: midcap | F7: 7878.02 | G7: 1852.3 | H7: 9.96 | I7: 443978 | J7: 532395
A8: YATHARTH | B8: Yatharth Hospital & Trauma Care Services Ltd | C8: healthcare | D8: healthcare | E8: midcap | F8: 10333.04 | G8: 1072.4 | H8: 9.17 | I8: 3679332 | J8: 543950
A9: AHCL | B9: Anlon Healthcare Ltd | C9: healthcare | D9: pharmaceuticals - indian - bulk drugs & formln | E9: smallcap | F9: 1160.83 | G9: 21.84 | H9: 8.98 | I9: 49745313 | J9: 544497
A10: GNFC | B10: Gujarat Narmada Valley Fertilizers And Chemicals Limited | C10: chemicals | D10: chemicals | E10: midcap | F10: 8593.83 | G10: 584.85 | H10: 8.36 | I10: 8250274 | J10: 500670
A11: MOTISONS | B11: Motisons Jewellers Ltd | C11: consumer discretionary | D11: diamond cutting / jewellery | E11: smallcap | F11: 2040.69 | G11: 17.94 | H11: 7.94 | I11: 236263034 | J11: 544053
A12: IRISDOREME | B12: Iris Clothings Ltd | C12: consumer discretionary | D12: textiles - products | E12: smallcap | F12: 1190.52 | G12: 62.55 | H12: 7.51 | I12: 1031078 | J12: 535123
A13: KROSS | B13: Kross Ltd | C13: auto | D13: auto ancillaries | E13: smallcap | F13: 1561.45 | G13: 242.05 | H13: 7.17 | I13: 1745433 | J13: 544253
... A26: BHAGYANGR | B26: Bhagyanagar India | C26: power & utilities | D26: power generation and supply | E26: smallcap | F26: 1495.62 | G26: 446.5 | H26: 5 | I26: 66357 | J26: 512296
A27: VALIANTLAB | B27: Valiant Laboratories Ltd | C27: healthcare | D27: pharmaceuticals - indian - bulk drugs & formln | E27: smallcap | F27: 666.69 | G27: 122.75 | H27: 5 | I27: 67876
A28: SALSTEEL | B28: SAL Steel | C28: metals & mining | D28: steel - sponge iron | E28: smallcap | F28: 1134.25 | G28: 78.35 | H28: 5 | I28: 243492 | J28: 532604
A29: ANUHPHR | B29: Anuh Pharma Ltd | C29: healthcare | D29: pharmaceuticals - indian - bulk drugs | E29: smallcap | F29: 938.9 | G29: 93.68 | H29: 5 | I29: 322234 | J29: 506260
A30: BODALCHEM | B30: Bodal Chemicals Limited | C30: chemicals | D30: dyes and pigments | E30: smallcap | F30: 2293.82 | G30: 182.13 | H30: 5 | I30: 2362229 | J30: 524370
A31: VALIANTORG | B31: Valiant Organics Ltd | C31: chemicals | D31: chemicals | E31: smallcap | F31: 1145.07 | G31: 408.45 | H31: 5 | I31: 79412 | J31: 540145
A32: SOFTTECH | B32: Softtech Engineers Ltd | C32: i.t | D32: computers - software - medium / small | E32: smallcap | F32: 693.08 | G32: 500.7 | H32: 4.99 | I32: 18047 | J32: 535078
A33: BHAGERIA | B33: Bhageria Industries Limited | C33: chemicals | D33: dyes and pigments | E33: smallcap | F33: 1391.59 | G33: 318.85 | H33: 4.99 | I33: 65522 | J33: 530803
A34: BIRLACABLE | B34: Birla Cable Limited | C34: industrials | D34: cables - telephone | E34: smallcap | F34: 1204.95 | G34: 401.65 | H34: 4.99 | I34: 431704 | J34: 500060
A35: STLNETWORK | B35: STL Networks Ltd | C35: telecom-service | D35: telecommunications - service provider | E35: smallcap | F35: 1996.72 | G35: 40.91 | H35: 4.98 | I35: 5830611 | J35: 544395
A36: MAZDA | B36: Mazda Limited | C36: industrials | D36: engineering | E36: smallcap | F36: 527.56 | G36: 263.45 | H36: 4.98 | I36: 10263 | J36: 523792
A37: STEL | B37: Stel Holdings Limited | C37: financials | D37: finance & investments | E37: smallcap | F37: 1166.2 | G37: 631.9 | H37: 4.96 | I37: 5198
A38: NORTHARC | B38: Northern ARC Capital Ltd | C38: financials | D38: finance & investments | E38: midcap | F38: 5018.87 | G38: 310.55 | H38: 4.95 | I38: 2358970
A39: OMAXE | B39: Omaxe Limited | C39: realty | D39: construction | E39: smallcap | F39: 2208.71 | G39: 120.76 | H39: 4.94 | I39: 755723 | J39: 532880
A40: SIGMAADV | B40: Sigma Advanced System Ltd | C40: aerospace & defence | D40: electronics - components | E40: midcap | F40: 16247.4 | G40: 857.4 | H40: 4.94 | I40: 292634 | J40: 532408
A41: PAISALO | B41: Paisalo Digital Ltd | C41: financials | D41: finance & investments | E41: midcap | F41: 8070.19 | G41: 88.73 | H41: 4.89 | I41: 26502335 | J41: 532900
A42: ACE | B42: Action Construction Equipment Limited | C42: industrials | D42: engineering | E42: midcap | F42: 14356.67 | G42: 1205.6 | H42: 4.86 | I42: 685925 | J42: 532762
A43: ONWARDTEC | B43: Onward Technologies Limited | C43: i.t | D43: computers - software - medium / small | E43: smallcap | F43: 648.94 | G43: 291.75 | H43: 4.72 | I43: 72827 | J43: 517536
A44: VIJAYA | B44: Vijaya Diagnostic Centre Ltd | C44: healthcare | D44: healthcare | E44: midcap | F44: 15497.28 | G44: 1506.1 | H44: 4.71 | I44: 196070 | J44: 543350
A45: QPOWER | B45: Quality Power Electrical Equipments Ltd | C45: industrials | D45: electric equipment | E45: midcap | F45: 11537.62 | G45: 1489.8 | H45: 4.7 | I45: 728624 | J45: 544367
A46: RGL | B46: Renaissance Global Ltd | C46: consumer discretionary | D46: diamond cutting / jewellery | E46: smallcap | F46: 1680.21 | G46: 156.49 | H46: 4.68 | I46: 777575 | J46: 532923
A47: WELSPUNLIV | B47: Welspun Living Ltd | C47: textiles | D47: textiles - products | E47: largecap | F47: 20052.37 | G47: 212.25 | H47: 4.65 | I47: 5153292 | J47: 514162
A48: AEGISVOPAK | B48: Aegis Vopak Terminals Ltd | C48: transportation | D48: miscellaneous | E48: largecap | F48: 34425.3 | G48: 310.7 | H48: 4.63 | I48: 6087355 | J48: 544407
A49: PFOCUS | B49: Prime Focus Limited | C49: realty | D49: miscellaneous | E49: largecap | F49: 26008.55 | G49: 334.95 | H49: 4.52 | I49: 6593481 | J49: 532748
A50: NOVARTIND | B50: Novartis India Ltd | C50: healthcare | D50: pharmaceuticals - multinational | E50: midcap | F50: 5141.12 | G50: 2082.2 | H50: 4.34 | I50: 153168 | J50: 500672
... A242: SETL | B242: Standard Enginnering Technology Ltd | C242: industrials | D242: engineering | E242: midcap | F242: 8008.59 | G242: 401.45 | H242: -4.99 | I242: 2842075 | J242: 544333

Sheet Confluence Overlap
A1: Confluence Rank | B1: Total Score | C1: Relative Strength Rating | D1: Symbol | E1: Company Name | F1: Industry | G1: Common Count | H1: Scanner Signal | I1: Chartink Universe | J1: Scan Matches Count | K1: Backtest Recurrence (30D)
A2: =IF(B2=0,"",ROW()-1) | B2: =IFERROR(INDEX('Monit Non Financial'!$B$2:$B$400, MATCH(D2, 'Monit Non Financial'!$C$2:$C$400, 0)), IFERROR(INDEX('Monit Banks NBFC'!$B$2:$B$100, MATCH(D2, 'Monit Banks NBFC'!$C$2:$C$100, 0)), 0)) | C2: =IFERROR(INDEX('Monit Non Financial'!$L$2:$L$400, MATCH(D2, 'Monit Non Financial'!$C$2:$C$400, 0)), IFERROR(INDEX('Monit Banks NBFC'!$L$2:$L$100, MATCH(D2, 'Monit Banks NBFC'!$C$2:$C$100, 0)), "")) | D2: IBULLSLTD | E2: Indiabulls Limited | F2: Diversified | G2: 2 | H2: No | I2: Yes | J2: 25 | K2: 3
A3: =IF(B3=0,"",ROW()-1) | B3: =IFERROR(INDEX('Monit Non Financial'!$B$2:$B$400, MATCH(D3, 'Monit Non Financial'!$C$2:$C$400, 0)), IFERROR(INDEX('Monit Banks NBFC'!$B$2:$B$100, MATCH(D3, 'Monit Banks NBFC'!$C$2:$C$100, 0)), 0)) | C3: =IFERROR(INDEX('Monit Non Financial'!$L$2:$L$400, MATCH(D3, 'Monit Non Financial'!$C$2:$C$400, 0)), IFERROR(INDEX('Monit Banks NBFC'!$L$2:$L$100, MATCH(D3, 'Monit Banks NBFC'!$C$2:$C$100, 0)), "")) | D3: TFCILTD | E3: Tourism Finance Corporation Of India Limited | F3: Finance - PSU Lending | G3: 2 | H3: No | I3: Yes | J3: 19 | K3: 30
A4: =IF(B4=0,"",ROW()-1) | B4: =IFERROR(INDEX('Monit Non Financial'!$B$2:$B$400, MATCH(D4, 'Monit Non Financial'!$C$2:$C$400, 0)), IFERROR(INDEX('Monit Banks NBFC'!$B$2:$B$100, MATCH(D4, 'Monit Banks NBFC'!$C$2:$C$100, 0)), 0)) | C4: =IFERROR(INDEX('Monit Non Financial'!$L$2:$L$400, MATCH(D4, 'Monit Non Financial'!$C$2:$C$400, 0)), IFERROR(INDEX('Monit Banks NBFC'!$L$2:$L$100, MATCH(D4, 'Monit Banks NBFC'!$C$2:$C$100, 0)), "")) | D4: VINCOFE | E4: Vintage Coffee & Beverages Ltd | F4: FMCG - Coffee | G4: 2 | H4: No | I4: Yes | J4: 21 | K4: 18
A5: =IF(B5=0,"",ROW()-1) | B5: =IFERROR(INDEX('Monit Non Financial'!$B$2:$B$400, MATCH(D5, 'Monit Non Financial'!$C$2:$C$400, 0)), IFERROR(INDEX('Monit Banks NBFC'!$B$2:$B$100, MATCH(D5, 'Monit Banks NBFC'!$C$2:$C$100, 0)), 0)) | C5: =IFERROR(INDEX('Monit Non Financial'!$L$2:$L$400, MATCH(D5, 'Monit Non Financial'!$C$2:$C$400, 0)), IFERROR(INDEX('Monit Banks NBFC'!$L$2:$L$100, MATCH(D5, 'Monit Banks NBFC'!$C$2:$C$100, 0)), "")) | D5: SYRMA | E5: Syrma SGS Technology Ltd | F5: Consumer Electronics - EMS | G5: 2 | H5: No | I5: Yes | J5: 24 | K5: 21
A6: =IF(B6=0,"",ROW()-1) | B6: =IFERROR(INDEX('Monit Non Financial'!$B$2:$B$400, MATCH(D6, 'Monit Non Financial'!$C$2:$C$400, 0)), IFERROR(INDEX('Monit Banks NBFC'!$B$2:$B$100, MATCH(D6, 'Monit Banks NBFC'!$C$2:$C$100, 0)), 0)) | C6: =IFERROR(INDEX('Monit Non Financial'!$L$2:$L$400, MATCH(D6, 'Monit Non Financial'!$C$2:$C$400, 0)), IFERROR(INDEX('Monit Banks NBFC'!$L$2:$L$100, MATCH(D6, 'Monit Banks NBFC'!$C$2:$C$100, 0)), "")) | D6: TBZ | E6: Tribhovandas Bhimji Zaveri Limited | F6: Diamond, Gems & Jewellery | G6: 2 | H6: No | I6: Yes | J6: 23 | K6: 23
A7: =IF(B7=0,"",ROW()-1) | B7: =IFERROR(INDEX('Monit Non Financial'!$B$2:$B$400, MATCH(D7, 'Monit Non Financial'!$C$2:$C$400, 0)), IFERROR(INDEX('Monit Banks NBFC'!$B$2:$B$100, MATCH(D7, 'Monit Banks NBFC'!$C$2:$C$100, 0)), 0)) | C7: =IFERROR(INDEX('Monit Non Financial'!$L$2:$L$400, MATCH(D7, 'Monit Non Financial'!$C$2:$C$400, 0)), IFERROR(INDEX('Monit Banks NBFC'!$L$2:$L$100, MATCH(D7, 'Monit Banks NBFC'!$C$2:$C$100, 0)), "")) | D7: BHAGYANGR | E7: Bhagyanagar India | F7: Recycling | G7: 2 | H7: No | I7: Yes | J7: 23 | K7: 8
A8: =IF(B8=0,"",ROW()-1) | B8: =IFERROR(INDEX('Monit Non Financial'!$B$2:$B$400, MATCH(D8, 'Monit Non Financial'!$C$2:$C$400, 0)), IFERROR(INDEX('Monit Banks NBFC'!$B$2:$B$100, MATCH(D8, 'Monit Banks NBFC'!$C$2:$C$100, 0)), 0)) | C8: =IFERROR(INDEX('Monit Non Financial'!$L$2:$L$400, MATCH(D8, 'Monit Non Financial'!$C$2:$C$400, 0)), IFERROR(INDEX('Monit Banks NBFC'!$L$2:$L$100, MATCH(D8, 'Monit Banks NBFC'!$C$2:$C$100, 0)), "")) | D8: SHAREINDIA | E8: Share India Securities Ltd | F8: Finance - Capital Markets - Brokers | G8: 2 | H8: No | I8: Yes | J8: 26 | K8: 8
A9: =IF(B9=0,"",ROW()-1) | B9: =IFERROR(INDEX('Monit Non Financial'!$B$2:$B$400, MATCH(D9, 'Monit Non Financial'!$C$2:$C$400, 0)), IFERROR(INDEX('Monit Banks NBFC'!$B$2:$B$100, MATCH(D9, 'Monit Banks NBFC'!$C$2:$C$100, 0)), 0)) | C9: =IFERROR(INDEX('Monit Non Financial'!$L$2:$L$400, MATCH(D9, 'Monit Non Financial'!$C$2:$C$400, 0)), IFERROR(INDEX('Monit Banks NBFC'!$L$2:$L$100, MATCH(D9, 'Monit Banks NBFC'!$C$2:$C$100, 0)), "")) | D9: IOLCP | E9: Iol Chemicals And Pharmaceuticals Limited | F9: Pharma - API & CRAMS | G9: 2 | H9: No | I9: Yes | J9: 21 | K9: 26
A10: =IF(B10=0,"",ROW()-1) | B10: =IFERROR(INDEX('Monit Non Financial'!$B$2:$B$400, MATCH(D10, 'Monit Non Financial'!$C$2:$C$400, 0)), IFERROR(INDEX('Monit Banks NBFC'!$B$2:$B$100, MATCH(D10, 'Monit Banks NBFC'!$C$2:$C$100, 0)), 0)) | C10: =IFERROR(INDEX('Monit Non Financial'!$L$2:$L$400, MATCH(D10, 'Monit Non Financial'!$C$2:$C$400, 0)), IFERROR(INDEX('Monit Banks NBFC'!$L$2:$L$100, MATCH(D10, 'Monit Banks NBFC'!$C$2:$C$100, 0)), "")) | D10: SAKAR | E10: Sakar Healthcare Ltd | F10: Hospitals | G10: 2 | H10: No | I10: Yes | J10: 22 | K10: 18
A11: =IF(B11=0,"",ROW()-1) | B11: =IFERROR(INDEX('Monit Non Financial'!$B$2:$B$400, MATCH(D11, 'Monit Non Financial'!$C$2:$C$400, 0)), IFERROR(INDEX('Monit Banks NBFC'!$B$2:$B$100, MATCH(D11, 'Monit Banks NBFC'!$C$2:$C$100, 0)), 0)) | C11: =IFERROR(INDEX('Monit Non Financial'!$L$2:$L$400, MATCH(D11, 'Monit Non Financial'!$C$2:$C$400, 0)), IFERROR(INDEX('Monit Banks NBFC'!$L$2:$L$100, MATCH(D11, 'Monit Banks NBFC'!$C$2:$C$100, 0)), "")) | D11: PAISALO | E11: Paisalo Digital Ltd | F11: Finance - Capital Markets - Brokers | G11: 2 | H11: No | I11: Yes | J11: 21 | K11: 11
A12: =IF(B12=0,"",ROW()-1) | B12: =IFERROR(INDEX('Monit Non Financial'!$B$2:$B$400, MATCH(D12, 'Monit Non Financial'!$C$2:$C$400, 0)), IFERROR(INDEX('Monit Banks NBFC'!$B$2:$B$100, MATCH(D12, 'Monit Banks NBFC'!$C$2:$C$100, 0)), 0)) | C12: =IFERROR(INDEX('Monit Non Financial'!$L$2:$L$400, MATCH(D12, 'Monit Non Financial'!$C$2:$C$400, 0)), IFERROR(INDEX('Monit Banks NBFC'!$L$2:$L$100, MATCH(D12, 'Monit Banks NBFC'!$C$2:$C$100, 0)), "")) | D12: KROSS | E12: Kross Ltd | F12: Auto Ancillaries - Transmission | G12: 2 | H12: No | I12: Yes | J12: 18 | K12: 21
A13: =IF(B13=0,"",ROW()-1) | B13: =IFERROR(INDEX('Monit Non Financial'!$B$2:$B$400, MATCH(D13, 'Monit Non Financial'!$C$2:$C$400, 0)), IFERROR(INDEX('Monit Banks NBFC'!$B$2:$B$100, MATCH(D13, 'Monit Banks NBFC'!$C$2:$C$100, 0)), 0)) | C13: =IFERROR(INDEX('Monit Non Financial'!$L$2:$L$400, MATCH(D13, 'Monit Non Financial'!$C$2:$C$400, 0)), IFERROR(INDEX('Monit Banks NBFC'!$L$2:$L$100, MATCH(D13, 'Monit Banks NBFC'!$C$2:$C$100, 0)), "")) | D13: WHEELS | E13: Wheels India Limited | F13: Auto Ancillaries - Wheels | G13: 2 | H13: No | I13: Yes | J13: 19 | K13: 20
... A70: =IF(B70=0,"",ROW()-1) | B70: =IFERROR(INDEX('Monit Non Financial'!$B$2:$B$400, MATCH(D70, 'Monit Non Financial'!$C$2:$C$400, 0)), IFERROR(INDEX('Monit Banks NBFC'!$B$2:$B$100, MATCH(D70, 'Monit Banks NBFC'!$C$2:$C$100, 0)), 0)) | C70: =IFERROR(INDEX('Monit Non Financial'!$L$2:$L$400, MATCH(D70, 'Monit Non Financial'!$C$2:$C$400, 0)), IFERROR(INDEX('Monit Banks NBFC'!$L$2:$L$100, MATCH(D70, 'Monit Banks NBFC'!$C$2:$C$100, 0)), "")) | D70: PRABHA | E70: Prabha Energy Ltd | F70: Oil Exploration/Allied Services | G70: 2 | H70: No | I70: Yes | J70: 20 | K70: 13

Sheet Monit Non Financial
A1: Rank (Non Financial) | B1: Total Score | C1: Symbol | D1: Company | E1: Sector | F1: Industry | G1: Market Cap Bucket | H1: Market Cap Cr | I1: Close | J1: Today Return % | K1: Volume | L1: Relative Strength Rating | M1: Relative Strength Status | N1: Relative Strength Score | O1: Calculated RSI (14) | P1: Calculated ADX (14) | Q1: Calculated V-stop Line | R1: Calculated Near-term Trigger | S1: Sector Benchmark | T1: Benchmark 1Y Return % | U1: Stock 1Y Return % | V1: Relative Strength 1Y (%) | W1: O'Neil Weighted Score | X1: Industry Growth | Y1: Industry Growth Score | Z1: Competitiveness | AA1: Competitiveness Score | AB1: Regulation | AC1: Regulation Score | AD1: Sector Headwinds/Tailwind | AE1: Sector Headwinds/Tailwind Score | AF1: Industry Type | AG1: Industry Type Score | AH1: Margins | AI1: Margins Score | AJ1: Margins Stability | AK1: Margins Stability Score | AL1: Growth | AM1: Growth Score | AN1: Business Type | AO1: Business Type Score | AP1: Near term triggers | AQ1: Near term triggers Score | AR1: Type of Revenue | AS1: Type of Revenue Score | AT1: Capital Allocation | AU1: Capital Allocation Score | AV1: Medium term Growth | AW1: Medium term Growth Score | AX1: ADX | AY1: ADX Score | AZ1: RSI | BA1: RSI Score | BB1: Stage Analysis | BC1: Stage Analysis Score | BD1: Price Volume Action | BE1: Price Volume Action Score | BF1: Secondary Trend | BG1: Secondary Trend Score | BH1: Primary Trend | BI1: Primary Trend Score | BJ1: Resistance | BK1: Resistance Score | BL1: V-stop | BM1: V-stop Score | BN1: PAT Growth | BO1: PAT Growth Score | BP1: Stock History | BQ1: Stock History Score | BR1: PE Ratio | BS1: PE Ratio Score | BT1: PEG Ratio | BU1: PEG Ratio Score | BV1: CFO to EBITDA | BW1: CFO to EBITDA Score | BX1: Debt to Equity | BY1: Debt to Equity Score | BZ1: Auditor Resignation | CA1: Auditor Resignation Score | CB1: Contingent Liability | CC1: Contingent Liability Score | CD1: Pledging | CE1: Pledging Score
A2: =IF(B2=0,"",RANK(B2,$B$2:$B$222,0)) | B2: =SUM(N2,Y2,AA2,AC2,AE2,AG2,AI2,AK2,AM2,AO2,AQ2,AS2,AU2,AW2,AY2,BA2,BC2,BE2,BG2,BI2,BK2,BM2,BO2,BQ2,BS2,BU2,BW2,BY2,CA2,CC2,CE2) | C2: IBULLSLTD | D2: Indiabulls Limited | E2: miscellaneous | F2: diversified - medium / small | G2: midcap | H2: 6907.1 | I2: 29.65 | J2: 2.99 | K2: 30372525 | L2: 82 | M2: Outperforming | N2: =IF(M2="Underperforming",-5,IF(L2>=95,15,IF(L2>=90,10,IF(L2>=80,5,0)))) | O2: 64.96 | P2: 41.31 | Q2: 21.15 | R2: Volume Spike & Near 52W High Breakout | S2: Nifty 50 | T2: -8.12 | U2: 66.01 | V2: 80.68 | W2: 28.8 | X2: Growing Industry | Y2: =IF(X2="Growing Industry",10,IF(X2="Cyclical in an Upturn",5,0)) | Z2: Too Many Players with High ROCE | AA2: =IF(Z2="Monopoly",10,IF(Z2="Oligopoly",5,IF(Z2="Duopoly that cooperate",10,IF(Z2="Duopoly that compete",5,IF(Z2="Too many players with High ROCE",5,0))))) | AB2: No | AC2: =IF(AB2="No",5,0) | AD2: Tailwind | AE2: =IF(AD2="Tailwind",10,0) | AF2: Structural (10 Years Consistency) | AG2: =IF(AF2="Structural (10 Years Consistency)",10,IF(AF2="Shallow Cyclical (2 to 3 years growth)",5,0)) | AH2: No | AI2: =IF(AH2="Yes due to Product Mix change or Operating Leverage",10,IF(AH2="Yes, these are peak margins",-5,IF(AH2="No",5,0))) | AJ2: Stable | AK2: =IF(AJ2="Stable",10,0) | AL2: Yes | AM2: =IF(AL2="Yes",10,0) | AN2: B2B | AO2: =IF(AN2="B2C",10,IF(AN2="B2B",5,0)) | AP2: Yes | AQ2: =IF(AP2="Yes",10,0) | AR2: Higher One Time, Lower Annuity | AS2: =IF(AR2="Fully Annuity",10,IF(AR2="Higher Annuity, Lower One Time",5,IF(AR2="Higher One Time, Lower Annuity",3,0))) | AT2: Good | AU2: =IF(AT2="Good",10,0) | AV2: Yes for more than 2 years | AW2: =IF(AV2="Yes for more than 2 years",10,IF(AV2="Yes only for next 1 to 2 years",5,0)) | AX2: Above 40 | AY2: =IF(AX2="Above 40",20,IF(AX2="20 to 40",10,IF(AX2="0 to 20",-5,0))) | AZ2: Between 50 to 75 | BA2: =IF(AZ2="Between 50 to 75",10,IF(AZ2="Above 75",0,0)) | BB2: Stage 2 | BC2: =IF(BB2="Stage 2",20,IF(BB2="Stage 1",0,IF(BB2="Stage 3",5,IF(BB2="Stage 4",-5,0)))) | BD2: Positive Trend | BE2: =IF(BD2="Positive Trend",20,IF(BD2="Negative Trend",-10,0)) | BF2: Uptrend | BG2: =IF(BF2="Uptrend",10,IF(BF2="Sideways",5,0)) | BH2: Uptrend | BI2: =IF(BH2="Uptrend",10,IF(BH2="Sideways",5,0)) | BJ2: Blue sky scenario | BK2: =IF(BJ2="Overhead supply in last 2 years in last 2 years",-5,IF(BJ2="Close to 52 week high or retracement",5,IF(BJ2="Blue sky scenario",10,IF(BJ2="Long term Downtrend",-10,0)))) | BL2: Yes | BM2: =IF(BL2="Yes",10,0) | BN2: More than 20% | BO2: =IF(BN2="More than 20%",10,IF(BN2="Between 12 to 20%",5,IF(BN2="Less than 12%",0,0))) | BP2: No | BQ2: =IF(BP2="No",10,0) | BR2: No | BS2: =IF(BR2="NO",5,0) | BT2: Less than 1.5 | BU2: =IF(BT2="Above 2",0,IF(BT2="Between 1.5 to 2",5,IF(BT2="Less than 1.5",10,0))) | BV2: Above 70% | BW2: =IF(BV2="Above 70%",10,IF(BV2="Between 50% to 70%",5,IF(BV2="Less than 50%",0,IF(BV2="Negative",-10,IF(BV2="Less than 50% and Borrowings are increasing",-5,0))))) | BX2: Less than 0.7 | BY2: =IF(BX2="More than 1.2",-10,IF(BX2="Between 0.7 to 1.2",0,IF(BX2="Less than 0.7",10,0))) | BZ2: No | CA2: =IF(BZ2="Yes",-10,0) | CB2: Less than 15% | CC2: =IF(CB2="More than 15%",-10,IF(CB2="Less than 15%",10,0)) | CD2: No | CE2: =IF(CD2="Yes, more than 10%",-10,IF(CD2="No",10,0))
A3: =IF(B3=0,"",RANK(B3,$B$2:$B$222,0)) | B3: =SUM(N3,Y3,AA3,AC3,AE3,AG3,AI3,AK3,AM3,AO3,AQ3,AS3,AU3,AW3,AY3,BA3,BC3,BE3,BG3,BI3,BK3,BM3,BO3,BQ3,BS3,BU3,BW3,BY3,CA3,CC3,CE3) | C3: TALBROAUTO | D3: Talbros Automotive Components Limited | E3: auto | F3: auto ancillaries | G3: smallcap | H3: 2686.41 | I3: 435.2 | J3: 3.92 | K3: 360775 | N3: =IF(M3="Underperforming",-5,IF(L3>=95,15,IF(L3>=90,10,IF(L3>=80,5,0)))) | O3: 68.5 | P3: 44.28 | Q3: 339.69 | R3: Near 52W High Breakout | S3: Nifty Auto | X3: Growing Industry | Y3: =IF(X3="Growing Industry",10,IF(X3="Cyclical in an Upturn",5,0)) | Z3: Too Many Players with High ROCE | AA3: =IF(Z3="Monopoly",10,IF(Z3="Oligopoly",5,IF(Z3="Duopoly that cooperate",10,IF(Z3="Duopoly that compete",5,IF(Z3="Too many players with High ROCE",5,0))))) | AB3: No | AC3: =IF(AB3="No",5,0) | AD3: Tailwind | AE3: =IF(AD3="Tailwind",10,0) | AF3: Structural (10 Years Consistency) | AG3: =IF(AF3="Structural (10 Years Consistency)",10,IF(AF3="Shallow Cyclical (2 to 3 years growth)",5,0)) | AH3: No | AI3: =IF(AH3="Yes due to Product Mix change or Operating Leverage",10,IF(AH3="Yes, these are peak margins",-5,IF(AH3="No",5,0))) | AJ3: Stable | AK3: =IF(AJ3="Stable",10,0) | AL3: Yes | AM3: =IF(AL3="Yes",10,0) | AN3: B2B | AO3: =IF(AN3="B2C",10,IF(AN3="B2B",5,0)) | AP3: Yes | AQ3: =IF(AP3="Yes",10,0) | AR3: Higher One Time, Lower Annuity | AS3: =IF(AR3="Fully Annuity",10,IF(AR3="Higher Annuity, Lower One Time",5,IF(AR3="Higher One Time, Lower Annuity",3,0))) | AT3: Good | AU3: =IF(AT3="Good",10,0) | AV3: Yes for more than 2 years | AW3: =IF(AV3="Yes for more than 2 years",10,IF(AV3="Yes only for next 1 to 2 years",5,0)) | AX3: Above 40 | AY3: =IF(AX3="Above 40",20,IF(AX3="20 to 40",10,IF(AX3="0 to 20",-5,0))) | AZ3: Between 50 to 75 | BA3: =IF(AZ3="Between 50 to 75",10,IF(AZ3="Above 75",0,0)) | BB3: Stage 2 | BC3: =IF(BB3="Stage 2",20,IF(BB3="Stage 1",0,IF(BB3="Stage 3",5,IF(BB3="Stage 4",-5,0)))) | BD3: Positive Trend | BE3: =IF(BD3="Positive Trend",20,IF(BD3="Negative Trend",-10,0)) | BF3: Uptrend | BG3: =IF(BF3="Uptrend",10,IF(BF3="Sideways",5,0)) | BH3: Uptrend | BI3: =IF(BH3="Uptrend",10,IF(BH3="Sideways",5,0)) | BJ3: Blue sky scenario | BK3: =IF(BJ3="Overhead supply in last 2 years in last 2 years",-5,IF(BJ3="Close to 52 week high or retracement",5,IF(BJ3="Blue sky scenario",10,IF(BJ3="Long term Downtrend",-10,0)))) | BL3: Yes | BM3: =IF(BL3="Yes",10,0) | BN3: More than 20% | BO3: =IF(BN3="More than 20%",10,IF(BN3="Between 12 to 20%",5,IF(BN3="Less than 12%",0,0))) | BP3: No | BQ3: =IF(BP3="No",10,0) | BR3: No | BS3: =IF(BR3="NO",5,0) | BT3: Less than 1.5 | BU3: =IF(BT3="Above 2",0,IF(BT3="Between 1.5 to 2",5,IF(BT3="Less than 1.5",10,0))) | BV3: Above 70% | BW3: =IF(BV3="Above 70%",10,IF(BV3="Between 50% to 70%",5,IF(BV3="Less than 50%",0,IF(BV3="Negative",-10,IF(BV3="Less than 50% and Borrowings are increasing",-5,0))))) | BX3: Less than 0.7 | BY3: =IF(BX3="More than 1.2",-10,IF(BX3="Between 0.7 to 1.2",0,IF(BX3="Less than 0.7",10,0))) | BZ3: No | CA3: =IF(BZ3="Yes",-10,0) | CB3: Less than 15% | CC3: =IF(CB3="More than 15%",-10,IF(CB3="Less than 15%",10,0)) | CD3: No | CE3: =IF(CD3="Yes, more than 10%",-10,IF(CD3="No",10,0))
A4: =IF(B4=0,"",RANK(B4,$B$2:$B$222,0)) | B4: =SUM(N4,Y4,AA4,AC4,AE4,AG4,AI4,AK4,AM4,AO4,AQ4,AS4,AU4,AW4,AY4,BA4,BC4,BE4,BG4,BI4,BK4,BM4,BO4,BQ4,BS4,BU4,BW4,BY4,CA4,CC4,CE4) | C4: UNIVPHOTO | D4: Universus Photo Imagings Ltd | E4: consumer discretionary | F4: photographic and allied products | G4: smallcap | H4: 672.12 | I4: 614 | J4: 3.18 | K4: 3110 | L4: 94 | M4: Outperforming | N4: =IF(M4="Underperforming",-5,IF(L4>=95,15,IF(L4>=90,10,IF(L4>=80,5,0)))) | O4: 74.62 | P4: 21.89 | Q4: 459.29 | R4: Volume Spike & Near 52W High Breakout | S4: Nifty 50 | T4: -8.12 | U4: 137.39 | V4: 158.36 | W4: 42.87 | X4: Growing Industry | Y4: =IF(X4="Growing Industry",10,IF(X4="Cyclical in an Upturn",5,0)) | Z4: Too Many Players with High ROCE | AA4: =IF(Z4="Monopoly",10,IF(Z4="Oligopoly",5,IF(Z4="Duopoly that cooperate",10,IF(Z4="Duopoly that compete",5,IF(Z4="Too many players with High ROCE",5,0))))) | AB4: No | AC4: =IF(AB4="No",5,0) | AD4: Tailwind | AE4: =IF(AD4="Tailwind",10,0) | AF4: Structural (10 Years Consistency) | AG4: =IF(AF4="Structural (10 Years Consistency)",10,IF(AF4="Shallow Cyclical (2 to 3 years growth)",5,0)) | AH4: No | AI4: =IF(AH4="Yes due to Product Mix change or Operating Leverage",10,IF(AH4="Yes, these are peak margins",-5,IF(AH4="No",5,0))) | AJ4: Stable | AK4: =IF(AJ4="Stable",10,0) | AL4: Yes | AM4: =IF(AL4="Yes",10,0) | AN4: B2B | AO4: =IF(AN4="B2C",10,IF(AN4="B2B",5,0)) | AP4: Yes | AQ4: =IF(AP4="Yes",10,0) | AR4: Higher One Time, Lower Annuity | AS4: =IF(AR4="Fully Annuity",10,IF(AR4="Higher Annuity, Lower One Time",5,IF(AR4="Higher One Time, Lower Annuity",3,0))) | AT4: Good | AU4: =IF(AT4="Good",10,0) | AV4: Yes for more than 2 years | AW4: =IF(AV4="Yes for more than 2 years",10,IF(AV4="Yes only for next 1 to 2 years",5,0)) | AX4: 20 to 40 | AY4: =IF(AX4="Above 40",20,IF(AX4="20 to 40",10,IF(AX4="0 to 20",-5,0))) | AZ4: Between 50 to 75 | BA4: =IF(AZ4="Between 50 to 75",10,IF(AZ4="Above 75",0,0)) | BB4: Stage 2 | BC4: =IF(BB4="Stage 2",20,IF(BB4="Stage 1",0,IF(BB4="Stage 3",5,IF(BB4="Stage 4",-5,0)))) | BD4: Positive Trend | BE4: =IF(BD4="Positive Trend",20,IF(BD4="Negative Trend",-10,0)) | BF4: Uptrend | BG4: =IF(BF4="Uptrend",10,IF(BF4="Sideways",5,0)) | BH4: Uptrend | BI4: =IF(BH4="Uptrend",10,IF(BH4="Sideways",5,0)) | BJ4: Blue sky scenario | BK4: =IF(BJ4="Overhead supply in last 2 years in last 2 years",-5,IF(BJ4="Close to 52 week high or retracement",5,IF(BJ4="Blue sky scenario",10,IF(BJ4="Long term Downtrend",-10,0)))) | BL4: Yes | BM4: =IF(BL4="Yes",10,0) | BN4: More than 20% | BO4: =IF(BN4="More than 20%",10,IF(BN4="Between 12 to 20%",5,IF(BN4="Less than 12%",0,0))) | BP4: No | BQ4: =IF(BP4="No",10,0) | BR4: No | BS4: =IF(BR4="NO",5,0) | BT4: Less than 1.5 | BU4: =IF(BT4="Above 2",0,IF(BT4="Between 1.5 to 2",5,IF(BT4="Less than 1.5",10,0))) | BV4: Above 70% | BW4: =IF(BV4="Above 70%",10,IF(BV4="Between 50% to 70%",5,IF(BV4="Less than 50%",0,IF(BV4="Negative",-10,IF(BV4="Less than 50% and Borrowings are increasing",-5,0))))) | BX4: Less than 0.7 | BY4: =IF(BX4="More than 1.2",-10,IF(BX4="Between 0.7 to 1.2",0,IF(BX4="Less than 0.7",10,0))) | BZ4: No | CA4: =IF(BZ4="Yes",-10,0) | CB4: Less than 15% | CC4: =IF(CB4="More than 15%",-10,IF(CB4="Less than 15%",10,0)) | CD4: No | CE4: =IF(CD4="Yes, more than 10%",-10,IF(CD4="No",10,0))
A5: =IF(B5=0,"",RANK(B5,$B$2:$B$222,0)) | B5: =SUM(N5,Y5,AA5,AC5,AE5,AG5,AI5,AK5,AM5,AO5,AQ5,AS5,AU5,AW5,AY5,BA5,BC5,BE5,BG5,BI5,BK5,BM5,BO5,BQ5,BS5,BU5,BW5,BY5,CA5,CC5,CE5) | C5: VISHNU | D5: Vishnu Chemicals Limited | E5: chemicals | F5: chemicals | G5: smallcap | H5: 4773.33 | I5: 709.1 | J5: 2.19 | K5: 87175 | L5: 37 | M5: Outperforming | N5: =IF(M5="Underperforming",-5,IF(L5>=95,15,IF(L5>=90,10,IF(L5>=80,5,0)))) | O5: 70.05 | P5: 44.89 | Q5: 576.23 | R5: Near 52W High Breakout | S5: Nifty 50 | T5: -8.12 | U5: 42.53 | V5: 55.12 | W5: 11.27 | X5: Growing Industry | Y5: =IF(X5="Growing Industry",10,IF(X5="Cyclical in an Upturn",5,0)) | Z5: Too Many Players with High ROCE | AA5: =IF(Z5="Monopoly",10,IF(Z5="Oligopoly",5,IF(Z5="Duopoly that cooperate",10,IF(Z5="Duopoly that compete",5,IF(Z5="Too many players with High ROCE",5,0))))) | AB5: No | AC5: =IF(AB5="No",5,0) | AD5: Tailwind | AE5: =IF(AD5="Tailwind",10,0) | AF5: Structural (10 Years Consistency) | AG5: =IF(AF5="Structural (10 Years Consistency)",10,IF(AF5="Shallow Cyclical (2 to 3 years growth)",5,0)) | AH5: No | AI5: =IF(AH5="Yes due to Product Mix change or Operating Leverage",10,IF(AH5="Yes, these are peak margins",-5,IF(AH5="No",5,0))) | AJ5: Stable | AK5: =IF(AJ5="Stable",10,0) | AL5: Yes | AM5: =IF(AL5="Yes",10,0) | AN5: B2B | AO5: =IF(AN5="B2C",10,IF(AN5="B2B",5,0)) | AP5: Yes | AQ5: =IF(AP5="Yes",10,0) | AR5: Higher One Time, Lower Annuity | AS5: =IF(AR5="Fully Annuity",10,IF(AR5="Higher Annuity, Lower One Time",5,IF(AR5="Higher One Time, Lower Annuity",3,0))) | AT5: Good | AU5: =IF(AT5="Good",10,0) | AV5: Yes for more than 2 years | AW5: =IF(AV5="Yes for more than 2 years",10,IF(AV5="Yes only for next 1 to 2 years",5,0)) | AX5: Above 40 | AY5: =IF(AX5="Above 40",20,IF(AX5="20 to 40",10,IF(AX5="0 to 20",-5,0))) | AZ5: Between 50 to 75 | BA5: =IF(AZ5="Between 50 to 75",10,IF(AZ5="Above 75",0,0)) | BB5: Stage 2 | BC5: =IF(BB5="Stage 2",20,IF(BB5="Stage 1",0,IF(BB5="Stage 3",5,IF(BB5="Stage 4",-5,0)))) | BD5: Positive Trend | BE5: =IF(BD5="Positive Trend",20,IF(BD5="Negative Trend",-10,0)) | BF5: Uptrend | BG5: =IF(BF5="Uptrend",10,IF(BF5="Sideways",5,0)) | BH5: Uptrend | BI5: =IF(BH5="Uptrend",10,IF(BH5="Sideways",5,0)) | BJ5: Blue sky scenario | BK5: =IF(BJ5="Overhead supply in last 2 years in last 2 years",-5,IF(BJ5="Close to 52 week high or retracement",5,IF(BJ5="Blue sky scenario",10,IF(BJ5="Long term Downtrend",-10,0)))) | BL5: Yes | BM5: =IF(BL5="Yes",10,0) | BN5: More than 20% | BO5: =IF(BN5="More than 20%",10,IF(BN5="Between 12 to 20%",5,IF(BN5="Less than 12%",0,0))) | BP5: No | BQ5: =IF(BP5="No",10,0) | BR5: No | BS5: =IF(BR5="NO",5,0) | BT5: Less than 1.5 | BU5: =IF(BT5="Above 2",0,IF(BT5="Between 1.5 to 2",5,IF(BT5="Less than 1.5",10,0))) | BV5: Above 70% | BW5: =IF(BV5="Above 70%",10,IF(BV5="Between 50% to 70%",5,IF(BV5="Less than 50%",0,IF(BV5="Negative",-10,IF(BV5="Less than 50% and Borrowings are increasing",-5,0))))) | BX5: Less than 0.7 | BY5: =IF(BX5="More than 1.2",-10,IF(BX5="Between 0.7 to 1.2",0,IF(BX5="Less than 0.7",10,0))) | BZ5: No | CA5: =IF(BZ5="Yes",-10,0) | CB5: Less than 15% | CC5: =IF(CB5="More than 15%",-10,IF(CB5="Less than 15%",10,0)) | CD5: No | CE5: =IF(CD5="Yes, more than 10%",-10,IF(CD5="No",10,0))
A6: =IF(B6=0,"",RANK(B6,$B$2:$B$222,0)) | B6: =SUM(N6,Y6,AA6,AC6,AE6,AG6,AI6,AK6,AM6,AO6,AQ6,AS6,AU6,AW6,AY6,BA6,BC6,BE6,BG6,BI6,BK6,BM6,BO6,BQ6,BS6,BU6,BW6,BY6,CA6,CC6,CE6) | C6: AUROPHARMA | D6: Aurobindo Pharma Limited | E6: healthcare | F6: pharmaceuticals - indian - bulk drugs & formln | G6: largecap | H6: 97238.86 | I6: 1690 | J6: 2.86 | K6: 758827 | L6: 38 | M6: Outperforming | N6: =IF(M6="Underperforming",-5,IF(L6>=95,15,IF(L6>=90,10,IF(L6>=80,5,0)))) | O6: 71.67 | P6: 41.56 | Q6: 1461.91 | R6: Near 52W High Breakout | S6: Nifty Pharma | T6: 17.16 | U6: 51 | V6: 28.89 | W6: 11.3 | X6: Growing Industry | Y6: =IF(X6="Growing Industry",10,IF(X6="Cyclical in an Upturn",5,0)) | Z6: Too Many Players with High ROCE | AA6: =IF(Z6="Monopoly",10,IF(Z6="Oligopoly",5,IF(Z6="Duopoly that cooperate",10,IF(Z6="Duopoly that compete",5,IF(Z6="Too many players with High ROCE",5,0))))) | AB6: Yes | AC6: =IF(AB6="No",5,0) | AD6: Tailwind | AE6: =IF(AD6="Tailwind",10,0) | AF6: Structural (10 Years Consistency) | AG6: =IF(AF6="Structural (10 Years Consistency)",10,IF(AF6="Shallow Cyclical (2 to 3 years growth)",5,0)) | AH6: No | AI6: =IF(AH6="Yes due to Product Mix change or Operating Leverage",10,IF(AH6="Yes, these are peak margins",-5,IF(AH6="No",5,0))) | AJ6: Stable | AK6: =IF(AJ6="Stable",10,0) | AL6: Yes | AM6: =IF(AL6="Yes",10,0) | AN6: B2B | AO6: =IF(AN6="B2C",10,IF(AN6="B2B",5,0)) | AP6: Yes | AQ6: =IF(AP6="Yes",10,0) | AR6: Higher Annuity, Lower One Time | AS6: =IF(AR6="Fully Annuity",10,IF(AR6="Higher Annuity, Lower One Time",5,IF(AR6="Higher One Time, Lower Annuity",3,0))) | AT6: Good | AU6: =IF(AT6="Good",10,0) | AV6: Yes for more than 2 years | AW6: =IF(AV6="Yes for more than 2 years",10,IF(AV6="Yes only for next 1 to 2 years",5,0)) | AX6: Above 40 | AY6: =IF(AX6="Above 40",20,IF(AX6="20 to 40",10,IF(AX6="0 to 20",-5,0))) | AZ6: Between 50 to 75 | BA6: =IF(AZ6="Between 50 to 75",10,IF(AZ6="Above 75",0,0)) | BB6: Stage 2 | BC6: =IF(BB6="Stage 2",20,IF(BB6="Stage 1",0,IF(BB6="Stage 3",5,IF(BB6="Stage 4",-5,0)))) | BD6: Positive Trend | BE6: =IF(BD6="Positive Trend",20,IF(BD6="Negative Trend",-10,0)) | BF6: Uptrend | BG6: =IF(BF6="Uptrend",10,IF(BF6="Sideways",5,0)) | BH6: Uptrend | BI6: =IF(BH6="Uptrend",10,IF(BH6="Sideways",5,0)) | BJ6: Blue sky scenario | BK6: =IF(BJ6="Overhead supply in last 2 years in last 2 years",-5,IF(BJ6="Close to 52 week high or retracement",5,IF(BJ6="Blue sky scenario",10,IF(BJ6="Long term Downtrend",-10,0)))) | BL6: Yes | BM6: =IF(BL6="Yes",10,0) | BN6: More than 20% | BO6: =IF(BN6="More than 20%",10,IF(BN6="Between 12 to 20%",5,IF(BN6="Less than 12%",0,0))) | BP6: No | BQ6: =IF(BP6="No",10,0) | BR6: No | BS6: =IF(BR6="NO",5,0) | BT6: Less than 1.5 | BU6: =IF(BT6="Above 2",0,IF(BT6="Between 1.5 to 2",5,IF(BT6="Less than 1.5",10,0))) | BV6: Above 70% | BW6: =IF(BV6="Above 70%",10,IF(BV6="Between 50% to 70%",5,IF(BV6="Less than 50%",0,IF(BV6="Negative",-10,IF(BV6="Less than 50% and Borrowings are increasing",-5,0))))) | BX6: Less than 0.7 | BY6: =IF(BX6="More than 1.2",-10,IF(BX6="Between 0.7 to 1.2",0,IF(BX6="Less than 0.7",10,0))) | BZ6: No | CA6: =IF(BZ6="Yes",-10,0) | CB6: Less than 15% | CC6: =IF(CB6="More than 15%",-10,IF(CB6="Less than 15%",10,0)) | CD6: No | CE6: =IF(CD6="Yes, more than 10%",-10,IF(CD6="No",10,0))
A7: =IF(B7=0,"",RANK(B7,$B$2:$B$222,0)) | B7: =SUM(N7,Y7,AA7,AC7,AE7,AG7,AI7,AK7,AM7,AO7,AQ7,AS7,AU7,AW7,AY7,BA7,BC7,BE7,BG7,BI7,BK7,BM7,BO7,BQ7,BS7,BU7,BW7,BY7,CA7,CC7,CE7) | C7: IPCALAB | D7: Ipca Laboratories Limited | E7: healthcare | F7: pharmaceuticals - indian - bulk drugs & formln | G7: largecap | H7: 49987.34 | I7: 1970.3 | J7: 1 | K7: 555590 | L7: 39 | M7: Outperforming | N7: =IF(M7="Underperforming",-5,IF(L7>=95,15,IF(L7>=90,10,IF(L7>=80,5,0)))) | O7: 69.59 | P7: 44.28 | Q7: 1612.69 | R7: Near 52W High Breakout | S7: Nifty Pharma | T7: 17.16 | U7: 37.21 | V7: 17.11 | W7: 11.86 | X7: Growing Industry | Y7: =IF(X7="Growing Industry",10,IF(X7="Cyclical in an Upturn",5,0)) | Z7: Too Many Players with High ROCE | AA7: =IF(Z7="Monopoly",10,IF(Z7="Oligopoly",5,IF(Z7="Duopoly that cooperate",10,IF(Z7="Duopoly that compete",5,IF(Z7="Too many players with High ROCE",5,0))))) | AB7: Yes | AC7: =IF(AB7="No",5,0) | AD7: Tailwind | AE7: =IF(AD7="Tailwind",10,0) | AF7: Structural (10 Years Consistency) | AG7: =IF(AF7="Structural (10 Years Consistency)",10,IF(AF7="Shallow Cyclical (2 to 3 years growth)",5,0)) | AH7: No | AI7: =IF(AH7="Yes due to Product Mix change or Operating Leverage",10,IF(AH7="Yes, these are peak margins",-5,IF(AH7="No",5,0))) | AJ7: Stable | AK7: =IF(AJ7="Stable",10,0) | AL7: Yes | AM7: =IF(AL7="Yes",10,0) | AN7: B2B | AO7: =IF(AN7="B2C",10,IF(AN7="B2B",5,0)) | AP7: Yes | AQ7: =IF(AP7="Yes",10,0) | AR7: Higher Annuity, Lower One Time | AS7: =IF(AR7="Fully Annuity",10,IF(AR7="Higher Annuity, Lower One Time",5,IF(AR7="Higher One Time, Lower Annuity",3,0))) | AT7: Good | AU7: =IF(AT7="Good",10,0) | AV7: Yes for more than 2 years | AW7: =IF(AV7="Yes for more than 2 years",10,IF(AV7="Yes only for next 1 to 2 years",5,0)) | AX7: Above 40 | AY7: =IF(AX7="Above 40",20,IF(AX7="20 to 40",10,IF(AX7="0 to 20",-5,0))) | AZ7: Between 50 to 75 | BA7: =IF(AZ7="Between 50 to 75",10,IF(AZ7="Above 75",0,0)) | BB7: Stage 2 | BC7: =IF(BB7="Stage 2",20,IF(BB7="Stage 1",0,IF(BB7="Stage 3",5,IF(BB7="Stage 4",-5,0)))) | BD7: Positive Trend | BE7: =IF(BD7="Positive Trend",20,IF(BD7="Negative Trend",-10,0)) | BF7: Uptrend | BG7: =IF(BF7="Uptrend",10,IF(BF7="Sideways",5,0)) | BH7: Uptrend | BI7: =IF(BH7="Uptrend",10,IF(BH7="Sideways",5,0)) | BJ7: Blue sky scenario | BK7: =IF(BJ7="Overhead supply in last 2 years in last 2 years",-5,IF(BJ7="Close to 52 week high or retracement",5,IF(BJ7="Blue sky scenario",10,IF(BJ7="Long term Downtrend",-10,0)))) | BL7: Yes | BM7: =IF(BL7="Yes",10,0) | BN7: More than 20% | BO7: =IF(BN7="More than 20%",10,IF(BN7="Between 12 to 20%",5,IF(BN7="Less than 12%",0,0))) | BP7: No | BQ7: =IF(BP7="No",10,0) | BR7: No | BS7: =IF(BR7="NO",5,0) | BT7: Less than 1.5 | BU7: =IF(BT7="Above 2",0,IF(BT7="Between 1.5 to 2",5,IF(BT7="Less than 1.5",10,0))) | BV7: Above 70% | BW7: =IF(BV7="Above 70%",10,IF(BV7="Between 50% to 70%",5,IF(BV7="Less than 50%",0,IF(BV7="Negative",-10,IF(BV7="Less than 50% and Borrowings are increasing",-5,0))))) | BX7: Less than 0.7 | BY7: =IF(BX7="More than 1.2",-10,IF(BX7="Between 0.7 to 1.2",0,IF(BX7="Less than 0.7",10,0))) | BZ7: No | CA7: =IF(BZ7="Yes",-10,0) | CB7: Less than 15% | CC7: =IF(CB7="More than 15%",-10,IF(CB7="Less than 15%",10,0)) | CD7: No | CE7: =IF(CD7="Yes, more than 10%",-10,IF(CD7="No",10,0))
A8: =IF(B8=0,"",RANK(B8,$B$2:$B$222,0)) | B8: =SUM(N8,Y8,AA8,AC8,AE8,AG8,AI8,AK8,AM8,AO8,AQ8,AS8,AU8,AW8,AY8,BA8,BC8,BE8,BG8,BI8,BK8,BM8,BO8,BQ8,BS8,BU8,BW8,BY8,CA8,CC8,CE8) | C8: SYRMA | D8: Syrma SGS Technology Ltd | E8: consumer discretionary | F8: electronics - components | G8: largecap | H8: 31194.19 | I8: 1617.7 | J8: 7.05 | K8: 9182371 | L8: 69 | M8: Outperforming | N8: =IF(M8="Underperforming",-5,IF(L8>=95,15,IF(L8>=90,10,IF(L8>=80,5,0)))) | O8: 73.34 | P8: 58.62 | Q8: 1249.4 | R8: Volume Spike & Near 52W High Breakout | S8: Nifty 50 | T8: -8.12 | U8: 95.68 | V8: 112.97 | W8: 21.71 | X8: Growing Industry | Y8: =IF(X8="Growing Industry",10,IF(X8="Cyclical in an Upturn",5,0)) | Z8: Too Many Players with High ROCE | AA8: =IF(Z8="Monopoly",10,IF(Z8="Oligopoly",5,IF(Z8="Duopoly that cooperate",10,IF(Z8="Duopoly that compete",5,IF(Z8="Too many players with High ROCE",5,0))))) | AB8: No | AC8: =IF(AB8="No",5,0) | AD8: Tailwind | AE8: =IF(AD8="Tailwind",10,0) | AF8: Structural (10 Years Consistency) | AG8: =IF(AF8="Structural (10 Years Consistency)",10,IF(AF8="Shallow Cyclical (2 to 3 years growth)",5,0)) | AH8: No | AI8: =IF(AH8="Yes due to Product Mix change or Operating Leverage",10,IF(AH8="Yes, these are peak margins",-5,IF(AH8="No",5,0))) | AJ8: Stable | AK8: =IF(AJ8="Stable",10,0) | AL8: Yes | AM8: =IF(AL8="Yes",10,0) | AN8: B2B | AO8: =IF(AN8="B2C",10,IF(AN8="B2B",5,0)) | AP8: Yes | AQ8: =IF(AP8="Yes",10,0) | AR8: Higher One Time, Lower Annuity | AS8: =IF(AR8="Fully Annuity",10,IF(AR8="Higher Annuity, Lower One Time",5,IF(AR8="Higher One Time, Lower Annuity",3,0))) | AT8: Good | AU8: =IF(AT8="Good",10,0) | AV8: Yes for more than 2 years | AW8: =IF(AV8="Yes for more than 2 years",10,IF(AV8="Yes only for next 1 to 2 years",5,0)) | AX8: Above 40 | AY8: =IF(AX8="Above 40",20,IF(AX8="20 to 40",10,IF(AX8="0 to 20",-5,0))) | AZ8: Between 50 to 75 | BA8: =IF(AZ8="Between 50 to 75",10,IF(AZ8="Above 75",0,0)) | BB8: Stage 2 | BC8: =IF(BB8="Stage 2",20,IF(BB8="Stage 1",0,IF(BB8="Stage 3",5,IF(BB8="Stage 4",-5,0)))) | BD8: Positive Trend | BE8: =IF(BD8="Positive Trend",20,IF(BD8="Negative Trend",-10,0)) | BF8: Uptrend | BG8: =IF(BF8="Uptrend",10,IF(BF8="Sideways",5,0)) | BH8: Uptrend | BI8: =IF(BH8="Uptrend",10,IF(BH8="Sideways",5,0)) | BJ8: Blue sky scenario | BK8: =IF(BJ8="Overhead supply in last 2 years in last 2 years",-5,IF(BJ8="Close to 52 week high or retracement",5,IF(BJ8="Blue sky scenario",10,IF(BJ8="Long term Downtrend",-10,0)))) | BL8: Yes | BM8: =IF(BL8="Yes",10,0) | BN8: More than 20% | BO8: =IF(BN8="More than 20%",10,IF(BN8="Between 12 to 20%",5,IF(BN8="Less than 12%",0,0))) | BP8: No | BQ8: =IF(BP8="No",10,0) | BR8: Yes | BS8: =IF(BR8="NO",5,0) | BT8: Less than 1.5 | BU8: =IF(BT8="Above 2",0,IF(BT8="Between 1.5 to 2",5,IF(BT8="Less than 1.5",10,0))) | BV8: Above 70% | BW8: =IF(BV8="Above 70%",10,IF(BV8="Between 50% to 70%",5,IF(BV8="Less than 50%",0,IF(BV8="Negative",-10,IF(BV8="Less than 50% and Borrowings are increasing",-5,0))))) | BX8: Less than 0.7 | BY8: =IF(BX8="More than 1.2",-10,IF(BX8="Between 0.7 to 1.2",0,IF(BX8="Less than 0.7",10,0))) | BZ8: No | CA8: =IF(BZ8="Yes",-10,0) | CB8: Less than 15% | CC8: =IF(CB8="More than 15%",-10,IF(CB8="Less than 15%",10,0)) | CD8: No | CE8: =IF(CD8="Yes, more than 10%",-10,IF(CD8="No",10,0))
A9: =IF(B9=0,"",RANK(B9,$B$2:$B$222,0)) | B9: =SUM(N9,Y9,AA9,AC9,AE9,AG9,AI9,AK9,AM9,AO9,AQ9,AS9,AU9,AW9,AY9,BA9,BC9,BE9,BG9,BI9,BK9,BM9,BO9,BQ9,BS9,BU9,BW9,BY9,CA9,CC9,CE9) | C9: TBZ | D9: Tribhovandas Bhimji Zaveri Limited | E9: consumer discretionary | F9: diamond cutting / jewellery | G9: smallcap | H9: 3836.01 | I9: 574.85 | J9: 5 | K9: 268358 | L9: 99 | M9: Outperforming | N9: =IF(M9="Underperforming",-5,IF(L9>=95,15,IF(L9>=90,10,IF(L9>=80,5,0)))) | O9: 91.15 | P9: 56.37 | Q9: 435.53 | R9: Near 52W High Breakout | S9: Nifty 50 | T9: -8.12 | U9: 207.85 | V9: 235.06 | W9: 85 | X9: Growing Industry | Y9: =IF(X9="Growing Industry",10,IF(X9="Cyclical in an Upturn",5,0)) | Z9: Too Many Players with High ROCE | AA9: =IF(Z9="Monopoly",10,IF(Z9="Oligopoly",5,IF(Z9="Duopoly that cooperate",10,IF(Z9="Duopoly that compete",5,IF(Z9="Too many players with High ROCE",5,0))))) | AB9: No | AC9: =IF(AB9="No",5,0) | AD9: Tailwind | AE9: =IF(AD9="Tailwind",10,0) | AF9: Structural (10 Years Consistency) | AG9: =IF(AF9="Structural (10 Years Consistency)",10,IF(AF9="Shallow Cyclical (2 to 3 years growth)",5,0)) | AH9: No | AI9: =IF(AH9="Yes due to Product Mix change or Operating Leverage",10,IF(AH9="Yes, these are peak margins",-5,IF(AH9="No",5,0))) | AJ9: Stable | AK9: =IF(AJ9="Stable",10,0) | AL9: Yes | AM9: =IF(AL9="Yes",10,0) | AN9: B2B | AO9: =IF(AN9="B2C",10,IF(AN9="B2B",5,0)) | AP9: Yes | AQ9: =IF(AP9="Yes",10,0) | AR9: Higher One Time, Lower Annuity | AS9: =IF(AR9="Fully Annuity",10,IF(AR9="Higher Annuity, Lower One Time",5,IF(AR9="Higher One Time, Lower Annuity",3,0))) | AT9: Good | AU9: =IF(AT9="Good",10,0) | AV9: Yes for more than 2 years | AW9: =IF(AV9="Yes for more than 2 years",10,IF(AV9="Yes only for next 1 to 2 years",5,0)) | AX9: Above 40 | AY9: =IF(AX9="Above 40",20,IF(AX9="20 to 40",10,IF(AX9="0 to 20",-5,0))) | AZ9: Above 75 | BA9: =IF(AZ9="Between 50 to 75",10,IF(AZ9="Above 75",0,0)) | BB9: Stage 2 | BC9: =IF(BB9="Stage 2",20,IF(BB9="Stage 1",0,IF(BB9="Stage 3",5,IF(BB9="Stage 4",-5,0)))) | BD9: Positive Trend | BE9: =IF(BD9="Positive Trend",20,IF(BD9="Negative Trend",-10,0)) | BF9: Uptrend | BG9: =IF(BF9="Uptrend",10,IF(BF9="Sideways",5,0)) | BH9: Uptrend | BI9: =IF(BH9="Uptrend",10,IF(BH9="Sideways",5,0)) | BJ9: Blue sky scenario | BK9: =IF(BJ9="Overhead supply in last 2 years in last 2 years",-5,IF(BJ9="Close to 52 week high or retracement",5,IF(BJ9="Blue sky scenario",10,IF(BJ9="Long term Downtrend",-10,0)))) | BL9: Yes | BM9: =IF(BL9="Yes",10,0) | BN9: More than 20% | BO9: =IF(BN9="More than 20%",10,IF(BN9="Between 12 to 20%",5,IF(BN9="Less than 12%",0,0))) | BP9: No | BQ9: =IF(BP9="No",10,0) | BR9: No | BS9: =IF(BR9="NO",5,0) | BT9: Less than 1.5 | BU9: =IF(BT9="Above 2",0,IF(BT9="Between 1.5 to 2",5,IF(BT9="Less than 1.5",10,0))) | BV9: Above 70% | BW9: =IF(BV9="Above 70%",10,IF(BV9="Between 50% to 70%",5,IF(BV9="Less than 50%",0,IF(BV9="Negative",-10,IF(BV9="Less than 50% and Borrowings are increasing",-5,0))))) | BX9: Between 0.7 to 1.2 | BY9: =IF(BX9="More than 1.2",-10,IF(BX9="Between 0.7 to 1.2",0,IF(BX9="Less than 0.7",10,0))) | BZ9: No | CA9: =IF(BZ9="Yes",-10,0) | CB9: Less than 15% | CC9: =IF(CB9="More than 15%",-10,IF(CB9="Less than 15%",10,0)) | CD9: No | CE9: =IF(CD9="Yes, more than 10%",-10,IF(CD9="No",10,0))
A10: =IF(B10=0,"",RANK(B10,$B$2:$B$222,0)) | B10: =SUM(N10,Y10,AA10,AC10,AE10,AG10,AI10,AK10,AM10,AO10,AQ10,AS10,AU10,AW10,AY10,BA10,BC10,BE10,BG10,BI10,BK10,BM10,BO10,BQ10,BS10,BU10,BW10,BY10,CA10,CC10,CE10) | C10: BHAGYANGR | D10: Bhagyanagar India | E10: power & utilities | F10: power generation and supply | G10: smallcap | H10: 1495.62 | I10: 446.5 | J10: 5 | K10: 66357 | L10: 95 | M10: Outperforming | N10: =IF(M10="Underperforming",-5,IF(L10>=95,15,IF(L10>=90,10,IF(L10>=80,5,0)))) | O10: 70.94 | P10: 66.44 | Q10: 318.78 | R10: Near 52W High Breakout | S10: Nifty IT | T10: -20.29 | U10: 381.09 | V10: 503.57 | W10: 49.89 | X10: Growing Industry | Y10: =IF(X10="Growing Industry",10,IF(X10="Cyclical in an Upturn",5,0)) | Z10: Too Many Players with High ROCE | AA10: =IF(Z10="Monopoly",10,IF(Z10="Oligopoly",5,IF(Z10="Duopoly that cooperate",10,IF(Z10="Duopoly that compete",5,IF(Z10="Too many players with High ROCE",5,0))))) | AB10: No | AC10: =IF(AB10="No",5,0) | AD10: Tailwind | AE10: =IF(AD10="Tailwind",10,0) | AF10: Structural (10 Years Consistency) | AG10: =IF(AF10="Structural (10 Years Consistency)",10,IF(AF10="Shallow Cyclical (2 to 3 years growth)",5,0)) | AH10: No | AI10: =IF(AH10="Yes due to Product Mix change or Operating Leverage",10,IF(AH10="Yes, these are peak margins",-5,IF(AH10="No",5,0))) | AJ10: Stable | AK10: =IF(AJ10="Stable",10,0) | AL10: Yes | AM10: =IF(AL10="Yes",10,0) | AN10: B2B | AO10: =IF(AN10="B2C",10,IF(AN10="B2B",5,0)) | AP10: Yes | AQ10: =IF(AP10="Yes",10,0) | AR10: Higher One Time, Lower Annuity | AS10: =IF(AR10="Fully Annuity",10,IF(AR10="Higher Annuity, Lower One Time",5,IF(AR10="Higher One Time, Lower Annuity",3,0))) | AT10: Good | AU10: =IF(AT10="Good",10,0) | AV10: Yes for more than 2 years | AW10: =IF(AV10="Yes for more than 2 years",10,IF(AV10="Yes only for next 1 to 2 years",5,0)) | AX10: Above 40 | AY10: =IF(AX10="Above 40",20,IF(AX10="20 to 40",10,IF(AX10="0 to 20",-5,0))) | AZ10: Between 50 to 75 | BA10: =IF(AZ10="Between 50 to 75",10,IF(AZ10="Above 75",0,0)) | BB10: Stage 2 | BC10: =IF(BB10="Stage 2",20,IF(BB10="Stage 1",0,IF(BB10="Stage 3",5,IF(BB10="Stage 4",-5,0)))) | BD10: Positive Trend | BE10: =IF(BD10="Positive Trend",20,IF(BD10="Negative Trend",-10,0)) | BF10: Uptrend | BG10: =IF(BF10="Uptrend",10,IF(BF10="Sideways",5,0)) | BH10: Uptrend | BI10: =IF(BH10="Uptrend",10,IF(BH10="Sideways",5,0)) | BJ10: Blue sky scenario | BK10: =IF(BJ10="Overhead supply in last 2 years in last 2 years",-5,IF(BJ10="Close to 52 week high or retracement",5,IF(BJ10="Blue sky scenario",10,IF(BJ10="Long term Downtrend",-10,0)))) | BL10: Yes | BM10: =IF(BL10="Yes",10,0) | BN10: More than 20% | BO10: =IF(BN10="More than 20%",10,IF(BN10="Between 12 to 20%",5,IF(BN10="Less than 12%",0,0))) | BP10: No | BQ10: =IF(BP10="No",10,0) | BR10: No | BS10: =IF(BR10="NO",5,0) | BT10: Above 2 | BU10: =IF(BT10="Above 2",0,IF(BT10="Between 1.5 to 2",5,IF(BT10="Less than 1.5",10,0))) | BV10: Above 70% | BW10: =IF(BV10="Above 70%",10,IF(BV10="Between 50% to 70%",5,IF(BV10="Less than 50%",0,IF(BV10="Negative",-10,IF(BV10="Less than 50% and Borrowings are increasing",-5,0))))) | BX10: Between 0.7 to 1.2 | BY10: =IF(BX10="More than 1.2",-10,IF(BX10="Between 0.7 to 1.2",0,IF(BX10="Less than 0.7",10,0))) | BZ10: No | CA10: =IF(BZ10="Yes",-10,0) | CB10: Less than 15% | CC10: =IF(CB10="More than 15%",-10,IF(CB10="Less than 15%",10,0)) | CD10: No | CE10: =IF(CD10="Yes, more than 10%",-10,IF(CD10="No",10,0))
