Workbook

Sheet Read Me
A1: 🏆 MONIT MULTIBAGGER RESEARCH ENGINE & SCANNER
A2: Daily Analytics Report | Generated: Wednesday, 16 September 2026
A5: 📖 QUICK REFERENCE RUNBOOK & SYSTEM FLOW
A6: Step 1: Reference this Read Me | B6: Understand terms, formulas, and underlying investment theses directly in this glossary dashboard.
A7: Step 2: Check Leaderboard Tab | B7: Locate long-term compounders with high Persistence Scores and streaks (institutional accumulation footprint).
A8: Step 3: Analyze Confluence Overlap | B8: Review the ultimate high-conviction candidates intersecting our scanner signals and StockScans overlaps.
A9: Step 4: Scoring Monit Tabs | B9: Open 'Monit Non Financial' or 'Monit Banks NBFC' to fill out your qualitative checks (Tailwinds, Promoters, Triggers).
A10: Step 5: Track Scan Matches | B10: Confirm consensus using 'Scan Match' tabs which score companies by total appearances across allStockScans.
A13: 📊 RESEARCH ENGINE GLOSSARY, METRICS & THESES
A15: Metric Term / Tab Name | B15: Practical Meaning & Underlying Investment Thesis | C15: Automated DB Query / Logic & Excel Formula
A16: EMA Crossover (Birth of a Trend) | B16: An entry signal triggered when price crosses above its 200-day EMA. [THESIS]: Represents the birth of a new long-term uptrend. Buying here provides maximum asymmetrical risk-to-reward because the entry is close to the logical stop-loss (the EMA itself). | C16: pine_signal == 'EMA Crossover' Sized at 7% capital allocation (~₹70,000 per position).
A17: 52W Breakout (Momentum Confirmation) | B17: A momentum signal triggered when a stock above its 200-day EMA breaks out to fresh 52-week highs. [THESIS]: Represents a confirmed breakout where institutional buying pressure clears all historical supply. High momentum outperformance. | C17: pine_signal == '52W Breakout' Sized at 5% capital allocation (~₹50,000 per position).
A18: ATH Momentum (Runaway Leader) | B18: An established trend signal triggered when the price is actively running near its All-Time Highs. [THESIS]: Identifies the strongest runaway leaders in the market. Ideal for high-velocity momentum trading where price experiences immediate continuation. | C18: pine_signal == 'ATH Momentum' Sized at 4% capital allocation (~₹40,000 per position).
A19: Persistence Score (30D) (Accumulation Footprint) | B19: The count of times a stock has appeared in the daily screener during the last 30 active trading days. [THESIS]: Represents persistent institutional buying. Random spikes appear 1-2 times, but compounders appear 10+ times as institutions accumulate. | C19: Queries the local SQLite database (`logs/backtest.db`) to sum the total number of distinct dates the ticker appeared on the screener during the last 30 active trading days. Formula: COUNT(DISTINCT date)
A20: Consecutive Streak Days (Uninterrupted Trend) | B20: The number of consecutive trading days that the stock has appeared in the screener up to today. [THESIS]: High streaks indicate an exceptionally strong, uninterrupted runaway trend with heavy daily buying pressure. | C20: Checks the chronological sequence of scanner dates in SQLite starting from the most recent run date and counting backward. The streak increments for every contiguous date the ticker appears.
A21: Sector Velocity WoW (Early Sector Rotation) | B21: Compares the volume of screener signals in a sector over the last 5 trading days (W1) against the previous 5 trading days (W2). [THESIS]: Detects early sector rotation. A sudden positive surge warns you of capital flowing aggressively into a specific theme. | C21: Counts appearances of all tickers categorized by their sector. Formula: W1_Count = COUNT(records WHERE date IN last 5 trading days) W2_Count = COUNT(records WHERE date IN days -10 to -5) Velocity % = ((W1_Count - W2_Count) / W2_Count) * 100
A22: Emerging Leaders (Momentum Expansion) | B22: Identifies breakout stocks experiencing a sudden momentum expansion. [THESIS]: Finds stocks with a high concentration of appearances recently but almost zero history in the preceding months. Represents new institutional entries. | C22: Finds stocks with at least 5 appearances in the last 10 trading days, but less than or equal to 3 appearances in the prior 50 trading days (i.e. trading days -60 to -10). Formula: COUNT(recent) >= 5 AND COUNT(historical) <= 3
A23: Tab: Confluence Overlap (The Ultimate Overlap) | B23: This sheet displays the absolute highest conviction watchlist candidates intersecting multiple strategies. [THESIS]: Filters out market noise by only displaying stocks appearing in at least two out of three major momentum dimensions: (1) Chartink screener universe, (2) Active scanner signals, and (3) StockScans overlap list. | C23: Calculates the mathematical intersection of the three sets: In_Universe + In_Scanner + In_StockScans >= 2 Single-dimension matches are automatically filtered out to eliminate market noise.
A24: Tab: Monit Non Financial (CHECKLIST SHEET) | B24: Your main watchlist scoring sheet for non-financial companies. [THESIS]: Keeps watchlist scoring fully formula-driven using Excel formulas. It combines automated metrics (RSI, ADX, V-stop, Persistence) with your qualitative scores (Promoter Buying, Near-Term Trigger, Headwind/Tailwind). | C24: Uses relative index-matching formulas to populate automated close prices, RSI, ADX, V-stop, and Persistence from the SQLite and Chartink universe sheets. Formula: INDEX-MATCH left-lookup.
A25: Tab: Monit Banks NBFC (BANKING CHECKLIST) | B25: Your main watchlist scoring sheet for banking and NBFC companies. [THESIS]: Tailored specifically for banking structures, incorporating specialized metrics like Net Interest Margins (NIM) and Credit Costs alongside technical indicators. | C25: Features banking-specific checklist criteria to ensure qualitative analyst inputs align with bank metrics.
A26: Tab: Scan Match tabs (StockScans Confluence) | B26: Displays the top 100 stocks appearing across all StockScans screeners. [THESIS]: Scores stocks qualitatively by scan volume. Stocks appearing in >20 scans receive a premium 10-point bonus, proving market-wide momentum consensus. | C26: Applies a nested Excel IF formula: `=IF(D8>20,10,IF(D8>=10,5,2))` Scores: >20 scans = 10 pts; 10-20 scans = 5 pts; <10 scans = 2 pts.
... A36: Weekly Tracking Highlighting (Additions / Removals) | B36: Visual highlights indicating weekly changes in the StockScans 100 (Scan Match) list. [THESIS]: Helps track the weekly turnover. Newly added candidates indicate fresh institutional attention, while removed candidates represent names losing relative strength. | C36: Compares daily lists against Monday's baseline database: - Added stocks: Highlighted in Soft Blue. - Removed stocks: Listed in the bottom section of Scan Match sheets.

Sheet Leaderboard
A1: 🌟 MULTIBAGGER MOMENTUM & SECTOR ROTATION LEADERBOARD 🌟
A4: TOP PERSISTENT MOMENTUM LEADERS (30D) | J4: SECTOR MOMENTUM VELOCITY HEATMAP (WoW)
A5: Rank | B5: Score | C5: Symbol | D5: Company Name | E5: Sector | F5: Streak (Days) | G5: Market Cap Cr | H5: Classification | J5: Sector Name | K5: Current Wk Count | L5: Previous Wk Count | M5: Velocity WoW %
A6: 1 | B6: 426 | C6: CYIENTDLM | D6: Cyient DLM Ltd | E6: aerospace & defence | F6: 56 | G6: 7007.17 | H6: Potential Leader | J6: telecom-service | K6: 9 | L6: 7 | M6: 28.6%
A7: 2 | B7: 420 | C7: SETL | D7: Standard Enginnering Technology Ltd | E7: industrials | F7: 55 | G7: 8872.39 | H7: Potential Leader | J7: services | K7: 40 | L7: 40 | M7: 0.0%
A8: 3 | B8: 378 | C8: SUNDRMFAST | D8: Sundram Fasteners Limited | E8: auto | F8: 48 | G8: 25999.18 | H8: Potential Leader | J8: power & utilities | K8: 9 | L8: 10 | M8: -10.0%
A9: 4 | B9: 354 | C9: KABRAEXTRU | D9: Kabra Extrusion Technik Limited | E9: industrials | F9: 44 | G9: 2276.21 | H9: Potential Leader | J9: aerospace & defence | K9: 54 | L9: 66 | M9: -18.2%
A10: 5 | B10: 342 | C10: DIVISLAB | D10: Divi's Laboratories Limited | E10: healthcare | F10: 42 | G10: 244178 | H10: Potential Leader | J10: healthcare | K10: 211 | L10: 269 | M10: -21.6%
A11: 6 | B11: 342 | C11: MENONBE | D11: Menon Bearings Limited | E11: auto | F11: 42 | G11: 1705.58 | H11: Potential Leader | J11: realty | K11: 77 | L11: 100 | M11: -23.0%
A12: 7 | B12: 342 | C12: TFCILTD | D12: Tourism Finance Corporation Of India Limited | E12: financials | F12: 42 | G12: 6397.42 | H12: Potential Leader | J12: auto | K12: 78 | L12: 102 | M12: -23.5%
A13: 8 | B13: 342 | C13: VSSL | D13: Vardhman Special Steels Limited | E13: metals & mining | F13: 42 | G13: 3762.04 | H13: Potential Leader | J13: co-working | K13: 6 | L13: 8 | M13: -25.0%
A14: 9 | B14: 330 | C14: WSTCSTPAPR | D14: West Coast Paper Mills Limited | E14: building materials | F14: 40 | G14: 4711.27 | H14: Potential Leader | J14: transportation | K14: 34 | L14: 46 | M14: -26.1%
A15: 10 | B15: 318 | C15: PAYTM | D15: One 97 Communications Ltd | E15: i.t | F15: 38 | G15: 110778.3 | H15: Potential Leader | J15: energy | K15: 56 | L15: 76 | M15: -26.3%
A16: 11 | B16: 312 | C16: DEEPINDS | D16: Deep Industries Ltd | E16: energy | F16: 37 | G16: 4674.56 | H16: Potential Leader | J16: industrials | K16: 193 | L16: 269 | M16: -28.3%
A17: 12 | B17: 312 | C17: REDINGTON | D17: Redington (india) Limited | E17: services | F17: 37 | G17: 29625.34 | H17: Potential Leader | J17: miscellaneous | K17: 31 | L17: 46 | M17: -32.6%
... A20: 15 | B20: 294 | C20: BIRLACABLE | D20: Birla Cable Limited | E20: industrials | F20: 34 | G20: 1133.85 | H20: Potential Leader | J20: metals & mining | K20: 94 | L20: 142 | M20: -33.8%
A21: 16 | B21: 294 | C21: MMP | D21: MMP Industries Ltd | E21: metals & mining | F21: 34 | G21: 866 | H21: Potential Leader
A22: 17 | B22: 288 | C22: DOLPHIN | D22: Dolphin Offshore Enterprises (India) Ltd | E22: energy | F22: 33 | G22: 2604.5 | H22: Potential Leader
A23: 18 | B23: 288 | C23: PTCIL | D23: PTC Industries Ltd | E23: industrials | F23: 33 | G23: 33823.19 | H23: Potential Leader
A24: 19 | B24: 288 | C24: RATNAVEER | D24: Ratnaveer Precision Engineering Ltd | E24: metals & mining | F24: 33 | G24: 2068.52 | H24: Potential Leader
A25: 20 | B25: 288 | C25: SHILPAMED | D25: Shilpa Medicare Limited | E25: healthcare | F25: 33 | G25: 17835.11 | H25: Potential Leader
A28: 🌟 EMERGING LEADERS (MOMENTUM EXPANSION) | J28: 💎 SATELLITE HOLDINGS SHORTLIST (MCAP < 25K CR)
A29: Symbol | B29: Company Name | C29: Sector | D29: Recent Matches (10D) | E29: Historical Matches | F29: Market Cap Cr | J29: Symbol | K29: Sector | L29: Monit Score | M29: Market Cap Cr | N29: Appearances (30D)
A30: GMMPFAUDLR | B30: GMM Pfaudler Ltd | C30: industrials | D30: 10 | E30: 2 | F30: 6060.23 | J30: WELINV | K30: financials | L30: 295 | M30: 831.76 | N30: 21
A31: PRABHA | B31: Prabha Energy Ltd | C31: energy | D31: 10 | E31: 2 | F31: 3509.25 | J31: VISHNU | K31: chemicals | L31: 288 | M31: 4596.29 | N31: 23
A32: SHREEJISPG | B32: Shreeji Shipping Global Ltd | C32: transportation | D32: 10 | E32: 0 | F32: 11143.61 | J32: UNIVPHOTO | K32: consumer discretionary | L32: 288 | M32: 620.4 | N32: 14
A33: MVGJL | B33: Manoj Vaibhav Gems N Jewellers Ltd | C33: consumer discretionary | D33: 10 | E33: 0 | F33: 957.65 | J33: DCBBANK | K33: bank | L33: 285 | M33: 7146.58 | N33: 20
A34: UNITEDPOLY | B34: United Polyfab Gujarat Ltd | C34: textiles | D34: 9 | E34: 0 | F34: 981.18 | J34: WELSPUNLIV | K34: textiles | L34: 283 | M34: 19049.04 | N34: 24
A35: IONEXCHANG | B35: Ion Exchange (India) Ltd | C35: realty | D35: 9 | E35: 1 | F35: 6336 | J35: TBZ | K35: consumer discretionary | L35: 283 | M35: 3499.69 | N35: 23
A36: BLUESTONE | B36: Bluestone Jewellery and Lifestyle Ltd | C36: consumer discretionary | D36: 8 | E36: 1 | F36: 12627.25 | J36: PASUPTAC | K36: textiles | L36: 283 | M36: 628.21 | N36: 13
A37: SMSPHARMA | B37: SMS Pharmaceuticals Limited | C37: Healthcare | D37: 8 | E37: 2 | F37: 3773.71 | J37: TFCILTD | K37: financials | L37: 280 | M37: 6397.42 | N37: 30
A38: PCJEWELLER | B38: Pc Jeweller Limited | C38: consumer discretionary | D38: 8 | E38: 0 | F38: 12516.88 | J38: INNOVACAP | K38: healthcare | L38: 280 | M38: 6524.21 | N38: 25
A39: INDIQUBE | B39: Indiqube Spaces Ltd | C39: co-working | D39: 8 | E39: 0 | F39: 4227.87 | J39: PAISALO | K39: financials | L39: 280 | M39: 7682.73 | N39: 10
A40: WENDT | B40: Wendt (india) Limited | C40: industrials | D40: 8 | E40: 0 | F40: 1716 | J40: SHAREINDIA | K40: financials | L40: 280 | M40: 4315.24 | N40: 7
A41: SPLPETRO | B41: Supreme Petrochem Ltd | C41: energy | D41: 8 | E41: 0 | F41: 14843.04 | J41: ARIES | K41: chemicals | L41: 278 | M41: 615.5 | N41: 24
A45: 🚀 HIGH MOMENTUM LEADERS (RS RATING >= 90)
A46: Rank | B46: RS Rating | C46: O'Neil Score | D46: Monit Score | E46: Symbol | F46: Company Name | G46: Sector | H46: Market Cap Cr
A47: 1 | B47: 99 | C47: 79.17 | D47: 283 | E47: TBZ | F47: Tribhovandas Bhimji Zaveri Limited | G47: consumer discretionary | H47: 3499.69
A48: 2 | B48: 98 | C48: 65.19 | D48: 258 | E48: SIGMAADV | F48: Sigma Advanced System Ltd | G48: aerospace & defence | H48: 15058.31
A49: 3 | B49: 98 | C49: 63.73 | D49: 268 | E49: KABRAEXTRU | F49: Kabra Extrusion Technik Limited | G49: industrials | H49: 2276.21
...

Sheet Chartink Universe
A1: symbol | B1: company | C1: sector | D1: industry | E1: marketcap_bucket | F1: marketcap_cr | G1: close | H1: today_return_pct | I1: volume | J1: bse_code
A2: NPST | B2: Network People Services Technologies Ltd | C2: i.t | D2: computers - software - medium / small | E2: smallcap | F2: 3420.57 | G2: 1834.6 | H2: 11.9 | I2: 3028115 | J2: 535391
A3: ANTELOPUS | B3: Antelopus Selan Energy Ltd | C3: energy | D3: oil drilling / allied services | E3: smallcap | F3: 3719.47 | G3: 1170.95 | H3: 10.7 | I3: 4319113 | J3: 530075
A4: FOSECOIND | B4: Foseco India Limited | C4: chemicals | D4: chemicals | E4: smallcap | F4: 4690.81 | G4: 6846.5 | H4: 10.01 | I4: 178685 | J4: 500150
A5: IOLCP | B5: Iol Chemicals And Pharmaceuticals Limited | C5: healthcare | D5: pharmaceuticals - indian - bulk drugs & formln | E5: midcap | F5: 5269.41 | G5: 194.57 | H5: 8.38 | I5: 8624277 | J5: 524164
A6: EMUDHRA | B6: eMudhra Ltd | C6: i.t | D6: computers - software - medium / small | E6: smallcap | F6: 4909.49 | G6: 642.3 | H6: 8.34 | I6: 30254888 | J6: 543533
A7: ARROWGREEN | B7: Arrow Greentech Limited | C7: plastic products | D7: plastics products | E7: smallcap | F7: 1265.2 | G7: 907.45 | H7: 8.22 | I7: 311513 | J7: 516064
A8: KANPRPLA | B8: Kanpur Plastipack Ltd | C8: industrials | D8: packaging | E8: smallcap | F8: 602.18 | G8: 265.85 | H8: 8.07 | I8: 27577 | J8: 507779
A9: MOREPENLAB | B9: Morepen Laboratories Limited | C9: healthcare | D9: pharmaceuticals - indian - bulk drugs & formln | E9: midcap | F9: 5820.36 | G9: 114.73 | H9: 8.01 | I9: 39424210 | J9: 500288
A10: KRYSTAL | B10: Krystal Integrated Services Ltd | C10: miscellaneous | D10: miscellaneous | E10: smallcap | F10: 849.22 | G10: 655.6 | H10: 7.86 | I10: 174712 | J10: 544149
A11: MOTISONS | B11: Motisons Jewellers Ltd | C11: consumer discretionary | D11: diamond cutting / jewellery | E11: smallcap | F11: 1759.72 | G11: 16.62 | H11: 7.43 | I11: 93614476 | J11: 544053
A12: MATRIMONY | B12: Matrimony.com Ltd | C12: miscellaneous | D12: miscellaneous | E12: smallcap | F12: 1029.12 | G12: 533.4 | H12: 7.15 | I12: 40915 | J12: 540704
A13: RUBYMILLS | B13: The Ruby Mills Limited | C13: textiles | D13: textiles - composite | E13: smallcap | F13: 1445.95 | G13: 462.1 | H13: 6.87 | I13: 90742 | J13: 503169
... A35: INDORAMA | B35: Indo Rama Synthetics (india) Limited | C35: textiles | D35: textiles - manmade | E35: smallcap | F35: 2162.28 | G35: 85.6 | H35: 3.37 | I35: 3645127 | J35: 500207
A36: BLUESTONE | B36: Bluestone Jewellery and Lifestyle Ltd | C36: consumer discretionary | D36: diamond cutting / jewellery | E36: midcap | F36: 12627.25 | G36: 856 | H36: 3.31 | I36: 806703
A37: SSWL | B37: Steel Strips Wheels Limited | C37: auto | D37: auto ancillaries | E37: midcap | F37: 5328.42 | G37: 350.05 | H37: 3.26 | I37: 1772756 | J37: 513262
A38: GRAPHITE | B38: Graphite India Limited | C38: industrials | D38: electrodes - graphites | E38: midcap | F38: 15268.6 | G38: 805.05 | H38: 3.01 | I38: 3021853 | J38: 509488
A39: TATACOMM | B39: Tata Communications Limited | C39: telecom-service | D39: telecommunications - service provider | E39: largecap | F39: 49826.63 | G39: 1799.3 | H39: 2.92 | I39: 317034 | J39: 500483
A40: DICIND | B40: Dic India Limited | C40: chemicals | D40: chemicals | E40: smallcap | F40: 544.45 | G40: 610.3 | H40: 2.89 | I40: 3625 | J40: 500089
A41: STAR | B41: Strides Shasun Limited | C41: healthcare | D41: pharmaceuticals - indian - bulk drugs & formln | E41: midcap | F41: 10605.39 | G41: 1183.9 | H41: 2.89 | I41: 398309 | J41: 532531
A42: SIGMAADV | B42: Sigma Advanced System Ltd | C42: aerospace & defence | D42: electronics - components | E42: midcap | F42: 15058.31 | G42: 817.05 | H42: 2.82 | I42: 250590 | J42: 532408
A43: PVRINOX | B43: PVR Inox Ltd | C43: media | D43: entertainment / electronic media software | E43: midcap | F43: 11990.22 | G43: 1254.6 | H43: 2.75 | I43: 456245 | J43: 532689
A44: TEGA | B44: Tega Industries Ltd | C44: industrials | D44: engineering | E44: midcap | F44: 12554.59 | G44: 1717.1 | H44: 2.75 | I44: 225032 | J44: 543413
A45: MANALIPETC | B45: Manali Petrochemicals Limited | C45: energy | D45: petrochemicals | E45: smallcap | F45: 1379.26 | G45: 82.37 | H45: 2.72 | I45: 2637453 | J45: 500268
A46: HINDOILEXP | B46: Hindustan Oil Exploration Company Limited | C46: energy | D46: oil drilling / allied services | E46: smallcap | F46: 2323.78 | G46: 180.44 | H46: 2.69 | I46: 971364 | J46: 500186
A47: SANSERA | B47: Sansera Engineering Ltd | C47: auto | D47: auto ancillaries | E47: largecap | F47: 24160.79 | G47: 3971.2 | H47: 2.57 | I47: 229404 | J47: 543358
A48: ABDL | B48: Allied Blenders & Distillers Ltd | C48: fmcg | D48: breweries & distilleries | E48: midcap | F48: 17666.49 | G48: 647.55 | H48: 2.53 | I48: 1453879 | J48: 544203
... A79: SWANDEF | B79: Swan Defence and Heavy Industries Ltd | C79: transportation | D79: miscellaneous | E79: midcap | F79: 13963.4 | G79: 2687.2 | H79: 1.38 | I79: 17649 | J79: 533107
A80: FIVESTAR | B80: Five-Star Business Finance Ltd | C80: financials | D80: finance & investments | E80: midcap | F80: 15997.27 | G80: 549.4 | H80: 1.37 | I80: 549733
A81: LOTUSDEV | B81: Sri Lotus Developers & Realty Ltd | C81: realty | D81: construction | E81: midcap | F81: 10436.21 | G81: 216.4 | H81: 1.34 | I81: 1914804 | J81: 544469
A82: KIRLFER | B82: Kirloskar Ferrous Industries Ltd | C82: metals & mining | D82: steel - large | E82: midcap | F82: 7669.67 | G82: 470.9 | H82: 1.3 | I82: 140176 | J82: 500245
A83: BIRLACABLE | B83: Birla Cable Limited | C83: industrials | D83: cables - telephone | E83: smallcap | F83: 1133.85 | G83: 382.55 | H83: 1.22 | I83: 734776 | J83: 500060
A84: CEIGALL | B84: Ceigall India Ltd | C84: realty | D84: construction | E84: midcap | F84: 6658.98 | G84: 386.8 | H84: 1.19 | I84: 393782 | J84: 544223
A85: BLACKBUCK | B85: BlackBuck Ltd | C85: transportation | D85: miscellaneous | E85: midcap | F85: 11145.06 | G85: 619.05 | H85: 1.17 | I85: 892263 | J85: 544288
A86: SURAKSHA | B86: Suraksha Diagnostic Ltd | C86: healthcare | D86: healthcare | E86: smallcap | F86: 1682.47 | G86: 326.8 | H86: 1.16 | I86: 98905 | J86: 544293
A87: SHREEPUSHK | B87: Shree Pushkar Chemicals & Fertilisers Limited | C87: chemicals | D87: dyes and pigments | E87: smallcap | F87: 1621.57 | G87: 506.95 | H87: 1.1 | I87: 123748 | J87: 539334
A88: UNITEDPOLY | B88: United Polyfab Gujarat Ltd | C88: textiles | D88: textiles - products | E88: smallcap | F88: 981.18 | G88: 43.19 | H88: 1.03 | I88: 143829 | J88: 533024
A89: ANANDRATHI | B89: Anand Rathi Wealth Ltd | C89: financials | D89: finance & investments | E89: largecap | F89: 36261.75 | G89: 2206.2 | H89: 1.02 | I89: 279080 | J89: 543415
A90: WENDT | B90: Wendt (india) Limited | C90: industrials | D90: abrasives and grinding wheels | E90: smallcap | F90: 1716 | G90: 8663.5 | H90: 0.97 | I90: 16389 | J90: 505412
A91: IPCALAB | B91: Ipca Laboratories Limited | C91: healthcare | D91: pharmaceuticals - indian - bulk drugs & formln | E91: largecap | F91: 49025.8 | G91: 1950.7 | H91: 0.95 | I91: 337123 | J91: 524494
...

Sheet Confluence Overlap
A1: Confluence Rank | B1: Total Score | C1: Relative Strength Rating | D1: Symbol | E1: Company Name | F1: Industry | G1: Common Count | H1: Scanner Signal | I1: Chartink Universe | J1: Scan Matches Count | K1: Backtest Recurrence (30D)
A2: =IF(B2=0,"",ROW()-1) | B2: =IFERROR(INDEX('Monit Non Financial'!$B$2:$B$400, MATCH(D2, 'Monit Non Financial'!$C$2:$C$400, 0)), IFERROR(INDEX('Monit Banks NBFC'!$B$2:$B$100, MATCH(D2, 'Monit Banks NBFC'!$C$2:$C$100, 0)), 0)) | C2: =IFERROR(INDEX('Monit Non Financial'!$L$2:$L$400, MATCH(D2, 'Monit Non Financial'!$C$2:$C$400, 0)), IFERROR(INDEX('Monit Banks NBFC'!$L$2:$L$100, MATCH(D2, 'Monit Banks NBFC'!$C$2:$C$100, 0)), "")) | D2: REDINGTON | E2: Redington (india) Limited | F2: unknown | G2: 2 | H2: ATH Momentum | I2: Yes | J2: 0 | K2: 30
A3: =IF(B3=0,"",ROW()-1) | B3: =IFERROR(INDEX('Monit Non Financial'!$B$2:$B$400, MATCH(D3, 'Monit Non Financial'!$C$2:$C$400, 0)), IFERROR(INDEX('Monit Banks NBFC'!$B$2:$B$100, MATCH(D3, 'Monit Banks NBFC'!$C$2:$C$100, 0)), 0)) | C3: =IFERROR(INDEX('Monit Non Financial'!$L$2:$L$400, MATCH(D3, 'Monit Non Financial'!$C$2:$C$400, 0)), IFERROR(INDEX('Monit Banks NBFC'!$L$2:$L$100, MATCH(D3, 'Monit Banks NBFC'!$C$2:$C$100, 0)), "")) | D3: TBZ | E3: Tribhovandas Bhimji Zaveri Limited | F3: unknown | G3: 2 | H3: ATH Momentum | I3: Yes | J3: 0 | K3: 23
A4: =IF(B4=0,"",ROW()-1) | B4: =IFERROR(INDEX('Monit Non Financial'!$B$2:$B$400, MATCH(D4, 'Monit Non Financial'!$C$2:$C$400, 0)), IFERROR(INDEX('Monit Banks NBFC'!$B$2:$B$100, MATCH(D4, 'Monit Banks NBFC'!$C$2:$C$100, 0)), 0)) | C4: =IFERROR(INDEX('Monit Non Financial'!$L$2:$L$400, MATCH(D4, 'Monit Non Financial'!$C$2:$C$400, 0)), IFERROR(INDEX('Monit Banks NBFC'!$L$2:$L$100, MATCH(D4, 'Monit Banks NBFC'!$C$2:$C$100, 0)), "")) | D4: PAISALO | E4: Paisalo Digital Ltd | F4: unknown | G4: 2 | H4: 52W Breakout | I4: Yes | J4: 0 | K4: 10
A5: =IF(B5=0,"",ROW()-1) | B5: =IFERROR(INDEX('Monit Non Financial'!$B$2:$B$400, MATCH(D5, 'Monit Non Financial'!$C$2:$C$400, 0)), IFERROR(INDEX('Monit Banks NBFC'!$B$2:$B$100, MATCH(D5, 'Monit Banks NBFC'!$C$2:$C$100, 0)), 0)) | C5: =IFERROR(INDEX('Monit Non Financial'!$L$2:$L$400, MATCH(D5, 'Monit Non Financial'!$C$2:$C$400, 0)), IFERROR(INDEX('Monit Banks NBFC'!$L$2:$L$100, MATCH(D5, 'Monit Banks NBFC'!$C$2:$C$100, 0)), "")) | D5: NRL | E5: Nupur Recyclers Ltd | F5: unknown | G5: 2 | H5: ATH Momentum | I5: Yes | J5: 0 | K5: 23
A6: =IF(B6=0,"",ROW()-1) | B6: =IFERROR(INDEX('Monit Non Financial'!$B$2:$B$400, MATCH(D6, 'Monit Non Financial'!$C$2:$C$400, 0)), IFERROR(INDEX('Monit Banks NBFC'!$B$2:$B$100, MATCH(D6, 'Monit Banks NBFC'!$C$2:$C$100, 0)), 0)) | C6: =IFERROR(INDEX('Monit Non Financial'!$L$2:$L$400, MATCH(D6, 'Monit Non Financial'!$C$2:$C$400, 0)), IFERROR(INDEX('Monit Banks NBFC'!$L$2:$L$100, MATCH(D6, 'Monit Banks NBFC'!$C$2:$C$100, 0)), "")) | D6: SWANDEF | E6: Swan Defence and Heavy Industries Ltd | F6: unknown | G6: 2 | H6: ATH Momentum | I6: Yes | J6: 0 | K6: 15
A7: =IF(B7=0,"",ROW()-1) | B7: =IFERROR(INDEX('Monit Non Financial'!$B$2:$B$400, MATCH(D7, 'Monit Non Financial'!$C$2:$C$400, 0)), IFERROR(INDEX('Monit Banks NBFC'!$B$2:$B$100, MATCH(D7, 'Monit Banks NBFC'!$C$2:$C$100, 0)), 0)) | C7: =IFERROR(INDEX('Monit Non Financial'!$L$2:$L$400, MATCH(D7, 'Monit Non Financial'!$C$2:$C$400, 0)), IFERROR(INDEX('Monit Banks NBFC'!$L$2:$L$100, MATCH(D7, 'Monit Banks NBFC'!$C$2:$C$100, 0)), "")) | D7: BHAGYANGR | E7: Bhagyanagar India | F7: unknown | G7: 2 | H7: ATH Momentum | I7: Yes | J7: 0 | K7: 7
A8: =IF(B8=0,"",ROW()-1) | B8: =IFERROR(INDEX('Monit Non Financial'!$B$2:$B$400, MATCH(D8, 'Monit Non Financial'!$C$2:$C$400, 0)), IFERROR(INDEX('Monit Banks NBFC'!$B$2:$B$100, MATCH(D8, 'Monit Banks NBFC'!$C$2:$C$100, 0)), 0)) | C8: =IFERROR(INDEX('Monit Non Financial'!$L$2:$L$400, MATCH(D8, 'Monit Non Financial'!$C$2:$C$400, 0)), IFERROR(INDEX('Monit Banks NBFC'!$L$2:$L$100, MATCH(D8, 'Monit Banks NBFC'!$C$2:$C$100, 0)), "")) | D8: BIRLACABLE | E8: Birla Cable Limited | F8: unknown | G8: 2 | H8: ATH Momentum | I8: Yes | J8: 0 | K8: 30
A9: =IF(B9=0,"",ROW()-1) | B9: =IFERROR(INDEX('Monit Non Financial'!$B$2:$B$400, MATCH(D9, 'Monit Non Financial'!$C$2:$C$400, 0)), IFERROR(INDEX('Monit Banks NBFC'!$B$2:$B$100, MATCH(D9, 'Monit Banks NBFC'!$C$2:$C$100, 0)), 0)) | C9: =IFERROR(INDEX('Monit Non Financial'!$L$2:$L$400, MATCH(D9, 'Monit Non Financial'!$C$2:$C$400, 0)), IFERROR(INDEX('Monit Banks NBFC'!$L$2:$L$100, MATCH(D9, 'Monit Banks NBFC'!$C$2:$C$100, 0)), "")) | D9: FILATEX | E9: Filatex India Limited | F9: unknown | G9: 2 | H9: 52W Breakout | I9: Yes | J9: 0 | K9: 18
A10: =IF(B10=0,"",ROW()-1) | B10: =IFERROR(INDEX('Monit Non Financial'!$B$2:$B$400, MATCH(D10, 'Monit Non Financial'!$C$2:$C$400, 0)), IFERROR(INDEX('Monit Banks NBFC'!$B$2:$B$100, MATCH(D10, 'Monit Banks NBFC'!$C$2:$C$100, 0)), 0)) | C10: =IFERROR(INDEX('Monit Non Financial'!$L$2:$L$400, MATCH(D10, 'Monit Non Financial'!$C$2:$C$400, 0)), IFERROR(INDEX('Monit Banks NBFC'!$L$2:$L$100, MATCH(D10, 'Monit Banks NBFC'!$C$2:$C$100, 0)), "")) | D10: KANORICHEM | E10: Kanoria Chemicals & Industries Limited | F10: unknown | G10: 2 | H10: 52W Breakout | I10: Yes | J10: 0 | K10: 28
A11: =IF(B11=0,"",ROW()-1) | B11: =IFERROR(INDEX('Monit Non Financial'!$B$2:$B$400, MATCH(D11, 'Monit Non Financial'!$C$2:$C$400, 0)), IFERROR(INDEX('Monit Banks NBFC'!$B$2:$B$100, MATCH(D11, 'Monit Banks NBFC'!$C$2:$C$100, 0)), 0)) | C11: =IFERROR(INDEX('Monit Non Financial'!$L$2:$L$400, MATCH(D11, 'Monit Non Financial'!$C$2:$C$400, 0)), IFERROR(INDEX('Monit Banks NBFC'!$L$2:$L$100, MATCH(D11, 'Monit Banks NBFC'!$C$2:$C$100, 0)), "")) | D11: LOTUSDEV | E11: Sri Lotus Developers & Realty Ltd | F11: unknown | G11: 2 | H11: 52W Breakout | I11: Yes | J11: 0 | K11: 15
A12: =IF(B12=0,"",ROW()-1) | B12: =IFERROR(INDEX('Monit Non Financial'!$B$2:$B$400, MATCH(D12, 'Monit Non Financial'!$C$2:$C$400, 0)), IFERROR(INDEX('Monit Banks NBFC'!$B$2:$B$100, MATCH(D12, 'Monit Banks NBFC'!$C$2:$C$100, 0)), 0)) | C12: =IFERROR(INDEX('Monit Non Financial'!$L$2:$L$400, MATCH(D12, 'Monit Non Financial'!$C$2:$C$400, 0)), IFERROR(INDEX('Monit Banks NBFC'!$L$2:$L$100, MATCH(D12, 'Monit Banks NBFC'!$C$2:$C$100, 0)), "")) | D12: ZIMLAB | E12: Zim Laboratories Ltd | F12: unknown | G12: 2 | H12: ATH Momentum | I12: Yes | J12: 0 | K12: 20
A13: =IF(B13=0,"",ROW()-1) | B13: =IFERROR(INDEX('Monit Non Financial'!$B$2:$B$400, MATCH(D13, 'Monit Non Financial'!$C$2:$C$400, 0)), IFERROR(INDEX('Monit Banks NBFC'!$B$2:$B$100, MATCH(D13, 'Monit Banks NBFC'!$C$2:$C$100, 0)), 0)) | C13: =IFERROR(INDEX('Monit Non Financial'!$L$2:$L$400, MATCH(D13, 'Monit Non Financial'!$C$2:$C$400, 0)), IFERROR(INDEX('Monit Banks NBFC'!$L$2:$L$100, MATCH(D13, 'Monit Banks NBFC'!$C$2:$C$100, 0)), "")) | D13: SHREEPUSHK | E13: Shree Pushkar Chemicals & Fertilisers Limited | F13: unknown | G13: 2 | H13: ATH Momentum | I13: Yes | J13: 0 | K13: 19
... A23: =IF(B23=0,"",ROW()-1) | B23: =IFERROR(INDEX('Monit Non Financial'!$B$2:$B$400, MATCH(D23, 'Monit Non Financial'!$C$2:$C$400, 0)), IFERROR(INDEX('Monit Banks NBFC'!$B$2:$B$100, MATCH(D23, 'Monit Banks NBFC'!$C$2:$C$100, 0)), 0)) | C23: =IFERROR(INDEX('Monit Non Financial'!$L$2:$L$400, MATCH(D23, 'Monit Non Financial'!$C$2:$C$400, 0)), IFERROR(INDEX('Monit Banks NBFC'!$L$2:$L$100, MATCH(D23, 'Monit Banks NBFC'!$C$2:$C$100, 0)), "")) | D23: ROSSTECH | E23: Rossell Techsys Ltd | F23: unknown | G23: 2 | H23: 52W Breakout | I23: Yes | J23: 0 | K23: 28

Sheet Monit Non Financial
A1: Rank (Non Financial) | B1: Total Score | C1: Symbol | D1: Company | E1: Sector | F1: Industry | G1: Market Cap Bucket | H1: Market Cap Cr | I1: Close | J1: Today Return % | K1: Volume | L1: Relative Strength Rating | M1: Relative Strength Status | N1: Relative Strength Score | O1: Calculated RSI (14) | P1: Calculated ADX (14) | Q1: Calculated V-stop Line | R1: Calculated Near-term Trigger | S1: Sector Benchmark | T1: Benchmark 1Y Return % | U1: Stock 1Y Return % | V1: Relative Strength 1Y (%) | W1: O'Neil Weighted Score | X1: Industry Growth | Y1: Industry Growth Score | Z1: Competitiveness | AA1: Competitiveness Score | AB1: Regulation | AC1: Regulation Score | AD1: Sector Headwinds/Tailwind | AE1: Sector Headwinds/Tailwind Score | AF1: Industry Type | AG1: Industry Type Score | AH1: Margins | AI1: Margins Score | AJ1: Margins Stability | AK1: Margins Stability Score | AL1: Growth | AM1: Growth Score | AN1: Business Type | AO1: Business Type Score | AP1: Near term triggers | AQ1: Near term triggers Score | AR1: Type of Revenue | AS1: Type of Revenue Score | AT1: Capital Allocation | AU1: Capital Allocation Score | AV1: Medium term Growth | AW1: Medium term Growth Score | AX1: ADX | AY1: ADX Score | AZ1: RSI | BA1: RSI Score | BB1: Stage Analysis | BC1: Stage Analysis Score | BD1: Price Volume Action | BE1: Price Volume Action Score | BF1: Secondary Trend | BG1: Secondary Trend Score | BH1: Primary Trend | BI1: Primary Trend Score | BJ1: Resistance | BK1: Resistance Score | BL1: V-stop | BM1: V-stop Score | BN1: PAT Growth | BO1: PAT Growth Score | BP1: Stock History | BQ1: Stock History Score | BR1: PE Ratio | BS1: PE Ratio Score | BT1: PEG Ratio | BU1: PEG Ratio Score | BV1: CFO to EBITDA | BW1: CFO to EBITDA Score | BX1: Debt to Equity | BY1: Debt to Equity Score | BZ1: Auditor Resignation | CA1: Auditor Resignation Score | CB1: Contingent Liability | CC1: Contingent Liability Score | CD1: Pledging | CE1: Pledging Score
A2: =IF(B2=0,"",RANK(B2,$B$2:$B$184,0)) | B2: =SUM(N2,Y2,AA2,AC2,AE2,AG2,AI2,AK2,AM2,AO2,AQ2,AS2,AU2,AW2,AY2,BA2,BC2,BE2,BG2,BI2,BK2,BM2,BO2,BQ2,BS2,BU2,BW2,BY2,CA2,CC2,CE2) | C2: UNIVPHOTO | D2: Universus Photo Imagings Ltd | E2: consumer discretionary | F2: photographic and allied products | G2: smallcap | H2: 620.4 | I2: 595.05 | J2: 4.99 | K2: 19469 | L2: 90 | M2: Outperforming | N2: =IF(M2="Underperforming",-5,IF(L2>=95,15,IF(L2>=90,10,IF(L2>=80,5,0)))) | O2: 73.34 | P2: 21.63 | Q2: 445.68 | R2: Volume Spike & Near 52W High Breakout | S2: Nifty 50 | T2: -8.33 | U2: 130.06 | V2: 150.96 | W2: 40.72 | X2: Growing Industry | Y2: =IF(X2="Growing Industry",10,IF(X2="Cyclical in an Upturn",5,0)) | Z2: Too Many Players with High ROCE | AA2: =IF(Z2="Monopoly",10,IF(Z2="Oligopoly",5,IF(Z2="Duopoly that cooperate",10,IF(Z2="Duopoly that compete",5,IF(Z2="Too many players with High ROCE",5,0))))) | AB2: No | AC2: =IF(AB2="No",5,0) | AD2: Tailwind | AE2: =IF(AD2="Tailwind",10,0) | AF2: Structural (10 Years Consistency) | AG2: =IF(AF2="Structural (10 Years Consistency)",10,IF(AF2="Shallow Cyclical (2 to 3 years growth)",5,0)) | AH2: No | AI2: =IF(AH2="Yes due to Product Mix change or Operating Leverage",10,IF(AH2="Yes, these are peak margins",-5,IF(AH2="No",5,0))) | AJ2: Stable | AK2: =IF(AJ2="Stable",10,0) | AL2: Yes | AM2: =IF(AL2="Yes",10,0) | AN2: B2B | AO2: =IF(AN2="B2C",10,IF(AN2="B2B",5,0)) | AP2: Yes | AQ2: =IF(AP2="Yes",10,0) | AR2: Higher One Time, Lower Annuity | AS2: =IF(AR2="Fully Annuity",10,IF(AR2="Higher Annuity, Lower One Time",5,IF(AR2="Higher One Time, Lower Annuity",3,0))) | AT2: Good | AU2: =IF(AT2="Good",10,0) | AV2: Yes for more than 2 years | AW2: =IF(AV2="Yes for more than 2 years",10,IF(AV2="Yes only for next 1 to 2 years",5,0)) | AX2: 20 to 40 | AY2: =IF(AX2="Above 40",20,IF(AX2="20 to 40",10,IF(AX2="0 to 20",-5,0))) | AZ2: Between 50 to 75 | BA2: =IF(AZ2="Between 50 to 75",10,IF(AZ2="Above 75",0,0)) | BB2: Stage 2 | BC2: =IF(BB2="Stage 2",20,IF(BB2="Stage 1",0,IF(BB2="Stage 3",5,IF(BB2="Stage 4",-5,0)))) | BD2: Positive Trend | BE2: =IF(BD2="Positive Trend",20,IF(BD2="Negative Trend",-10,0)) | BF2: Uptrend | BG2: =IF(BF2="Uptrend",10,IF(BF2="Sideways",5,0)) | BH2: Uptrend | BI2: =IF(BH2="Uptrend",10,IF(BH2="Sideways",5,0)) | BJ2: Blue sky scenario | BK2: =IF(BJ2="Overhead supply in last 2 years in last 2 years",-5,IF(BJ2="Close to 52 week high or retracement",5,IF(BJ2="Blue sky scenario",10,IF(BJ2="Long term Downtrend",-10,0)))) | BL2: Yes | BM2: =IF(BL2="Yes",10,0) | BN2: More than 20% | BO2: =IF(BN2="More than 20%",10,IF(BN2="Between 12 to 20%",5,IF(BN2="Less than 12%",0,0))) | BP2: No | BQ2: =IF(BP2="No",10,0) | BR2: No | BS2: =IF(BR2="NO",5,0) | BT2: Less than 1.5 | BU2: =IF(BT2="Above 2",0,IF(BT2="Between 1.5 to 2",5,IF(BT2="Less than 1.5",10,0))) | BV2: Above 70% | BW2: =IF(BV2="Above 70%",10,IF(BV2="Between 50% to 70%",5,IF(BV2="Less than 50%",0,IF(BV2="Negative",-10,IF(BV2="Less than 50% and Borrowings are increasing",-5,0))))) | BX2: Less than 0.7 | BY2: =IF(BX2="More than 1.2",-10,IF(BX2="Between 0.7 to 1.2",0,IF(BX2="Less than 0.7",10,0))) | BZ2: No | CA2: =IF(BZ2="Yes",-10,0) | CB2: Less than 15% | CC2: =IF(CB2="More than 15%",-10,IF(CB2="Less than 15%",10,0)) | CD2: No | CE2: =IF(CD2="Yes, more than 10%",-10,IF(CD2="No",10,0))
A3: =IF(B3=0,"",RANK(B3,$B$2:$B$184,0)) | B3: =SUM(N3,Y3,AA3,AC3,AE3,AG3,AI3,AK3,AM3,AO3,AQ3,AS3,AU3,AW3,AY3,BA3,BC3,BE3,BG3,BI3,BK3,BM3,BO3,BQ3,BS3,BU3,BW3,BY3,CA3,CC3,CE3) | C3: REDINGTON | D3: Redington (india) Limited | E3: services | F3: trading | G3: largecap | H3: 29625.34 | I3: 388.15 | J3: 2.43 | K3: 5640367 | L3: 55 | M3: Outperforming | N3: =IF(M3="Underperforming",-5,IF(L3>=95,15,IF(L3>=90,10,IF(L3>=80,5,0)))) | O3: 72.37 | P3: 47.51 | Q3: 307.49 | R3: Near 52W High Breakout | S3: Nifty 50 | T3: -8.33 | U3: 32.34 | V3: 44.37 | W3: 16.48 | X3: Growing Industry | Y3: =IF(X3="Growing Industry",10,IF(X3="Cyclical in an Upturn",5,0)) | Z3: Too Many Players with High ROCE | AA3: =IF(Z3="Monopoly",10,IF(Z3="Oligopoly",5,IF(Z3="Duopoly that cooperate",10,IF(Z3="Duopoly that compete",5,IF(Z3="Too many players with High ROCE",5,0))))) | AB3: No | AC3: =IF(AB3="No",5,0) | AD3: Tailwind | AE3: =IF(AD3="Tailwind",10,0) | AF3: Structural (10 Years Consistency) | AG3: =IF(AF3="Structural (10 Years Consistency)",10,IF(AF3="Shallow Cyclical (2 to 3 years growth)",5,0)) | AH3: No | AI3: =IF(AH3="Yes due to Product Mix change or Operating Leverage",10,IF(AH3="Yes, these are peak margins",-5,IF(AH3="No",5,0))) | AJ3: Stable | AK3: =IF(AJ3="Stable",10,0) | AL3: Yes | AM3: =IF(AL3="Yes",10,0) | AN3: B2B | AO3: =IF(AN3="B2C",10,IF(AN3="B2B",5,0)) | AP3: Yes | AQ3: =IF(AP3="Yes",10,0) | AR3: Higher One Time, Lower Annuity | AS3: =IF(AR3="Fully Annuity",10,IF(AR3="Higher Annuity, Lower One Time",5,IF(AR3="Higher One Time, Lower Annuity",3,0))) | AT3: Good | AU3: =IF(AT3="Good",10,0) | AV3: Yes for more than 2 years | AW3: =IF(AV3="Yes for more than 2 years",10,IF(AV3="Yes only for next 1 to 2 years",5,0)) | AX3: Above 40 | AY3: =IF(AX3="Above 40",20,IF(AX3="20 to 40",10,IF(AX3="0 to 20",-5,0))) | AZ3: Between 50 to 75 | BA3: =IF(AZ3="Between 50 to 75",10,IF(AZ3="Above 75",0,0)) | BB3: Stage 2 | BC3: =IF(BB3="Stage 2",20,IF(BB3="Stage 1",0,IF(BB3="Stage 3",5,IF(BB3="Stage 4",-5,0)))) | BD3: Positive Trend | BE3: =IF(BD3="Positive Trend",20,IF(BD3="Negative Trend",-10,0)) | BF3: Uptrend | BG3: =IF(BF3="Uptrend",10,IF(BF3="Sideways",5,0)) | BH3: Uptrend | BI3: =IF(BH3="Uptrend",10,IF(BH3="Sideways",5,0)) | BJ3: Blue sky scenario | BK3: =IF(BJ3="Overhead supply in last 2 years in last 2 years",-5,IF(BJ3="Close to 52 week high or retracement",5,IF(BJ3="Blue sky scenario",10,IF(BJ3="Long term Downtrend",-10,0)))) | BL3: Yes | BM3: =IF(BL3="Yes",10,0) | BN3: More than 20% | BO3: =IF(BN3="More than 20%",10,IF(BN3="Between 12 to 20%",5,IF(BN3="Less than 12%",0,0))) | BP3: No | BQ3: =IF(BP3="No",10,0) | BR3: No | BS3: =IF(BR3="NO",5,0) | BT3: Less than 1.5 | BU3: =IF(BT3="Above 2",0,IF(BT3="Between 1.5 to 2",5,IF(BT3="Less than 1.5",10,0))) | BV3: Above 70% | BW3: =IF(BV3="Above 70%",10,IF(BV3="Between 50% to 70%",5,IF(BV3="Less than 50%",0,IF(BV3="Negative",-10,IF(BV3="Less than 50% and Borrowings are increasing",-5,0))))) | BX3: Less than 0.7 | BY3: =IF(BX3="More than 1.2",-10,IF(BX3="Between 0.7 to 1.2",0,IF(BX3="Less than 0.7",10,0))) | BZ3: No | CA3: =IF(BZ3="Yes",-10,0) | CB3: Less than 15% | CC3: =IF(CB3="More than 15%",-10,IF(CB3="Less than 15%",10,0)) | CD3: No | CE3: =IF(CD3="Yes, more than 10%",-10,IF(CD3="No",10,0))
A4: =IF(B4=0,"",RANK(B4,$B$2:$B$184,0)) | B4: =SUM(N4,Y4,AA4,AC4,AE4,AG4,AI4,AK4,AM4,AO4,AQ4,AS4,AU4,AW4,AY4,BA4,BC4,BE4,BG4,BI4,BK4,BM4,BO4,BQ4,BS4,BU4,BW4,BY4,CA4,CC4,CE4) | C4: VISHNU | D4: Vishnu Chemicals Limited | E4: chemicals | F4: chemicals | G4: smallcap | H4: 4596.29 | I4: 693.9 | J4: 1.63 | K4: 112259 | L4: 35 | M4: Outperforming | N4: =IF(M4="Underperforming",-5,IF(L4>=95,15,IF(L4>=90,10,IF(L4>=80,5,0)))) | O4: 66.28 | P4: 44.89 | Q4: 576.22 | R4: Near 52W High Breakout | S4: Nifty 50 | T4: -8.33 | U4: 39.47 | V4: 52.15 | W4: 10.26 | X4: Growing Industry | Y4: =IF(X4="Growing Industry",10,IF(X4="Cyclical in an Upturn",5,0)) | Z4: Too Many Players with High ROCE | AA4: =IF(Z4="Monopoly",10,IF(Z4="Oligopoly",5,IF(Z4="Duopoly that cooperate",10,IF(Z4="Duopoly that compete",5,IF(Z4="Too many players with High ROCE",5,0))))) | AB4: No | AC4: =IF(AB4="No",5,0) | AD4: Tailwind | AE4: =IF(AD4="Tailwind",10,0) | AF4: Structural (10 Years Consistency) | AG4: =IF(AF4="Structural (10 Years Consistency)",10,IF(AF4="Shallow Cyclical (2 to 3 years growth)",5,0)) | AH4: No | AI4: =IF(AH4="Yes due to Product Mix change or Operating Leverage",10,IF(AH4="Yes, these are peak margins",-5,IF(AH4="No",5,0))) | AJ4: Stable | AK4: =IF(AJ4="Stable",10,0) | AL4: Yes | AM4: =IF(AL4="Yes",10,0) | AN4: B2B | AO4: =IF(AN4="B2C",10,IF(AN4="B2B",5,0)) | AP4: Yes | AQ4: =IF(AP4="Yes",10,0) | AR4: Higher One Time, Lower Annuity | AS4: =IF(AR4="Fully Annuity",10,IF(AR4="Higher Annuity, Lower One Time",5,IF(AR4="Higher One Time, Lower Annuity",3,0))) | AT4: Good | AU4: =IF(AT4="Good",10,0) | AV4: Yes for more than 2 years | AW4: =IF(AV4="Yes for more than 2 years",10,IF(AV4="Yes only for next 1 to 2 years",5,0)) | AX4: Above 40 | AY4: =IF(AX4="Above 40",20,IF(AX4="20 to 40",10,IF(AX4="0 to 20",-5,0))) | AZ4: Between 50 to 75 | BA4: =IF(AZ4="Between 50 to 75",10,IF(AZ4="Above 75",0,0)) | BB4: Stage 2 | BC4: =IF(BB4="Stage 2",20,IF(BB4="Stage 1",0,IF(BB4="Stage 3",5,IF(BB4="Stage 4",-5,0)))) | BD4: Positive Trend | BE4: =IF(BD4="Positive Trend",20,IF(BD4="Negative Trend",-10,0)) | BF4: Uptrend | BG4: =IF(BF4="Uptrend",10,IF(BF4="Sideways",5,0)) | BH4: Uptrend | BI4: =IF(BH4="Uptrend",10,IF(BH4="Sideways",5,0)) | BJ4: Blue sky scenario | BK4: =IF(BJ4="Overhead supply in last 2 years in last 2 years",-5,IF(BJ4="Close to 52 week high or retracement",5,IF(BJ4="Blue sky scenario",10,IF(BJ4="Long term Downtrend",-10,0)))) | BL4: Yes | BM4: =IF(BL4="Yes",10,0) | BN4: More than 20% | BO4: =IF(BN4="More than 20%",10,IF(BN4="Between 12 to 20%",5,IF(BN4="Less than 12%",0,0))) | BP4: No | BQ4: =IF(BP4="No",10,0) | BR4: No | BS4: =IF(BR4="NO",5,0) | BT4: Less than 1.5 | BU4: =IF(BT4="Above 2",0,IF(BT4="Between 1.5 to 2",5,IF(BT4="Less than 1.5",10,0))) | BV4: Above 70% | BW4: =IF(BV4="Above 70%",10,IF(BV4="Between 50% to 70%",5,IF(BV4="Less than 50%",0,IF(BV4="Negative",-10,IF(BV4="Less than 50% and Borrowings are increasing",-5,0))))) | BX4: Less than 0.7 | BY4: =IF(BX4="More than 1.2",-10,IF(BX4="Between 0.7 to 1.2",0,IF(BX4="Less than 0.7",10,0))) | BZ4: No | CA4: =IF(BZ4="Yes",-10,0) | CB4: Less than 15% | CC4: =IF(CB4="More than 15%",-10,IF(CB4="Less than 15%",10,0)) | CD4: No | CE4: =IF(CD4="Yes, more than 10%",-10,IF(CD4="No",10,0))
A5: =IF(B5=0,"",RANK(B5,$B$2:$B$184,0)) | B5: =SUM(N5,Y5,AA5,AC5,AE5,AG5,AI5,AK5,AM5,AO5,AQ5,AS5,AU5,AW5,AY5,BA5,BC5,BE5,BG5,BI5,BK5,BM5,BO5,BQ5,BS5,BU5,BW5,BY5,CA5,CC5,CE5) | C5: IPCALAB | D5: Ipca Laboratories Limited | E5: healthcare | F5: pharmaceuticals - indian - bulk drugs & formln | G5: largecap | H5: 49025.8 | I5: 1950.7 | J5: 0.95 | K5: 337123 | L5: 40 | M5: Outperforming | N5: =IF(M5="Underperforming",-5,IF(L5>=95,15,IF(L5>=90,10,IF(L5>=80,5,0)))) | O5: 67.71 | P5: 44.28 | Q5: 1614.76 | R5: Near 52W High Breakout | S5: Nifty Pharma | T5: 15.25 | U5: 35.84 | V5: 17.87 | W5: 11.37 | X5: Growing Industry | Y5: =IF(X5="Growing Industry",10,IF(X5="Cyclical in an Upturn",5,0)) | Z5: Too Many Players with High ROCE | AA5: =IF(Z5="Monopoly",10,IF(Z5="Oligopoly",5,IF(Z5="Duopoly that cooperate",10,IF(Z5="Duopoly that compete",5,IF(Z5="Too many players with High ROCE",5,0))))) | AB5: Yes | AC5: =IF(AB5="No",5,0) | AD5: Tailwind | AE5: =IF(AD5="Tailwind",10,0) | AF5: Structural (10 Years Consistency) | AG5: =IF(AF5="Structural (10 Years Consistency)",10,IF(AF5="Shallow Cyclical (2 to 3 years growth)",5,0)) | AH5: No | AI5: =IF(AH5="Yes due to Product Mix change or Operating Leverage",10,IF(AH5="Yes, these are peak margins",-5,IF(AH5="No",5,0))) | AJ5: Stable | AK5: =IF(AJ5="Stable",10,0) | AL5: Yes | AM5: =IF(AL5="Yes",10,0) | AN5: B2B | AO5: =IF(AN5="B2C",10,IF(AN5="B2B",5,0)) | AP5: Yes | AQ5: =IF(AP5="Yes",10,0) | AR5: Higher Annuity, Lower One Time | AS5: =IF(AR5="Fully Annuity",10,IF(AR5="Higher Annuity, Lower One Time",5,IF(AR5="Higher One Time, Lower Annuity",3,0))) | AT5: Good | AU5: =IF(AT5="Good",10,0) | AV5: Yes for more than 2 years | AW5: =IF(AV5="Yes for more than 2 years",10,IF(AV5="Yes only for next 1 to 2 years",5,0)) | AX5: Above 40 | AY5: =IF(AX5="Above 40",20,IF(AX5="20 to 40",10,IF(AX5="0 to 20",-5,0))) | AZ5: Between 50 to 75 | BA5: =IF(AZ5="Between 50 to 75",10,IF(AZ5="Above 75",0,0)) | BB5: Stage 2 | BC5: =IF(BB5="Stage 2",20,IF(BB5="Stage 1",0,IF(BB5="Stage 3",5,IF(BB5="Stage 4",-5,0)))) | BD5: Positive Trend | BE5: =IF(BD5="Positive Trend",20,IF(BD5="Negative Trend",-10,0)) | BF5: Uptrend | BG5: =IF(BF5="Uptrend",10,IF(BF5="Sideways",5,0)) | BH5: Uptrend | BI5: =IF(BH5="Uptrend",10,IF(BH5="Sideways",5,0)) | BJ5: Blue sky scenario | BK5: =IF(BJ5="Overhead supply in last 2 years in last 2 years",-5,IF(BJ5="Close to 52 week high or retracement",5,IF(BJ5="Blue sky scenario",10,IF(BJ5="Long term Downtrend",-10,0)))) | BL5: Yes | BM5: =IF(BL5="Yes",10,0) | BN5: More than 20% | BO5: =IF(BN5="More than 20%",10,IF(BN5="Between 12 to 20%",5,IF(BN5="Less than 12%",0,0))) | BP5: No | BQ5: =IF(BP5="No",10,0) | BR5: No | BS5: =IF(BR5="NO",5,0) | BT5: Less than 1.5 | BU5: =IF(BT5="Above 2",0,IF(BT5="Between 1.5 to 2",5,IF(BT5="Less than 1.5",10,0))) | BV5: Above 70% | BW5: =IF(BV5="Above 70%",10,IF(BV5="Between 50% to 70%",5,IF(BV5="Less than 50%",0,IF(BV5="Negative",-10,IF(BV5="Less than 50% and Borrowings are increasing",-5,0))))) | BX5: Less than 0.7 | BY5: =IF(BX5="More than 1.2",-10,IF(BX5="Between 0.7 to 1.2",0,IF(BX5="Less than 0.7",10,0))) | BZ5: No | CA5: =IF(BZ5="Yes",-10,0) | CB5: Less than 15% | CC5: =IF(CB5="More than 15%",-10,IF(CB5="Less than 15%",10,0)) | CD5: No | CE5: =IF(CD5="Yes, more than 10%",-10,IF(CD5="No",10,0))
A6: =IF(B6=0,"",RANK(B6,$B$2:$B$184,0)) | B6: =SUM(N6,Y6,AA6,AC6,AE6,AG6,AI6,AK6,AM6,AO6,AQ6,AS6,AU6,AW6,AY6,BA6,BC6,BE6,BG6,BI6,BK6,BM6,BO6,BQ6,BS6,BU6,BW6,BY6,CA6,CC6,CE6) | C6: TBZ | D6: Tribhovandas Bhimji Zaveri Limited | E6: consumer discretionary | F6: diamond cutting / jewellery | G6: smallcap | H6: 3499.69 | I6: 547.5 | J6: 4.4 | K6: 1564537 | L6: 99 | M6: Outperforming | N6: =IF(M6="Underperforming",-5,IF(L6>=95,15,IF(L6>=90,10,IF(L6>=80,5,0)))) | O6: 90.49 | P6: 56.37 | Q6: 412.89 | R6: Near 52W High Breakout | S6: Nifty 50 | T6: -8.33 | U6: 193.21 | V6: 219.85 | W6: 79.17 | X6: Growing Industry | Y6: =IF(X6="Growing Industry",10,IF(X6="Cyclical in an Upturn",5,0)) | Z6: Too Many Players with High ROCE | AA6: =IF(Z6="Monopoly",10,IF(Z6="Oligopoly",5,IF(Z6="Duopoly that cooperate",10,IF(Z6="Duopoly that compete",5,IF(Z6="Too many players with High ROCE",5,0))))) | AB6: No | AC6: =IF(AB6="No",5,0) | AD6: Tailwind | AE6: =IF(AD6="Tailwind",10,0) | AF6: Structural (10 Years Consistency) | AG6: =IF(AF6="Structural (10 Years Consistency)",10,IF(AF6="Shallow Cyclical (2 to 3 years growth)",5,0)) | AH6: No | AI6: =IF(AH6="Yes due to Product Mix change or Operating Leverage",10,IF(AH6="Yes, these are peak margins",-5,IF(AH6="No",5,0))) | AJ6: Stable | AK6: =IF(AJ6="Stable",10,0) | AL6: Yes | AM6: =IF(AL6="Yes",10,0) | AN6: B2B | AO6: =IF(AN6="B2C",10,IF(AN6="B2B",5,0)) | AP6: Yes | AQ6: =IF(AP6="Yes",10,0) | AR6: Higher One Time, Lower Annuity | AS6: =IF(AR6="Fully Annuity",10,IF(AR6="Higher Annuity, Lower One Time",5,IF(AR6="Higher One Time, Lower Annuity",3,0))) | AT6: Good | AU6: =IF(AT6="Good",10,0) | AV6: Yes for more than 2 years | AW6: =IF(AV6="Yes for more than 2 years",10,IF(AV6="Yes only for next 1 to 2 years",5,0)) | AX6: Above 40 | AY6: =IF(AX6="Above 40",20,IF(AX6="20 to 40",10,IF(AX6="0 to 20",-5,0))) | AZ6: Above 75 | BA6: =IF(AZ6="Between 50 to 75",10,IF(AZ6="Above 75",0,0)) | BB6: Stage 2 | BC6: =IF(BB6="Stage 2",20,IF(BB6="Stage 1",0,IF(BB6="Stage 3",5,IF(BB6="Stage 4",-5,0)))) | BD6: Positive Trend | BE6: =IF(BD6="Positive Trend",20,IF(BD6="Negative Trend",-10,0)) | BF6: Uptrend | BG6: =IF(BF6="Uptrend",10,IF(BF6="Sideways",5,0)) | BH6: Uptrend | BI6: =IF(BH6="Uptrend",10,IF(BH6="Sideways",5,0)) | BJ6: Blue sky scenario | BK6: =IF(BJ6="Overhead supply in last 2 years in last 2 years",-5,IF(BJ6="Close to 52 week high or retracement",5,IF(BJ6="Blue sky scenario",10,IF(BJ6="Long term Downtrend",-10,0)))) | BL6: Yes | BM6: =IF(BL6="Yes",10,0) | BN6: More than 20% | BO6: =IF(BN6="More than 20%",10,IF(BN6="Between 12 to 20%",5,IF(BN6="Less than 12%",0,0))) | BP6: No | BQ6: =IF(BP6="No",10,0) | BR6: No | BS6: =IF(BR6="NO",5,0) | BT6: Less than 1.5 | BU6: =IF(BT6="Above 2",0,IF(BT6="Between 1.5 to 2",5,IF(BT6="Less than 1.5",10,0))) | BV6: Above 70% | BW6: =IF(BV6="Above 70%",10,IF(BV6="Between 50% to 70%",5,IF(BV6="Less than 50%",0,IF(BV6="Negative",-10,IF(BV6="Less than 50% and Borrowings are increasing",-5,0))))) | BX6: Between 0.7 to 1.2 | BY6: =IF(BX6="More than 1.2",-10,IF(BX6="Between 0.7 to 1.2",0,IF(BX6="Less than 0.7",10,0))) | BZ6: No | CA6: =IF(BZ6="Yes",-10,0) | CB6: Less than 15% | CC6: =IF(CB6="More than 15%",-10,IF(CB6="Less than 15%",10,0)) | CD6: No | CE6: =IF(CD6="Yes, more than 10%",-10,IF(CD6="No",10,0))
A7: =IF(B7=0,"",RANK(B7,$B$2:$B$184,0)) | B7: =SUM(N7,Y7,AA7,AC7,AE7,AG7,AI7,AK7,AM7,AO7,AQ7,AS7,AU7,AW7,AY7,BA7,BC7,BE7,BG7,BI7,BK7,BM7,BO7,BQ7,BS7,BU7,BW7,BY7,CA7,CC7,CE7) | C7: WELSPUNLIV | D7: Welspun Living Ltd | E7: textiles | F7: textiles - products | G7: midcap | H7: 19049.04 | I7: 202.82 | J7: 0.59 | K7: 3113066 | L7: 56 | M7: Outperforming | N7: =IF(M7="Underperforming",-5,IF(L7>=95,15,IF(L7>=90,10,IF(L7>=80,5,0)))) | O7: 73.82 | P7: 42.65 | Q7: 166.86 | R7: Near 52W High Breakout | S7: Nifty 50 | T7: -8.33 | U7: 63.12 | V7: 77.94 | W7: 17.06 | X7: Growing Industry | Y7: =IF(X7="Growing Industry",10,IF(X7="Cyclical in an Upturn",5,0)) | Z7: Too Many Players with High ROCE | AA7: =IF(Z7="Monopoly",10,IF(Z7="Oligopoly",5,IF(Z7="Duopoly that cooperate",10,IF(Z7="Duopoly that compete",5,IF(Z7="Too many players with High ROCE",5,0))))) | AB7: No | AC7: =IF(AB7="No",5,0) | AD7: Tailwind | AE7: =IF(AD7="Tailwind",10,0) | AF7: Structural (10 Years Consistency) | AG7: =IF(AF7="Structural (10 Years Consistency)",10,IF(AF7="Shallow Cyclical (2 to 3 years growth)",5,0)) | AH7: No | AI7: =IF(AH7="Yes due to Product Mix change or Operating Leverage",10,IF(AH7="Yes, these are peak margins",-5,IF(AH7="No",5,0))) | AJ7: Stable | AK7: =IF(AJ7="Stable",10,0) | AL7: Yes | AM7: =IF(AL7="Yes",10,0) | AN7: B2B | AO7: =IF(AN7="B2C",10,IF(AN7="B2B",5,0)) | AP7: Yes | AQ7: =IF(AP7="Yes",10,0) | AR7: Higher One Time, Lower Annuity | AS7: =IF(AR7="Fully Annuity",10,IF(AR7="Higher Annuity, Lower One Time",5,IF(AR7="Higher One Time, Lower Annuity",3,0))) | AT7: Good | AU7: =IF(AT7="Good",10,0) | AV7: Yes for more than 2 years | AW7: =IF(AV7="Yes for more than 2 years",10,IF(AV7="Yes only for next 1 to 2 years",5,0)) | AX7: Above 40 | AY7: =IF(AX7="Above 40",20,IF(AX7="20 to 40",10,IF(AX7="0 to 20",-5,0))) | AZ7: Between 50 to 75 | BA7: =IF(AZ7="Between 50 to 75",10,IF(AZ7="Above 75",0,0)) | BB7: Stage 2 | BC7: =IF(BB7="Stage 2",20,IF(BB7="Stage 1",0,IF(BB7="Stage 3",5,IF(BB7="Stage 4",-5,0)))) | BD7: Positive Trend | BE7: =IF(BD7="Positive Trend",20,IF(BD7="Negative Trend",-10,0)) | BF7: Uptrend | BG7: =IF(BF7="Uptrend",10,IF(BF7="Sideways",5,0)) | BH7: Uptrend | BI7: =IF(BH7="Uptrend",10,IF(BH7="Sideways",5,0)) | BJ7: Blue sky scenario | BK7: =IF(BJ7="Overhead supply in last 2 years in last 2 years",-5,IF(BJ7="Close to 52 week high or retracement",5,IF(BJ7="Blue sky scenario",10,IF(BJ7="Long term Downtrend",-10,0)))) | BL7: Yes | BM7: =IF(BL7="Yes",10,0) | BN7: More than 20% | BO7: =IF(BN7="More than 20%",10,IF(BN7="Between 12 to 20%",5,IF(BN7="Less than 12%",0,0))) | BP7: No | BQ7: =IF(BP7="No",10,0) | BR7: Yes | BS7: =IF(BR7="NO",5,0) | BT7: Less than 1.5 | BU7: =IF(BT7="Above 2",0,IF(BT7="Between 1.5 to 2",5,IF(BT7="Less than 1.5",10,0))) | BV7: Above 70% | BW7: =IF(BV7="Above 70%",10,IF(BV7="Between 50% to 70%",5,IF(BV7="Less than 50%",0,IF(BV7="Negative",-10,IF(BV7="Less than 50% and Borrowings are increasing",-5,0))))) | BX7: Less than 0.7 | BY7: =IF(BX7="More than 1.2",-10,IF(BX7="Between 0.7 to 1.2",0,IF(BX7="Less than 0.7",10,0))) | BZ7: No | CA7: =IF(BZ7="Yes",-10,0) | CB7: Less than 15% | CC7: =IF(CB7="More than 15%",-10,IF(CB7="Less than 15%",10,0)) | CD7: No | CE7: =IF(CD7="Yes, more than 10%",-10,IF(CD7="No",10,0))
A8: =IF(B8=0,"",RANK(B8,$B$2:$B$184,0)) | B8: =SUM(N8,Y8,AA8,AC8,AE8,AG8,AI8,AK8,AM8,AO8,AQ8,AS8,AU8,AW8,AY8,BA8,BC8,BE8,BG8,BI8,BK8,BM8,BO8,BQ8,BS8,BU8,BW8,BY8,CA8,CC8,CE8) | C8: PASUPTAC | D8: Pasupati Acrylon Ltd | E8: textiles | F8: textiles - manmade | G8: smallcap | H8: 628.21 | I8: 68.07 | J8: -3.42 | K8: 159716 | L8: 33 | M8: Outperforming | N8: =IF(M8="Underperforming",-5,IF(L8>=95,15,IF(L8>=90,10,IF(L8>=80,5,0)))) | O8: 62.2 | P8: 46.9 | Q8: 49.52 | R8: Volume Spike / Accumulation | S8: Nifty 50 | T8: -8.33 | U8: 46.07 | V8: 59.34 | W8: 10.15 | X8: Growing Industry | Y8: =IF(X8="Growing Industry",10,IF(X8="Cyclical in an Upturn",5,0)) | Z8: Too Many Players with High ROCE | AA8: =IF(Z8="Monopoly",10,IF(Z8="Oligopoly",5,IF(Z8="Duopoly that cooperate",10,IF(Z8="Duopoly that compete",5,IF(Z8="Too many players with High ROCE",5,0))))) | AB8: No | AC8: =IF(AB8="No",5,0) | AD8: Tailwind | AE8: =IF(AD8="Tailwind",10,0) | AF8: Structural (10 Years Consistency) | AG8: =IF(AF8="Structural (10 Years Consistency)",10,IF(AF8="Shallow Cyclical (2 to 3 years growth)",5,0)) | AH8: No | AI8: =IF(AH8="Yes due to Product Mix change or Operating Leverage",10,IF(AH8="Yes, these are peak margins",-5,IF(AH8="No",5,0))) | AJ8: Stable | AK8: =IF(AJ8="Stable",10,0) | AL8: Yes | AM8: =IF(AL8="Yes",10,0) | AN8: B2B | AO8: =IF(AN8="B2C",10,IF(AN8="B2B",5,0)) | AP8: Yes | AQ8: =IF(AP8="Yes",10,0) | AR8: Higher One Time, Lower Annuity | AS8: =IF(AR8="Fully Annuity",10,IF(AR8="Higher Annuity, Lower One Time",5,IF(AR8="Higher One Time, Lower Annuity",3,0))) | AT8: Good | AU8: =IF(AT8="Good",10,0) | AV8: Yes for more than 2 years | AW8: =IF(AV8="Yes for more than 2 years",10,IF(AV8="Yes only for next 1 to 2 years",5,0)) | AX8: Above 40 | AY8: =IF(AX8="Above 40",20,IF(AX8="20 to 40",10,IF(AX8="0 to 20",-5,0))) | AZ8: Between 50 to 75 | BA8: =IF(AZ8="Between 50 to 75",10,IF(AZ8="Above 75",0,0)) | BB8: Stage 2 | BC8: =IF(BB8="Stage 2",20,IF(BB8="Stage 1",0,IF(BB8="Stage 3",5,IF(BB8="Stage 4",-5,0)))) | BD8: Positive Trend | BE8: =IF(BD8="Positive Trend",20,IF(BD8="Negative Trend",-10,0)) | BF8: Uptrend | BG8: =IF(BF8="Uptrend",10,IF(BF8="Sideways",5,0)) | BH8: Uptrend | BI8: =IF(BH8="Uptrend",10,IF(BH8="Sideways",5,0)) | BJ8: Close to 52 week high or retracement | BK8: =IF(BJ8="Overhead supply in last 2 years in last 2 years",-5,IF(BJ8="Close to 52 week high or retracement",5,IF(BJ8="Blue sky scenario",10,IF(BJ8="Long term Downtrend",-10,0)))) | BL8: Yes | BM8: =IF(BL8="Yes",10,0) | BN8: More than 20% | BO8: =IF(BN8="More than 20%",10,IF(BN8="Between 12 to 20%",5,IF(BN8="Less than 12%",0,0))) | BP8: No | BQ8: =IF(BP8="No",10,0) | BR8: No | BS8: =IF(BR8="NO",5,0) | BT8: Less than 1.5 | BU8: =IF(BT8="Above 2",0,IF(BT8="Between 1.5 to 2",5,IF(BT8="Less than 1.5",10,0))) | BV8: Above 70% | BW8: =IF(BV8="Above 70%",10,IF(BV8="Between 50% to 70%",5,IF(BV8="Less than 50%",0,IF(BV8="Negative",-10,IF(BV8="Less than 50% and Borrowings are increasing",-5,0))))) | BX8: Less than 0.7 | BY8: =IF(BX8="More than 1.2",-10,IF(BX8="Between 0.7 to 1.2",0,IF(BX8="Less than 0.7",10,0))) | BZ8: No | CA8: =IF(BZ8="Yes",-10,0) | CB8: Less than 15% | CC8: =IF(CB8="More than 15%",-10,IF(CB8="Less than 15%",10,0)) | CD8: No | CE8: =IF(CD8="Yes, more than 10%",-10,IF(CD8="No",10,0))
A9: =IF(B9=0,"",RANK(B9,$B$2:$B$184,0)) | B9: =SUM(N9,Y9,AA9,AC9,AE9,AG9,AI9,AK9,AM9,AO9,AQ9,AS9,AU9,AW9,AY9,BA9,BC9,BE9,BG9,BI9,BK9,BM9,BO9,BQ9,BS9,BU9,BW9,BY9,CA9,CC9,CE9) | C9: INNOVACAP | D9: Innova Captab Ltd | E9: healthcare | F9: pharmaceuticals - indian - bulk drugs & formln | G9: midcap | H9: 6524.21 | I9: 1133.4 | J9: -0.59 | K9: 119085 | L9: 40 | M9: Outperforming | N9: =IF(M9="Underperforming",-5,IF(L9>=95,15,IF(L9>=90,10,IF(L9>=80,5,0)))) | O9: 69.76 | P9: 62.71 | Q9: 912.13 | R9: Near 52W High Breakout | S9: Nifty Pharma | T9: 15.25 | U9: 32.01 | V9: 14.54 | W9: 11.48 | X9: Growing Industry | Y9: =IF(X9="Growing Industry",10,IF(X9="Cyclical in an Upturn",5,0)) | Z9: Too Many Players with High ROCE | AA9: =IF(Z9="Monopoly",10,IF(Z9="Oligopoly",5,IF(Z9="Duopoly that cooperate",10,IF(Z9="Duopoly that compete",5,IF(Z9="Too many players with High ROCE",5,0))))) | AB9: Yes | AC9: =IF(AB9="No",5,0) | AD9: Tailwind | AE9: =IF(AD9="Tailwind",10,0) | AF9: Structural (10 Years Consistency) | AG9: =IF(AF9="Structural (10 Years Consistency)",10,IF(AF9="Shallow Cyclical (2 to 3 years growth)",5,0)) | AH9: No | AI9: =IF(AH9="Yes due to Product Mix change or Operating Leverage",10,IF(AH9="Yes, these are peak margins",-5,IF(AH9="No",5,0))) | AJ9: Stable | AK9: =IF(AJ9="Stable",10,0) | AL9: Yes | AM9: =IF(AL9="Yes",10,0) | AN9: B2B | AO9: =IF(AN9="B2C",10,IF(AN9="B2B",5,0)) | AP9: Yes | AQ9: =IF(AP9="Yes",10,0) | AR9: Higher Annuity, Lower One Time | AS9: =IF(AR9="Fully Annuity",10,IF(AR9="Higher Annuity, Lower One Time",5,IF(AR9="Higher One Time, Lower Annuity",3,0))) | AT9: Good | AU9: =IF(AT9="Good",10,0) | AV9: Yes for more than 2 years | AW9: =IF(AV9="Yes for more than 2 years",10,IF(AV9="Yes only for next 1 to 2 years",5,0)) | AX9: Above 40 | AY9: =IF(AX9="Above 40",20,IF(AX9="20 to 40",10,IF(AX9="0 to 20",-5,0))) | AZ9: Between 50 to 75 | BA9: =IF(AZ9="Between 50 to 75",10,IF(AZ9="Above 75",0,0)) | BB9: Stage 2 | BC9: =IF(BB9="Stage 2",20,IF(BB9="Stage 1",0,IF(BB9="Stage 3",5,IF(BB9="Stage 4",-5,0)))) | BD9: Positive Trend | BE9: =IF(BD9="Positive Trend",20,IF(BD9="Negative Trend",-10,0)) | BF9: Uptrend | BG9: =IF(BF9="Uptrend",10,IF(BF9="Sideways",5,0)) | BH9: Uptrend | BI9: =IF(BH9="Uptrend",10,IF(BH9="Sideways",5,0)) | BJ9: Blue sky scenario | BK9: =IF(BJ9="Overhead supply in last 2 years in last 2 years",-5,IF(BJ9="Close to 52 week high or retracement",5,IF(BJ9="Blue sky scenario",10,IF(BJ9="Long term Downtrend",-10,0)))) | BL9: Yes | BM9: =IF(BL9="Yes",10,0) | BN9: More than 20% | BO9: =IF(BN9="More than 20%",10,IF(BN9="Between 12 to 20%",5,IF(BN9="Less than 12%",0,0))) | BP9: No | BQ9: =IF(BP9="No",10,0) | BR9: Yes | BS9: =IF(BR9="NO",5,0) | BT9: Less than 1.5 | BU9: =IF(BT9="Above 2",0,IF(BT9="Between 1.5 to 2",5,IF(BT9="Less than 1.5",10,0))) | BV9: Above 70% | BW9: =IF(BV9="Above 70%",10,IF(BV9="Between 50% to 70%",5,IF(BV9="Less than 50%",0,IF(BV9="Negative",-10,IF(BV9="Less than 50% and Borrowings are increasing",-5,0))))) | BX9: Less than 0.7 | BY9: =IF(BX9="More than 1.2",-10,IF(BX9="Between 0.7 to 1.2",0,IF(BX9="Less than 0.7",10,0))) | BZ9: No | CA9: =IF(BZ9="Yes",-10,0) | CB9: Less than 15% | CC9: =IF(CB9="More than 15%",-10,IF(CB9="Less than 15%",10,0)) | CD9: No | CE9: =IF(CD9="Yes, more than 10%",-10,IF(CD9="No",10,0))
A10: =IF(B10=0,"",RANK(B10,$B$2:$B$184,0)) | B10: =SUM(N10,Y10,AA10,AC10,AE10,AG10,AI10,AK10,AM10,AO10,AQ10,AS10,AU10,AW10,AY10,BA10,BC10,BE10,BG10,BI10,BK10,BM10,BO10,BQ10,BS10,BU10,BW10,BY10,CA10,CC10,CE10) | C10: MBECL | D10: Mcnally Bharat Engineering Company Limited | E10: realty | F10: engineering - turnkey services | G10: smallcap | H10: 1156.4 | I10: 364.26 | J10: 5 | K10: 28195 | N10: =IF(M10="Underperforming",-5,IF(L10>=95,15,IF(L10>=90,10,IF(L10>=80,5,0)))) | O10: 99.97 | P10: 61.59 | Q10: 306.78 | R10: Volume Spike & Near 52W High Breakout | S10: Nifty Realty | X10: Growing Industry | Y10: =IF(X10="Growing Industry",10,IF(X10="Cyclical in an Upturn",5,0)) | Z10: Too Many Players with High ROCE | AA10: =IF(Z10="Monopoly",10,IF(Z10="Oligopoly",5,IF(Z10="Duopoly that cooperate",10,IF(Z10="Duopoly that compete",5,IF(Z10="Too many players with High ROCE",5,0))))) | AB10: No | AC10: =IF(AB10="No",5,0) | AD10: Tailwind | AE10: =IF(AD10="Tailwind",10,0) | AF10: Structural (10 Years Consistency) | AG10: =IF(AF10="Structural (10 Years Consistency)",10,IF(AF10="Shallow Cyclical (2 to 3 years growth)",5,0)) | AH10: No | AI10: =IF(AH10="Yes due to Product Mix change or Operating Leverage",10,IF(AH10="Yes, these are peak margins",-5,IF(AH10="No",5,0))) | AJ10: Stable | AK10: =IF(AJ10="Stable",10,0) | AL10: Yes | AM10: =IF(AL10="Yes",10,0) | AN10: B2B | AO10: =IF(AN10="B2C",10,IF(AN10="B2B",5,0)) | AP10: Yes | AQ10: =IF(AP10="Yes",10,0) | AR10: Higher One Time, Lower Annuity | AS10: =IF(AR10="Fully Annuity",10,IF(AR10="Higher Annuity, Lower One Time",5,IF(AR10="Higher One Time, Lower Annuity",3,0))) | AT10: Good | AU10: =IF(AT10="Good",10,0) | AV10: Yes for more than 2 years | AW10: =IF(AV10="Yes for more than 2 years",10,IF(AV10="Yes only for next 1 to 2 years",5,0)) | AX10: Above 40 | AY10: =IF(AX10="Above 40",20,IF(AX10="20 to 40",10,IF(AX10="0 to 20",-5,0))) | AZ10: Above 75 | BA10: =IF(AZ10="Between 50 to 75",10,IF(AZ10="Above 75",0,0)) | BB10: Stage 2 | BC10: =IF(BB10="Stage 2",20,IF(BB10="Stage 1",0,IF(BB10="Stage 3",5,IF(BB10="Stage 4",-5,0)))) | BD10: Positive Trend | BE10: =IF(BD10="Positive Trend",20,IF(BD10="Negative Trend",-10,0)) | BF10: Uptrend | BG10: =IF(BF10="Uptrend",10,IF(BF10="Sideways",5,0)) | BH10: Uptrend | BI10: =IF(BH10="Uptrend",10,IF(BH10="Sideways",5,0)) | BJ10: Blue sky scenario | BK10: =IF(BJ10="Overhead supply in last 2 years in last 2 years",-5,IF(BJ10="Close to 52 week high or retracement",5,IF(BJ10="Blue sky scenario",10,IF(BJ10="Long term Downtrend",-10,0)))) | BL10: Yes | BM10: =IF(BL10="Yes",10,0) | BN10: More than 20% | BO10: =IF(BN10="More than 20%",10,IF(BN10="Between 12 to 20%",5,IF(BN10="Less than 12%",0,0))) | BP10: No | BQ10: =IF(BP10="No",10,0) | BR10: No | BS10: =IF(BR10="NO",5,0) | BT10: Less than 1.5 | BU10: =IF(BT10="Above 2",0,IF(BT10="Between 1.5 to 2",5,IF(BT10="Less than 1.5",10,0))) | BV10: Above 70% | BW10: =IF(BV10="Above 70%",10,IF(BV10="Between 50% to 70%",5,IF(BV10="Less than 50%",0,IF(BV10="Negative",-10,IF(BV10="Less than 50% and Borrowings are increasing",-5,0))))) | BX10: Less than 0.7 | BY10: =IF(BX10="More than 1.2",-10,IF(BX10="Between 0.7 to 1.2",0,IF(BX10="Less than 0.7",10,0))) | BZ10: No | CA10: =IF(BZ10="Yes",-10,0) | CB10: Less than 15% | CC10: =IF(CB10="More than 15%",-10,IF(CB10="Less than 15%",10,0)) | CD10: No | CE10: =IF(CD10="Yes, more than 10%",-10,IF(CD10="No",10,0))
